<?xml version="1.0" ?>
<robot name="mini_pupper_2" xmlns:xacro="http://www.ros.org/wiki/xacro">

  <xacro:include filename="$(find mini_pupper_2_description)/urdf/materials.xacro" />
  <xacro:include filename="$(find mini_pupper_2_description)/urdf/mini_pupper_description.trans" />
  
  <!-- CONSTANTS -->
  <!-- Link group 1 - lf1, rf1, lb1, rb1 -->
  <xacro:property name="lnkgrp1_weight" value="0.020769" />
  
  <!-- Link group 2 - lf2, rf2, lb2, rb2 -->
  <xacro:property name="lnkgrp2_weight" value="0.001906" />
  
  <!-- Link group 3 - lf3, rf3, lb3, rb3 -->
  <xacro:property name="lnkgrp3_weight" value="0.001144" />
  
  <!-- Plate group 1 - lpf1, rpf1, lpb1, rpb1 -->
  <xacro:property name="pltgrp1_weight" value="0.002574" />
  
  <!-- Plate group 2 - lpf2, rpf2, lpb2, rpb2 -->
  <xacro:property name="pltgrp2_weight" value="0.002231" />

  <!-- Feet - lffoot, rffoot, lbfoot, rbfoot -->
  <xacro:property name="feet_weight" value="0.001405" />
  <!-- -0.004982788451759437 -2.855826620254409e-07 0.006488368014064216 -->
  <!-- COM-Y: 0.00025 -->
  <xacro:property name="feet_centre_of_mass"
                  value="-0.014 0.00025 0.002488" />
  
  <link name="base_link">
    <visual>
      <origin xyz="0 0 0" rpy="0 0 0"/>
      <geometry>
        <mesh filename="file://$(find mini_pupper_2_description)/meshes/base_link.stl" scale="1 1 1"/>
      </geometry>
      <material name="opaque252525"/>
    </visual>
    <collision>
      <origin xyz="0 0 0" rpy="0 0 0"/>
      <geometry>
        <mesh filename="file://$(find mini_pupper_2_description)/meshes/base_link.stl" scale="1 1 1"/>
      </geometry>
    </collision>
  </link>

  <link name="base_inertia">
    <inertial>
      <origin xyz="-0.008867 0.000396 -0.007154" rpy="0 0 0"/>
      <mass value="0.09818420433466489"/>
      <inertia ixx="5.2003168e-5" iyy="2.437e-4" izz="2.523e-4" ixy="7.28047e-7" iyz="603.31e-11" ixz="-9.716561e-7"/>
    </inertial>
  </link>

  <link name="lf1">
    <inertial>
      <origin xyz="0.020109 0.002332 0.006500" rpy="0 0 0"/>
      <mass value="${lnkgrp1_weight}"/>
      <inertia ixx="2.494061e-6" iyy="3.735906e-6" izz="3.222909e-6" ixy="-7.662e-9" iyz="-0.014e-9" ixz="-33.565e-9"/>
    </inertial>
    <visual>
      <origin xyz="0 0 0" rpy="0 0 0"/>
      <geometry>
        <mesh filename="file://$(find mini_pupper_2_description)/meshes/lf1.stl" scale="1 1 1"/>
      </geometry>
      <material name="opaque666666"/>
    </visual>
    <collision>
      <origin xyz="0 0 0" rpy="0 0 0"/>
      <geometry>
        <mesh filename="file://$(find mini_pupper_2_description)/meshes/lf1.stl" scale="1 1 1"/>
      </geometry>
    </collision>
  </link>

  <link name="lf2">
    <inertial>
      <origin xyz="-0.003174 0.000986 -0.017984" rpy="0 0 0"/>
      <mass value="${lnkgrp2_weight}"/>
      <inertia ixx="0.462154e-6" iyy="0.481174e-6" izz="26.893e-9" ixy="3.117e-9" iyz="17.662e-9" ixz="-79.269e-9"/>
    </inertial>
    <visual>
      <origin xyz="0 0 0" rpy="0 0 0"/>
      <geometry>
        <mesh filename="file://$(find mini_pupper_2_description)/meshes/lf2.stl" scale="1 1 1"/>
      </geometry>
      <material name="opaque636363"/>
    </visual>
    <collision>
      <origin xyz="0 0 0" rpy="0 0 0"/>
      <geometry>
        <mesh filename="file://$(find mini_pupper_2_description)/meshes/lf2.stl" scale="1 1 1"/>
      </geometry>
    </collision>
  </link>

  <link name="lf3">
    <inertial>
      <origin xyz="0.006211 0.003456 -0.015014" rpy="0 0 0"/>
      <mass value="${lnkgrp3_weight}"/>
      <inertia ixx="0.484471e-6" iyy="0.567615e-6" izz="91.813e-9" ixy="-2.101e-9" iyz="5.008e-9" ixz="0.20057e-6"/>
    </inertial>
    <visual>
      <origin xyz="0 0 0" rpy="0 0 0"/>
      <geometry>
        <mesh filename="file://$(find mini_pupper_2_description)/meshes/lf3.stl" scale="1 1 1"/>
      </geometry>
      <material name="opaque252525"/>
    </visual>
    <collision>
      <origin xyz="0 0 0" rpy="0 0 0"/>
      <geometry>
        <mesh filename="file://$(find mini_pupper_2_description)/meshes/lf3.stl" scale="1 1 1"/>
      </geometry>
    </collision>
  </link>

  <link name="rf1">
    <inertial>
      <origin xyz="0.020109 -0.002332 0.006500" rpy="0 0 0"/>
      <mass value="${lnkgrp1_weight}"/>
      <inertia ixx="2.494061e-06" iyy="3.735906e-06" izz="3.222909e-06" ixy="7.662e-9" iyz="-0.014e-9" ixz="-33.565e-9"/>
    </inertial>
    <visual>
      <origin xyz="0 0 0" rpy="0 0 0"/>
      <geometry>
        <mesh filename="file://$(find mini_pupper_2_description)/meshes/rf1.stl" scale="1 1 1"/>
      </geometry>
      <material name="opaque666666"/>
    </visual>
    <collision>
      <origin xyz="0 0 0" rpy="0 0 0"/>
      <geometry>
        <mesh filename="file://$(find mini_pupper_2_description)/meshes/rf1.stl" scale="1 1 1"/>
      </geometry>
    </collision>
  </link>

  <link name="rf2">
    <inertial>
      <origin xyz="-0.003174 -0.000986 -0.017984" rpy="0 0 0"/>
      <mass value="${lnkgrp2_weight}"/>
      <inertia ixx="0.462154e-6" iyy="0.481174e-6" izz="26.893e-9" ixy="-3.117e-9" iyz="-17.662e-9" ixz="-79.269e-9"/>
    </inertial>
    <visual>
      <origin xyz="0 0 0" rpy="0 0 0"/>
      <geometry>
        <mesh filename="file://$(find mini_pupper_2_description)/meshes/rf2.stl" scale="1 1 1"/>
      </geometry>
      <material name="opaque636363"/>
    </visual>
    <collision>
      <origin xyz="0 0 0" rpy="0 0 0"/>
      <geometry>
        <mesh filename="file://$(find mini_pupper_2_description)/meshes/rf2.stl" scale="1 1 1"/>
      </geometry>
    </collision>
  </link>

  <link name="rf3">
    <inertial>
      <origin xyz="0.006211 -0.003456 -0.015014" rpy="0 0 0"/>
      <mass value="${lnkgrp3_weight}"/>
      <inertia ixx="0.484471e-6" iyy="0.567615e-06" izz="91.813e-9" ixy="2.101e-9" iyz="-5.008e-9" ixz="0.20057e-6"/>
    </inertial>
    <visual>
      <origin xyz="0 0 0" rpy="0 0 0"/>
      <geometry>
        <mesh filename="file://$(find mini_pupper_2_description)/meshes/rf3.stl" scale="1 1 1"/>
      </geometry>
      <material name="opaque252525"/>
    </visual>
    <collision>
      <origin xyz="0 0 0" rpy="0 0 0"/>
      <geometry>
        <mesh filename="file://$(find mini_pupper_2_description)/meshes/rf3.stl" scale="1 1 1"/>
      </geometry>
    </collision>
  </link>

  <link name="rb1">
    <inertial>
      <origin xyz="-0.020109 -0.002332 0.006500" rpy="0 0 0"/>
      <mass value="${lnkgrp1_weight}"/>
      <inertia ixx="2.494061e-06" iyy="3.735906e-06" izz="3.222909e-06" ixy="-7.662e-9" iyz="-0.014e-9" ixz="-33.565e-9"/>
    </inertial>
    <visual>
      <origin xyz="0 0 0" rpy="0 0 0"/>
      <geometry>
        <mesh filename="file://$(find mini_pupper_2_description)/meshes/rb1.stl" scale="1 1 1"/>
      </geometry>
      <material name="opaque666666"/>
    </visual>
    <collision>
      <origin xyz="0 0 0" rpy="0 0 0"/>
      <geometry>
        <mesh filename="file://$(find mini_pupper_2_description)/meshes/rb1.stl" scale="1 1 1"/>
      </geometry>
    </collision>
  </link>

  <link name="rb2">
    <inertial>
      <origin xyz="-0.003174 -0.000986 -0.017984" rpy="0 0 0"/>
      <mass value="${lnkgrp2_weight}"/>
      <inertia ixx="0.462154e-6" iyy="0.481174e-6" izz="26.893e-9" ixy="-3.117e-9" iyz="-17.662e-9" ixz="-79.269e-9"/>
    </inertial>
    <visual>
      <origin xyz="0 0 0" rpy="0 0 0"/>
      <geometry>
        <mesh filename="file://$(find mini_pupper_2_description)/meshes/rb2.stl" scale="1 1 1"/>
      </geometry>
      <material name="opaque636363"/>
    </visual>
    <collision>
      <origin xyz="0 0 0" rpy="0 0 0"/>
      <geometry>
        <mesh filename="file://$(find mini_pupper_2_description)/meshes/rb2.stl" scale="1 1 1"/>
      </geometry>
    </collision>
  </link>

  <link name="rb3">
    <inertial>
      <origin xyz="0.006211 -0.003456 -0.015014" rpy="0 0 0"/>
      <mass value="${lnkgrp3_weight}"/>
      <inertia ixx="0.484816e-6" iyy="0.567883e-06" izz="91.777e-9" ixy="2.212e-9" iyz="-5.34e-9" ixz="0.200564e-6"/>
    </inertial>
    <visual>
      <origin xyz="0 0 0" rpy="0 0 0"/>
      <geometry>
        <mesh filename="file://$(find mini_pupper_2_description)/meshes/rb3.stl" scale="1 1 1"/>
      </geometry>
      <material name="opaque252525"/>
    </visual>
    <collision>
      <origin xyz="0 0 0" rpy="0 0 0"/>
      <geometry>
        <mesh filename="file://$(find mini_pupper_2_description)/meshes/rb3.stl" scale="1 1 1"/>
      </geometry>
    </collision>
  </link>

  <link name="lb1">
    <inertial>
      <origin xyz="-0.020109 0.002332 0.006500" rpy="0 0 0"/>
      <mass value="${lnkgrp1_weight}"/>
      <inertia ixx="2.494061e-06" iyy="3.735906e-06" izz="3.222909e-06" ixy="7.662e-9" iyz="-0.014e-9" ixz="-33.565e-9"/>
    </inertial>
    <visual>
      <origin xyz="0 0 0" rpy="0 0 0"/>
      <geometry>
        <mesh filename="file://$(find mini_pupper_2_description)/meshes/lb1.stl" scale="1 1 1"/>
      </geometry>
      <material name="opaque666666"/>
    </visual>
    <collision>
      <origin xyz="0 0 0" rpy="0 0 0"/>
      <geometry>
        <mesh filename="file://$(find mini_pupper_2_description)/meshes/lb1.stl" scale="1 1 1"/>
      </geometry>
    </collision>
  </link>

  <link name="lb2">
    <inertial>
      <origin xyz="-0.003174 0.000986 -0.017984" rpy="0 0 0"/>
      <mass value="${lnkgrp2_weight}"/>
      <inertia ixx="0.462154e-6" iyy="0.481174e-6" izz="26.893e-9" ixy="3.117e-9" iyz="17.662e-9" ixz="-79.269e-9"/>
    </inertial>
    <visual>
      <origin xyz="0 0 0" rpy="0 0 0"/>
      <geometry>
        <mesh filename="file://$(find mini_pupper_2_description)/meshes/lb2.stl" scale="1 1 1"/>
      </geometry>
      <material name="opaque636363"/>
    </visual>
    <collision>
      <origin xyz="0 0 0" rpy="0 0 0"/>
      <geometry>
        <mesh filename="file://$(find mini_pupper_2_description)/meshes/lb2.stl" scale="1 1 1"/>
      </geometry>
    </collision>
  </link>

  <link name="lb3">
    <inertial>
      <origin xyz="0.006211 0.003456 -0.015014" rpy="0 0 0"/>
      <mass value="${lnkgrp3_weight}"/>
      <inertia ixx="0.484471e-6" iyy="0.567615e-06" izz="91.813e-9" ixy="-2.101e-9" iyz="5.008e-9" ixz="0.20057e-6"/>
    </inertial>
    <visual>
      <origin xyz="0 0 0" rpy="0 0 0"/>
      <geometry>
        <mesh filename="file://$(find mini_pupper_2_description)/meshes/lb3.stl" scale="1 1 1"/>
      </geometry>
      <material name="opaque252525"/>
    </visual>
    <collision>
      <origin xyz="0 0 0" rpy="0 0 0"/>
      <geometry>
        <mesh filename="file://$(find mini_pupper_2_description)/meshes/lb3.stl" scale="1 1 1"/>
      </geometry>
    </collision>
  </link>

  <link name="Body_front">
    <inertial>
      <origin xyz="-0.005539 -0.000204 0.020223" rpy="0 0 0"/>
      <mass value="0.00785515871148119"/>
      <inertia ixx="5.306048e-6" iyy="1.837621e-6" izz="3.61974e-6" ixy="-22.863e-9" iyz="-4.925e-9" ixz="-9.195e-9"/>
    </inertial>
    <visual>
      <origin xyz="-0.089299 0 0.015543" rpy="0 0 0"/>
      <geometry>
        <mesh filename="file://$(find mini_pupper_2_description)/meshes/Body_front.stl" scale="1 1 1"/>
      </geometry>
      <material name="opaque2552210"/>
    </visual>
    <collision>
      <origin xyz="-0.089299 0 0.015543" rpy="0 0 0"/>
      <geometry>
        <mesh filename="file://$(find mini_pupper_2_description)/meshes/Body_front.stl" scale="1 1 1"/>
      </geometry>
    </collision>
  </link>

  <link name="Board_PCB">
    <inertial>
      <origin xyz="0.089461 0.023505 0.0" rpy="0 0 0"/>
      <mass value="0.014261552601793053"/>
      <inertia ixx="4.425965e-6" iyy="3.4560775e-5" izz="3.8954441e-5" ixy="0.104871e-6" iyz="75.406e-9" ixz="0.113313e-6"/>
    </inertial>
    <visual>
      <origin xyz="0.087701 0.023505 -0.026457" rpy="0 0 0"/>
      <geometry>
        <mesh filename="file://$(find mini_pupper_2_description)/meshes/Board_PCB.stl" scale="1 1 1"/>
      </geometry>
      <material name="opaque646464"/>
    </visual>
    <collision>
      <origin xyz="0.087701 0.023505 -0.026457" rpy="0 0 0"/>
      <geometry>
        <mesh filename="file://$(find mini_pupper_2_description)/meshes/Board_PCB.stl" scale="1 1 1"/>
      </geometry>
    </collision>
  </link>

  <link name="Board_connectors_1">
    <!-- <inertial>
      <origin xyz="-0.07276303117117414 -0.002323344081837562 -0.0010631239213060653" rpy="0 0 0"/>
      <mass value="0.004688613655947816"/>
      <inertia ixx="0.203205e-6" iyy="1.5404404e-5" izz="1.5546403e-5" ixy="-0.625328e-6" iyz="42.901e-9" ixz="0.186346e-9"/>
    </inertial> -->
    <visual>
      <origin xyz="-0.061334 3.3e-05 -0.026457" rpy="0 0 0"/>
      <geometry>
        <mesh filename="file://$(find mini_pupper_2_description)/meshes/Board_connectors_1.stl" scale="1 1 1"/>
      </geometry>
      <material name="opaque2491590"/>
    </visual>
    <collision>
      <origin xyz="-0.061334 3.3e-05 -0.026457" rpy="0 0 0"/>
      <geometry>
        <mesh filename="file://$(find mini_pupper_2_description)/meshes/Board_connectors_1.stl" scale="1 1 1"/>
      </geometry>
    </collision>
  </link>

  <link name="Board_connectors_2">
    <!-- <inertial>
      <origin xyz="0.008233541174180986 -0.0021383697865476553 -0.00030110978110910874" rpy="0 0 0"/>
      <mass value="0.0019746031301169403"/>
      <inertia ixx="0.458183e-6" iyy="3.284548e-6" izz="3.720196e-6" ixy="-79.741e-9" iyz="4.796e-9" ixz="0.123868e-9"/>
    </inertial> -->
    <visual>
      <origin xyz="0.045346 5e-06 -0.026457" rpy="0 0 0"/>
      <geometry>
        <mesh filename="file://$(find mini_pupper_2_description)/meshes/Board_connectors_2.stl" scale="1 1 1"/>
      </geometry>
      <material name="opaque255255255"/>
    </visual>
    <collision>
      <origin xyz="0.045346 5e-06 -0.026457" rpy="0 0 0"/>
      <geometry>
        <mesh filename="file://$(find mini_pupper_2_description)/meshes/Board_connectors_2.stl" scale="1 1 1"/>
      </geometry>
    </collision>
  </link>
  <link
    name="lidar_link">
    <inertial>
      <origin
        xyz="1.56706411611127E-05 -5.16565672073303E-13 -0.0191835739440227"
        rpy="0 0 -1.57" />
      <mass value="0.0001" />
      <inertia
        ixx="8.74731426973985E-06"
        ixy="-6.66781590704156E-08"
        ixz="1.89196685410159E-11"
        iyy="8.70097486591694E-06"
        iyz="-1.13397577799603E-17"
        izz="9.98821295317784E-06" />
    </inertial>
    <visual>
      <origin xyz="0 0 0" rpy="0 0 -1.57"/>
      <geometry>
        <mesh
          filename="file://$(find mini_pupper_2_description)/meshes/lidar.stl" />
      </geometry>
      <material name="">
        <color rgba="0.2 0.2 0.2 1" />
      </material>
    </visual>
    <collision>
      <origin xyz="0 0 0" rpy="0 0 -1.57" />
      <geometry>
        <mesh
          filename="file://$(find mini_pupper_2_description)/meshes/lidar.stl" />
      </geometry>
    </collision>
  </link>
  <link name="rffoot">
    <inertial>
      <origin xyz="${feet_centre_of_mass}" rpy="0 0 0"/>
      <mass value="${feet_weight}"/>
      <inertia ixx="41.995e-9" iyy="62.40e-9" izz="29.798e-9" ixy="0.0e-9" iyz="0.0e-9" ixz="1.616e-9"/>
    </inertial>
    <visual>
      <origin xyz="0 0 0" rpy="0 0 0"/>
      <geometry>
        <mesh filename="file://$(find mini_pupper_2_description)/meshes/rffoot.stl" scale="1 1 1"/>
      </geometry>
      <material name="opaque666666"/>
    </visual>
    <collision>
      <origin xyz="0 0 0" rpy="0 0 0"/>
      <geometry>
        <mesh filename="file://$(find mini_pupper_2_description)/meshes/rffoot.stl" scale="1 1 1"/>
      </geometry>
    </collision>
  </link>

  <link name="rbfoot">
    <inertial>
      <origin xyz="${feet_centre_of_mass}" rpy="0 0 0"/>
      <mass value="${feet_weight}"/>
      <inertia ixx="41.995e-9" iyy="62.40e-9" izz="29.798e-9" ixy="0.0e-9" iyz="0.0e-9" ixz="1.616e-9"/>
    </inertial>
    <visual>
      <origin xyz="0 0 0" rpy="0 0 0"/>
      <geometry>
        <mesh filename="file://$(find mini_pupper_2_description)/meshes/rbfoot.stl" scale="1 1 1"/>
      </geometry>
      <material name="opaque666666"/>
    </visual>
    <collision>
      <origin xyz="0 0 0" rpy="0 0 0"/>
      <geometry>
        <mesh filename="file://$(find mini_pupper_2_description)/meshes/rbfoot.stl" scale="1 1 1"/>
      </geometry>
    </collision>
  </link>

  <link name="lbfoot">
    <inertial>
      <origin xyz="${feet_centre_of_mass}" rpy="0 0 0"/>
      <mass value="${feet_weight}"/>
      <inertia ixx="41.995e-9" iyy="62.40e-9" izz="29.798e-9" ixy="0.0e-9" iyz="0.0e-9" ixz="1.616e-9"/>
    </inertial>
    <visual>
      <origin xyz="0 0 0" rpy="0 0 0"/>
      <geometry>
        <mesh filename="file://$(find mini_pupper_2_description)/meshes/lbfoot.stl" scale="1 1 1"/>
      </geometry>
      <material name="opaque666666"/>
    </visual>
    <collision>
      <origin xyz="0 0 0" rpy="0 0 0"/>
      <geometry>
        <mesh filename="file://$(find mini_pupper_2_description)/meshes/lbfoot.stl" scale="1 1 1"/>
      </geometry>
    </collision>
  </link>

  <link name="lffoot">
    <inertial>
      <origin xyz="${feet_centre_of_mass}" rpy="0 0 0"/>
      <mass value="${feet_weight}"/>
      <inertia ixx="41.995e-9" iyy="62.40e-9" izz="29.798e-9" ixy="0.0e-9" iyz="0.0e-9" ixz="1.616e-9"/>
    </inertial>
    <visual>
      <origin xyz="0 0 0" rpy="0 0 0"/>
      <geometry>
        <mesh filename="file://$(find mini_pupper_2_description)/meshes/lffoot.stl" scale="1 1 1"/>
      </geometry>
      <material name="opaque666666"/>
    </visual>
    <collision>
      <origin xyz="0 0 0" rpy="0 0 0"/>
      <geometry>
        <mesh filename="file://$(find mini_pupper_2_description)/meshes/lffoot.stl" scale="1 1 1"/>
      </geometry>
    </collision>
  </link>

  <link name="lpf1">
    <inertial>
      <origin xyz="0.002259 0.008667 -0.002748" rpy="0 0 0"/>
      <mass value="${pltgrp1_weight}"/>
      <inertia ixx="0.39059e-6" iyy="0.412444e-6" izz="0.246337e-6" ixy="24.631e-9" iyz="3.861e-9" ixz="54.116e-9"/>
    </inertial>
    <visual>
      <origin xyz="0 0 0" rpy="0 0 0"/>
      <geometry>
        <mesh filename="file://$(find mini_pupper_2_description)/meshes/lpf1.stl" scale="1 1 1"/>
      </geometry>
      <material name="opaque2552210"/>
    </visual>
    <collision>
      <origin xyz="0 0 0" rpy="0 0 0"/>
      <geometry>
        <mesh filename="file://$(find mini_pupper_2_description)/meshes/lpf1.stl" scale="1 1 1"/>
      </geometry>
    </collision>
  </link>

  <link name="lpb1">
    <inertial>
      <origin xyz="0.002259 0.008667 -0.002748" rpy="0 0 0"/>
      <mass value="${pltgrp1_weight}"/>
      <inertia ixx="0.39059e-6" iyy="0.412444e-6" izz="0.246337e-6" ixy="24.631e-9" iyz="3.861e-9" ixz="54.116e-9"/>
    </inertial>
    <visual>
      <origin xyz="0 0 0" rpy="0 0 0"/>
      <geometry>
        <mesh filename="file://$(find mini_pupper_2_description)/meshes/lpb1.stl" scale="1 1 1"/>
      </geometry>
      <material name="opaque2552210"/>
    </visual>
    <collision>
      <origin xyz="0 0 0" rpy="0 0 0"/>
      <geometry>
        <mesh filename="file://$(find mini_pupper_2_description)/meshes/lpb1.stl" scale="1 1 1"/>
      </geometry>
    </collision>
  </link>

  <link name="rpf1">
    <inertial>
      <origin xyz="0.002259 -0.008667 -0.002748" rpy="0 0 0"/>
      <mass value="${pltgrp1_weight}"/>
      <inertia ixx="0.39059e-6" iyy="0.412444e-6" izz="0.246337e-6" ixy="-24.631e-9" iyz="-3.861e-9" ixz="54.116e-9"/>
    </inertial>
    <visual>
      <origin xyz="0 0 0" rpy="0 0 0"/>
      <geometry>
        <mesh filename="file://$(find mini_pupper_2_description)/meshes/rpf1.stl" scale="1 1 1"/>
      </geometry>
      <material name="opaque2552210"/>
    </visual>
    <collision>
      <origin xyz="0 0 0" rpy="0 0 0"/>
      <geometry>
        <mesh filename="file://$(find mini_pupper_2_description)/meshes/rpf1.stl" scale="1 1 1"/>
      </geometry>
    </collision>
  </link>

  <link name="rpb1">
    <inertial>
      <origin xyz="0.002259 -0.008667 -0.002748" rpy="0 0 0"/>
      <mass value="${pltgrp1_weight}"/>
      <inertia ixx="0.39059e-6" iyy="0.412444e-6" izz="0.246337e-6" ixy="-24.631e-9" iyz="-3.861e-9" ixz="54.116e-9"/>
    </inertial>
    <visual>
      <origin xyz="0 0 0" rpy="0 0 0"/>
      <geometry>
        <mesh filename="file://$(find mini_pupper_2_description)/meshes/rpb1.stl" scale="1 1 1"/>
      </geometry>
      <material name="opaque2552210"/>
    </visual>
    <collision>
      <origin xyz="0 0 0" rpy="0 0 0"/>
      <geometry>
        <mesh filename="file://$(find mini_pupper_2_description)/meshes/rpb1.stl" scale="1 1 1"/>
      </geometry>
    </collision>
  </link>

  <link name="lpf2">
    <inertial>
      <origin xyz="-0.001747 0.007904 0.005365" rpy="0 0 0"/>
      <mass value="${pltgrp2_weight}"/>
      <inertia ixx="0.862567e-6" iyy="0.991403e-6" izz="0.13904e-6" ixy="1.254e-9" iyz="-13.212e-9" ixz="-0.112894e-6"/>
    </inertial>
    <visual>
      <origin xyz="0 0 0" rpy="0 0 0"/>
      <geometry>
        <mesh filename="file://$(find mini_pupper_2_description)/meshes/lpf2.stl" scale="1 1 1"/>
      </geometry>
      <material name="opaque2552210"/>
    </visual>
    <collision>
      <origin xyz="0 0 0" rpy="0 0 0"/>
      <geometry>
        <mesh filename="file://$(find mini_pupper_2_description)/meshes/lpf2.stl" scale="1 1 1"/>
      </geometry>
    </collision>
  </link>

  <link name="lpb2">
    <inertial>
      <origin xyz="-0.001747 0.007904 0.005365" rpy="0 0 0"/>
      <mass value="${pltgrp2_weight}"/>
      <inertia ixx="0.862567e-6" iyy="0.991403e-6" izz="0.13904e-6" ixy="1.254e-9" iyz="-13.212e-9" ixz="-0.112894e-6"/>
    </inertial>
    <visual>
      <origin xyz="0 0 0" rpy="0 0 0"/>
      <geometry>
        <mesh filename="file://$(find mini_pupper_2_description)/meshes/lpb2.stl" scale="1 1 1"/>
      </geometry>
      <material name="opaque2552210"/>
    </visual>
    <collision>
      <origin xyz="0 0 0" rpy="0 0 0"/>
      <geometry>
        <mesh filename="file://$(find mini_pupper_2_description)/meshes/lpb2.stl" scale="1 1 1"/>
      </geometry>
    </collision>
  </link>

  <link name="rpf2">
    <inertial>
      <origin xyz="-0.001747 -0.007904 0.005365" rpy="0 0 0"/>
      <mass value="${pltgrp2_weight}"/>
      <inertia ixx="0.862567e-6" iyy="0.991403e-6" izz="0.13904e-6" ixy="-1.254e-9" iyz="13.212e-9" ixz="-0.11152e-6"/>
    </inertial>
    <visual>
      <origin xyz="0 0 0" rpy="0 0 0"/>
      <geometry>
        <mesh filename="file://$(find mini_pupper_2_description)/meshes/rpf2.stl" scale="1 1 1"/>
      </geometry>
      <material name="opaque2552210"/>
    </visual>
    <collision>
      <origin xyz="0 0 0" rpy="0 0 0"/>
      <geometry>
        <mesh filename="file://$(find mini_pupper_2_description)/meshes/rpf2.stl" scale="1 1 1"/>
      </geometry>
    </collision>
  </link>

  <link name="rpb2">
    <inertial>
      <origin xyz="-0.001747 -0.007904 0.005365" rpy="0 0 0"/>
      <mass value="${pltgrp2_weight}"/>
      <inertia ixx="0.862567e-6" iyy="0.991403e-6" izz="0.13904e-6" ixy="-1.254e-9" iyz="13.212e-9" ixz="-0.11152e-6"/>
    </inertial>
    <visual>
      <origin xyz="0 0 0" rpy="0 0 0"/>
      <geometry>
        <mesh filename="file://$(find mini_pupper_2_description)/meshes/rpb2.stl" scale="1 1 1"/>
      </geometry>
      <material name="opaque2552210"/>
    </visual>
    <collision>
      <origin xyz="0 0 0" rpy="0 0 0"/>
      <geometry>
        <mesh filename="file://$(find mini_pupper_2_description)/meshes/rpb2.stl" scale="1 1 1"/>
      </geometry>
    </collision>
  </link>

  <link name="Shell_Side">
    <inertial>
      <!-- <origin xyz="-2.7696824994288393e-05 0.0 0.02237056777957029" rpy="0 0 0"/>  -->
      <origin xyz="-0.00003 0.030005 0.022371" rpy="0 0 0"/> 
      <mass value="0.0051928835390001775"/>
      <inertia ixx="5.834352e-6" iyy="3.214872e-6" izz="6.996514e-6" ixy="0.0e-9" iyz="0.0e-9" ixz="15.218e-9"/>
    </inertial>
    <visual>
      <origin xyz="0.002701 0.030005 0.016293" rpy="0 0 0"/>
      <geometry>
        <mesh filename="file://$(find mini_pupper_2_description)/meshes/Shell_Side.stl" scale="1 1 1"/>
      </geometry>
      <material name="opaque2552210"/>
    </visual>
    <collision>
      <origin xyz="0.002701 0.030005 0.016293" rpy="0 0 0"/>
      <geometry>
        <mesh filename="file://$(find mini_pupper_2_description)/meshes/Shell_Side.stl" scale="1 1 1"/>
      </geometry>
    </collision>
  </link>
  
  <joint name="base_link_to_base_inertia" type="fixed">
    <parent link="base_link"/>
    <child link="base_inertia"/>
    <origin rpy="0 0 0" xyz="0 0 0"/>
  </joint>

  <joint name="base_lf1" type="revolute">
    <origin xyz="0.05 0.0235 0.0" rpy="0 0 0"/>
    <parent link="base_link"/>
    <child link="lf1"/>
    <axis xyz="1.0 0.0 0.0"/>
    <limit upper="0.425" lower="-0.550" effort="10" velocity="1.5"/>
  </joint>

  <joint name="lf1_lf2" type="revolute">
    <origin xyz="-4E-05 0.0197 0" rpy="0 0 0"/>
    <parent link="lf1"/>
    <child link="lf2"/>
    <axis xyz="0.0 1.0 0.0"/>
    <limit upper="2.40" lower="0.55" effort="10" velocity="1.5"/>
  </joint>

  <joint name="lf2_lf3" type="revolute">
    <origin xyz="0 0.00475 -0.05" rpy="0 0 0"/>
    <parent link="lf2"/>
    <child link="lf3"/>
    <axis xyz="0.0 1.0 0.0"/>
    <limit upper="-0.22" lower="-2.18" effort="10" velocity="1.5"/>
  </joint>

  <joint name="base_rf1" type="revolute">
    <origin xyz="0.05 -0.0235 0.0" rpy="0 0 0"/>
    <parent link="base_link"/>
    <child link="rf1"/>
    <axis xyz="1.0 0.0 0.0"/>
    <limit upper="0.550" lower="-0.425" effort="10" velocity="1.5"/>
  </joint>

  <joint name="rf1_rf2" type="revolute">
    <origin xyz="-4E-05 -0.0197 0" rpy="0 0 0"/>
    <parent link="rf1"/>
    <child link="rf2"/>
    <axis xyz="0.0 1.0 0.0"/>
    <limit upper="2.40" lower="0.55" effort="10" velocity="1.5"/>
  </joint>

  <joint name="rf2_rf3" type="revolute">
    <origin xyz="0 -0.00475 -0.05" rpy="0 0 0"/>
    <parent link="rf2"/>
    <child link="rf3"/>
    <axis xyz="0.0 1.0 0.0"/>
    <limit upper="-0.22" lower="-2.18" effort="10" velocity="1.5"/>
  </joint>

  <joint name="base_rb1" type="revolute">
    <origin xyz="-0.066 -0.0235 0.0" rpy="0 0 0"/>
    <parent link="base_link"/>
    <child link="rb1"/>
    <axis xyz="1.0 0.0 0.0"/>
    <limit upper="0.550" lower="-0.425" effort="10" velocity="1.5"/>
  </joint>

  <joint name="rb1_rb2" type="revolute">
    <origin xyz="-4E-05 -0.0197 0" rpy="0 0 0"/>
    <parent link="rb1"/>
    <child link="rb2"/>
    <axis xyz="0.0 1.0 0.0"/>
    <limit upper="2.40" lower="0.55" effort="10" velocity="1.5"/>
  </joint>

  <joint name="rb2_rb3" type="revolute">
    <origin xyz="0 -0.00475 -0.05" rpy="0 0 0"/>
    <parent link="rb2"/>
    <child link="rb3"/>
    <axis xyz="0.0 1.0 0.0"/>
    <limit upper="-0.22" lower="-2.18" effort="10" velocity="1.5"/>
  </joint>

  <joint name="base_lb1" type="revolute">
    <origin xyz="-0.066 0.0235 0.0" rpy="0 0 0"/>
    <parent link="base_link"/>
    <child link="lb1"/>
    <axis xyz="1.0 0.0 0.0"/>
    <limit upper="0.425" lower="-0.550" effort="10" velocity="1.5"/>
  </joint>

  <joint name="lb1_lb2" type="revolute">
    <origin xyz="-4E-05 0.0197 0" rpy="0 0 0"/>
    <parent link="lb1"/>
    <child link="lb2"/>
    <axis xyz="0.0 1.0 0.0"/>
    <limit upper="2.40" lower="0.55" effort="10" velocity="1.5"/>
  </joint>

  <joint name="lb2_lb3" type="revolute">
    <origin xyz="0 0.00475 -0.05" rpy="0 0 0"/>
    <parent link="lb2"/>
    <child link="lb3"/>
    <axis xyz="0.0 1.0 0.0"/>
    <limit upper="-0.22" lower="-2.18" effort="10" velocity="1.5"/>
  </joint>

  <joint name="base_front" type="fixed">
    <origin xyz="0.089299 -5e-06 -0.015543" rpy="0 0 0"/>
    <parent link="base_link"/>
    <child link="Body_front"/>
  </joint>

  <joint name="base_board" type="fixed">
    <origin xyz="-0.087701 -0.023505 0.026457" rpy="0 0 0"/>
    <parent link="base_link"/>
    <child link="Board_PCB"/>
  </joint>

  <joint name="base_cn1" type="fixed">
    <origin xyz="0.149035 0.023472 0.0" rpy="0 0 0"/>
    <parent link="Board_PCB"/>
    <child link="Board_connectors_1"/>
  </joint>

  <joint name="base_cn2" type="fixed">
    <origin xyz="0.042355 0.0235 0.0" rpy="0 0 0"/>
    <parent link="Board_PCB"/>
    <child link="Board_connectors_2"/>
  </joint>

  <joint name="pcb_lidar" type="fixed">
    <origin xyz="0.009 0.024 0.042" rpy="0 0 1.57" />
    <parent link="Board_PCB" />
    <child link="lidar_link" />
  </joint>

  <joint name="rf3_foot" type="fixed">
    <origin xyz="0 0 -0.056" rpy="0 0 0"/>
    <parent link="rf3"/>
    <child link="rffoot"/>
  </joint>

  <joint name="rb3_foot" type="fixed">
    <origin xyz="0 0 -0.056" rpy="0 0 0"/>
    <parent link="rb3"/>
    <child link="rbfoot"/>
  </joint>

  <joint name="lb3_foot" type="fixed">
    <origin xyz="0 0 -0.056" rpy="0 0 0"/>
    <parent link="lb3"/>
    <child link="lbfoot"/>
  </joint>

  <joint name="lf3_foot" type="fixed">
    <origin xyz="0 0 -0.056" rpy="0 0 0"/>
    <parent link="lf3"/>
    <child link="lffoot"/>
  </joint>

  <joint name="lf1_hip" type="fixed">
    <origin xyz="0.01076 0.0307 0.013" rpy="0 0 0"/>
    <parent link="lf1"/>
    <child link="lpf1"/>
  </joint>

  <joint name="lb1_hip" type="fixed">
    <origin xyz="0.01076 0.0307 0.013" rpy="0 0 0"/>
    <parent link="lb1"/>
    <child link="lpb1"/>
  </joint>

  <joint name="rf1_hip" type="fixed">
    <origin xyz="0.01076 -0.0307 0.013" rpy="0 0 0"/>
    <parent link="rf1"/>
    <child link="rpf1"/>
  </joint>

  <joint name="rb2_hip" type="fixed">
    <origin xyz="0.01076 -0.0307 0.013" rpy="0 0 0"/>
    <parent link="rb1"/>
    <child link="rpb1"/>
  </joint>

  <joint name="lf2_shell" type="fixed">
    <origin xyz="0 0.01 -0.05" rpy="0 0 0"/>
    <parent link="lf2"/>
    <child link="lpf2"/>
  </joint>

  <joint name="lb2_shell" type="fixed">
    <origin xyz="0 0.01 -0.05" rpy="0 0 0"/>
    <parent link="lb2"/>
    <child link="lpb2"/>
  </joint>

  <joint name="rf2_shell" type="fixed">
    <origin xyz="0 -0.01 -0.05" rpy="0 0 0"/>
    <parent link="rf2"/>
    <child link="rpf2"/>
  </joint>

  <joint name="rb2_shell" type="fixed">
    <origin xyz="0 -0.01 -0.05" rpy="0 0 0"/>
    <parent link="rb2"/>
    <child link="rpb2"/>
  </joint>

  <joint name="base_sides" type="fixed">
    <origin xyz="-0.002701 -0.030005 -0.016293" rpy="0 0 0"/>
    <parent link="base_link"/>
    <child link="Shell_Side"/>
  </joint>
  <ros2_control name="GazeboSystem" type="system">
    <hardware>
      <plugin>gazebo_ros2_control/GazeboSystem</plugin>
    </hardware>
    <joint name="base_lf1">
      <command_interface name="effort"/> 
      <state_interface name="position"/>
      <state_interface name="velocity"/>
    </joint>
    <joint name="lf1_lf2">
      <command_interface name="effort"/> 
      <state_interface name="position"/>
      <state_interface name="velocity"/>
    </joint>
    <joint name="lf2_lf3">
      <command_interface name="effort"/> 
      <state_interface name="position"/>
      <state_interface name="velocity"/>
    </joint>
    <joint name="base_rf1">
      <command_interface name="effort"/> 
      <state_interface name="position"/>
      <state_interface name="velocity"/>
    </joint>
    <joint name="rf1_rf2">
      <command_interface name="effort"/> 
      <state_interface name="position"/>
      <state_interface name="velocity"/>
    </joint>
    <joint name="rf2_rf3">
      <command_interface name="effort"/> 
      <state_interface name="position"/>
      <state_interface name="velocity"/>
    </joint>
    <joint name="base_lb1">
      <command_interface name="effort"/> 
      <state_interface name="position"/>
      <state_interface name="velocity"/>
    </joint>
    <joint name="lb1_lb2">
      <command_interface name="effort"/> 
      <state_interface name="position"/>
      <state_interface name="velocity"/>
    </joint>
    <joint name="lb2_lb3">
      <command_interface name="effort"/> 
      <state_interface name="position"/>
      <state_interface name="velocity"/>
    </joint>
    <joint name="base_rb1">
      <command_interface name="effort"/> 
      <state_interface name="position"/>
      <state_interface name="velocity"/>
    </joint>
    <joint name="rb1_rb2">
      <command_interface name="effort"/> 
      <state_interface name="position"/>
      <state_interface name="velocity"/>
    </joint>
    <joint name="rb2_rb3">
      <command_interface name="effort"/> 
      <state_interface name="position"/>
      <state_interface name="velocity"/>
    </joint>
  </ros2_control>
  <!-- coloring Gazebo model -->
  <gazebo reference="base_link">
    <material>Gazebo/FlatBlack</material>
  </gazebo>
  <gazebo reference="Board_PCB">
    <material>Gazebo/FlatBlack</material>
  </gazebo>
  <gazebo reference="Body_front">
    <material>Gazebo/Yellow</material>
  </gazebo>
  <gazebo reference="Shell_Side">
    <material>Gazebo/Yellow</material>
  </gazebo>
  <gazebo reference="Board_connectors_1">
    <material>Gazebo/Orange</material>
  </gazebo>
  <gazebo reference="Board_connectors_2">
    <material>Gazebo/White</material>
  </gazebo>
  
  <gazebo reference="lf1">
    <kp>30000.0</kp>
    <kd>1.0</kd>
    <mu1>0.8</mu1>
    <mu2>0.8</mu2>
    <maxVel>0.0</maxVel>
    <minDepth>0.001</minDepth>
    <material>Gazebo/FlatBlack</material>
  </gazebo>
  <gazebo reference="lpf1">
    <material>Gazebo/Yellow</material>
  </gazebo>
  <gazebo reference="lf2">
    <kp>30000.0</kp>
    <kd>1.0</kd>
    <mu1>0.8</mu1>
    <mu2>0.8</mu2>
    <maxVel>0.0</maxVel>
    <minDepth>0.001</minDepth>
    <material>Gazebo/FlatBlack</material>
  </gazebo>
  <gazebo reference="lpf2">
    <material>Gazebo/Yellow</material>
  </gazebo>
  <gazebo reference="lf3">
    <kp>30000.0</kp>
    <kd>1.0</kd>
    <mu1>0.8</mu1>
    <mu2>0.8</mu2>
    <maxVel>0.0</maxVel>
    <minDepth>0.001</minDepth>
    <material>Gazebo/FlatBlack</material>
  </gazebo>
  <gazebo reference="lffoot">
    <kp>30000.0</kp>
    <kd>1.0</kd>
    <mu1>0.8</mu1>
    <mu2>0.8</mu2>
    <maxVel>0.0</maxVel>
    <minDepth>0.001</minDepth>
    <material>Gazebo/FlatBlack</material>
  </gazebo>
  <gazebo reference="rf1">
    <kp>30000.0</kp>
    <kd>1.0</kd>
    <mu1>0.8</mu1>
    <mu2>0.8</mu2>
    <maxVel>0.0</maxVel>
    <minDepth>0.001</minDepth>
    <material>Gazebo/FlatBlack</material>
  </gazebo>
  <gazebo reference="rpf1">
    <material>Gazebo/Yellow</material>
  </gazebo>
  <gazebo reference="rf2">
    <kp>30000.0</kp>
    <kd>1.0</kd>
    <mu1>0.8</mu1>
    <mu2>0.8</mu2>
    <maxVel>0.0</maxVel>
    <minDepth>0.001</minDepth>
    <material>Gazebo/FlatBlack</material>
  </gazebo>
  <gazebo reference="rpf2">
    <material>Gazebo/Yellow</material>
  </gazebo>
  <gazebo reference="rf3">
    <kp>30000.0</kp>
    <kd>1.0</kd>
    <mu1>0.8</mu1>
    <mu2>0.8</mu2>
    <maxVel>0.0</maxVel>
    <minDepth>0.001</minDepth>
    <material>Gazebo/FlatBlack</material>
  </gazebo>
  <gazebo reference="rffoot">
    <kp>30000.0</kp>
    <kd>1.0</kd>
    <mu1>0.8</mu1>
    <mu2>0.8</mu2>
    <maxVel>0.0</maxVel>
    <minDepth>0.001</minDepth>
    <material>Gazebo/FlatBlack</material>
  </gazebo>
  <gazebo reference="lb1">
    <kp>30000.0</kp>
    <kd>1.0</kd>
    <mu1>0.8</mu1>
    <mu2>0.8</mu2>
    <maxVel>0.0</maxVel>
    <minDepth>0.001</minDepth>
    <material>Gazebo/FlatBlack</material>
  </gazebo>
  <gazebo reference="lpb1">
    <material>Gazebo/Yellow</material>
  </gazebo>
  <gazebo reference="lb2">
    <kp>30000.0</kp>
    <kd>1.0</kd>
    <mu1>0.8</mu1>
    <mu2>0.8</mu2>
    <maxVel>0.0</maxVel>
    <minDepth>0.001</minDepth>
    <material>Gazebo/FlatBlack</material>
  </gazebo>
  <gazebo reference="lpb2">
    <material>Gazebo/Yellow</material>
  </gazebo>
  <gazebo reference="lb3">
    <kp>30000.0</kp>
    <kd>1.0</kd>
    <mu1>0.8</mu1>
    <mu2>0.8</mu2>
    <maxVel>0.0</maxVel>
    <minDepth>0.001</minDepth>
    <material>Gazebo/FlatBlack</material>
  </gazebo>
  <gazebo reference="lbfoot">
    <kp>30000.0</kp>
    <kd>1.0</kd>
    <mu1>0.8</mu1>
    <mu2>0.8</mu2>
    <maxVel>0.0</maxVel>
    <minDepth>0.001</minDepth>
    <material>Gazebo/FlatBlack</material>
  </gazebo>
  <gazebo reference="rb1">
    <kp>30000.0</kp>
    <kd>1.0</kd>
    <mu1>0.8</mu1>
    <mu2>0.8</mu2>
    <maxVel>0.0</maxVel>
    <minDepth>0.001</minDepth>
    <material>Gazebo/FlatBlack</material>
  </gazebo>
  <gazebo reference="rpb1">
    <material>Gazebo/Yellow</material>
  </gazebo>
  <gazebo reference="rb2">
    <kp>30000.0</kp>
    <kd>1.0</kd>
    <mu1>0.8</mu1>
    <mu2>0.8</mu2>
    <maxVel>0.0</maxVel>
    <minDepth>0.001</minDepth>
    <material>Gazebo/FlatBlack</material>
  </gazebo>
  <gazebo reference="rpb2">
    <material>Gazebo/Yellow</material>
  </gazebo>
  <gazebo reference="rb3">
    <kp>30000.0</kp>
    <kd>1.0</kd>
    <mu1>0.8</mu1>
    <mu2>0.8</mu2>
    <maxVel>0.0</maxVel>
    <minDepth>0.001</minDepth>
    <material>Gazebo/FlatBlack</material>
  </gazebo>
  <gazebo reference="rbfoot">
    <kp>30000.0</kp>
    <kd>1.0</kd>
    <mu1>0.8</mu1>
    <mu2>0.8</mu2>
    <maxVel>0.0</maxVel>
    <minDepth>0.001</minDepth>
    <material>Gazebo/FlatBlack</material>
  </gazebo>

  <gazebo reference="lidar_link">
    <material>Gazebo/FlatBlack</material>
    <sensor type="ray" name="lidar">
      <always_on>true</always_on>
      <update_rate>30</update_rate>
      <pose>0 0 0 0 0 0</pose>
      <visualize>false</visualize>
      <ray>
        <scan>
          <horizontal>
            <samples>1040</samples>
            <resolution>1</resolution>
            <min_angle>0</min_angle>
            <max_angle>6.28</max_angle>
          </horizontal>
        </scan>
        <range>
          <min>0.2</min>
          <max>50.0</max>
          <resolution>0.01</resolution>
        </range>
        <noise>
          <type>gaussian</type>
          <mean>0.0</mean>
          <stddev>0.004</stddev>
        </noise>
      </ray>
      <plugin name="gazebo_ros_lidar_controller" filename="libgazebo_ros_ray_sensor.so">
        <ros>
          <remapping>~/out:=/scan</remapping>
        </ros>
        <output_type>sensor_msgs/LaserScan</output_type>
        <frame_name>lidar_link</frame_name> 
      </plugin>
    </sensor>
  </gazebo> 

  <gazebo>
    <plugin filename="libgazebo_ros_p3d.so" name="p3d_base_controller">
      <ros>
        <remapping>odom:=odom/ground_truth</remapping>
      </ros>
      <body_name>base_link</body_name>
      <frame_name>world</frame_name>
      <update_rate>10.0</update_rate>
      <xyz_offset>0 0 0</xyz_offset>
      <rpy_offset>0 0 0</rpy_offset>
      <gaussian_noise>0.01</gaussian_noise>
    </plugin>
  </gazebo>

  <gazebo>
    <plugin filename="libgazebo_ros2_control.so" name="gazebo_ros2_control">
      <parameters>$(find mini_pupper_2_description)/config/ros_control/mini_pupper_controller.yaml</parameters>
    </plugin>
  </gazebo>
  
  <link name="imu_link">
    <inertial>
      <mass value="0.0001"/>
      <origin rpy="0 0 0" xyz="0 0 0"/>
      <inertia ixx="1e-09" ixy="0.0" ixz="0.0" iyy="1e-09" iyz="0.0" izz="1e-09"/>
    </inertial>
  </link>

  <joint name="imu_joint" type="fixed">
    <parent link="base_link"/>
    <child link="imu_link"/>
  </joint>

  <gazebo reference="imu_link">
    <sensor name="imu_controller" type="imu">
      <always_on>true</always_on>
      <update_rate>50</update_rate>
      <plugin name="gazebo_ros_imu_sensor" filename="libgazebo_ros_imu_sensor.so">
          <ros>
              <namespace>/imu</namespace>
              <remapping>~/out:=data</remapping>
          </ros>
      </plugin>
    </sensor>
  </gazebo>

</robot>