<?xml version="1.0" ?>
<robot name="mini_pupper" xmlns:xacro="http://www.ros.org/wiki/xacro">

  <xacro:include filename="$(find mini_pupper_2_description)/urdf/materials.xacro" />
  <xacro:include filename="$(find mini_pupper_2_description)/urdf/mini_pupper_description.trans" />
  <link name="base_link">
    <visual>
      <origin xyz="0 0 0" rpy="0 0 0"/>
      <geometry>
        <mesh filename="file://$(find mini_pupper_2_description)/meshes/base_link.stl" scale="1 1 1"/>
      </geometry>
      <material name="opaque252525"/>
    </visual>
    <collision>
      <origin xyz="0 0 0" rpy="0 0 0"/>
      <geometry>
        <mesh filename="file://$(find mini_pupper_2_description)/meshes/base_link.stl" scale="1 1 1"/>
      </geometry>
    </collision>
  </link>

  <link name="base_inertia">
    <inertial>
      <origin xyz="-0.008867 0.000646 -0.007154" rpy="0 0 0"/>
      <mass value="0.09818420433466489"/>
      <inertia ixx="5.2003168e-05" iyy="2.437e-4" izz="2.523e-4" ixy="7.28047e-07" iyz="6.0331e-07" ixz="-9.716561e-06"/>
    </inertial>
  </link>

  <link name="lf1">
    <inertial>
      <origin xyz="0.020109281613098752 0.002331771723067172 0.0064994497731911665" rpy="0 0 0"/>
      <mass value="0.020769030109708524"/>
      <inertia ixx="2.494e-06" iyy="3.736e-06" izz="3.223e-06" ixy="-7.659e-9" iyz="0.072e-9" ixz="-33.608e-9"/>
    </inertial>
    <visual>
      <origin xyz="-0.037299 -0.023745 -5.7e-05" rpy="0 0 0"/>
      <geometry>
        <mesh filename="file://$(find mini_pupper_2_description)/meshes/lf1.stl" scale="1 1 1"/>
      </geometry>
      <material name="opaque666666"/>
    </visual>
    <collision>
      <origin xyz="-0.037299 -0.023745 -5.7e-05" rpy="0 0 0"/>
      <geometry>
        <mesh filename="file://$(find mini_pupper_2_description)/meshes/lf1.stl" scale="1 1 1"/>
      </geometry>
    </collision>
  </link>

  <link name="lf2">
    <inertial>
      <origin xyz="-0.0031735030993243693 0.000986055889313886 -0.01798354657247523" rpy="0 0 0"/>
      <mass value="0.0019057729925096327"/>
      <inertia ixx="0.462154e-6" iyy="0.481174e-6" izz="26.893e-9" ixy="3.117e-9" iyz="17.662e-9" ixz="-79.269e-9"/>
    </inertial>
    <visual>
      <origin xyz="-0.052165 -0.041445 -5.7e-05" rpy="0 0 0"/>
      <geometry>
        <mesh filename="file://$(find mini_pupper_2_description)/meshes/lf2.stl" scale="1 1 1"/>
      </geometry>
      <material name="opaque636363"/>
    </visual>
    <collision>
      <origin xyz="-0.052165 -0.041445 -5.7e-05" rpy="0 0 0"/>
      <geometry>
        <mesh filename="file://$(find mini_pupper_2_description)/meshes/lf2.stl" scale="1 1 1"/>
      </geometry>
    </collision>
  </link>

  <link name="lf3">
    <inertial>
      <origin xyz="0.006210627225594921 0.003455723027058405 -0.015013638057132746" rpy="0 0 0"/>
      <mass value="0.0011438144457690698"/>
      <inertia ixx="0.484118e-6" iyy="0.567346e-06" izz="91.82e-9" ixy="-2.157e-9" iyz="4.945e-9" ixz="0.200546e-6"/>
    </inertial>
    <visual>
      <origin xyz="-0.043476 -0.044445 0.049183" rpy="0 0 0"/>
      <geometry>
        <mesh filename="file://$(find mini_pupper_2_description)/meshes/lf3.stl" scale="1 1 1"/>
      </geometry>
      <material name="opaque252525"/>
    </visual>
    <collision>
      <origin xyz="-0.043476 -0.044445 0.049183" rpy="0 0 0"/>
      <geometry>
        <mesh filename="file://$(find mini_pupper_2_description)/meshes/lf3.stl" scale="1 1 1"/>
      </geometry>
    </collision>
  </link>

  <link name="rf1">
    <inertial>
      <origin xyz="0.020106742599110078 -0.00233237781568562 0.006497900858401761" rpy="0 0 0"/>
      <mass value="0.020769549324466178"/>
      <inertia ixx="2.494e-06" iyy="3.736e-06" izz="3.223e-06" ixy="7.618e-9" iyz="0.098e-9" ixz="-37.629e-9"/>
    </inertial>
    <visual>
      <origin xyz="-0.037299 0.023255 -5.7e-05" rpy="0 0 0"/>
      <geometry>
        <mesh filename="file://$(find mini_pupper_2_description)/meshes/rf1.stl" scale="1 1 1"/>
      </geometry>
      <material name="opaque666666"/>
    </visual>
    <collision>
      <origin xyz="-0.037299 0.023255 -5.7e-05" rpy="0 0 0"/>
      <geometry>
        <mesh filename="file://$(find mini_pupper_2_description)/meshes/rf1.stl" scale="1 1 1"/>
      </geometry>
    </collision>
  </link>

  <link name="rf2">
    <inertial>
      <origin xyz="-0.00317137334512671 -0.000986627579459616 -0.01798392230653304" rpy="0 0 0"/>
      <mass value="0.0019057729924780605"/>
      <inertia ixx="0.462172e-6" iyy="0.481174e-6" izz="26.874e-9" ixy="-3.114e-9" iyz="-17.663e-9" ixz="-79.218e-9"/>
    </inertial>
    <visual>
      <origin xyz="-0.052165 0.040955 -5.7e-05" rpy="0 0 0"/>
      <geometry>
        <mesh filename="file://$(find mini_pupper_2_description)/meshes/rf2.stl" scale="1 1 1"/>
      </geometry>
      <material name="opaque636363"/>
    </visual>
    <collision>
      <origin xyz="-0.052165 0.040955 -5.7e-05" rpy="0 0 0"/>
      <geometry>
        <mesh filename="file://$(find mini_pupper_2_description)/meshes/rf2.stl" scale="1 1 1"/>
      </geometry>
    </collision>
  </link>

  <link name="rf3">
    <inertial>
      <origin xyz="0.006211719758792998 -0.0034574884973188197 -0.01500899883342268" rpy="0 0 0"/>
      <mass value="0.001143490701517533"/>
      <inertia ixx="0.484726e-6" iyy="0.567959e-06" izz="91.882e-9" ixy="2.056e-9" iyz="-4.954e-9" ixz="0.200706e-6"/>
    </inertial>
    <visual>
      <origin xyz="-0.043482 0.043955 0.049184" rpy="0 0 0"/>
      <geometry>
        <mesh filename="file://$(find mini_pupper_2_description)/meshes/rf3.stl" scale="1 1 1"/>
      </geometry>
      <material name="opaque252525"/>
    </visual>
    <collision>
      <origin xyz="-0.043482 0.043955 0.049184" rpy="0 0 0"/>
      <geometry>
        <mesh filename="file://$(find mini_pupper_2_description)/meshes/rf3.stl" scale="1 1 1"/>
      </geometry>
    </collision>
  </link>

  <link name="rb1">
    <inertial>
      <origin xyz="-0.020107177922528044 -0.0023288309787250286 0.006502376356642127" rpy="0 0 0"/>
      <mass value="0.020769549324363486"/>
      <inertia ixx="2.494e-06" iyy="3.736e-06" izz="3.223e-06" ixy="-7.639e-9" iyz="-0.378e-9" ixz="-37.624e-9"/>
    </inertial>
    <visual>
      <origin xyz="0.042701 0.023255 -5.7e-05" rpy="0 0 0"/>
      <geometry>
        <mesh filename="file://$(find mini_pupper_2_description)/meshes/rb1.stl" scale="1 1 1"/>
      </geometry>
      <material name="opaque666666"/>
    </visual>
    <collision>
      <origin xyz="0.042701 0.023255 -5.7e-05" rpy="0 0 0"/>
      <geometry>
        <mesh filename="file://$(find mini_pupper_2_description)/meshes/rb1.stl" scale="1 1 1"/>
      </geometry>
    </collision>
  </link>

  <link name="rb2">
    <inertial>
      <origin xyz="-0.0031709881638501275 -0.0009964344348111775 -0.017982726579309202" rpy="0 0 0"/>
      <mass value="0.0019057729926311429"/>
      <inertia ixx="0.462172e-6" iyy="0.481155e-6" izz="26.893e-9" ixy="-3.158e-9" iyz="-17.911e-9" ixz="-79.911e-9"/>
    </inertial>
    <visual>
      <origin xyz="0.068367 0.040955 -6.6e-05" rpy="0 0 0"/>
      <geometry>
        <mesh filename="file://$(find mini_pupper_2_description)/meshes/rb2.stl" scale="1 1 1"/>
      </geometry>
      <material name="opaque636363"/>
    </visual>
    <collision>
      <origin xyz="0.068367 0.040955 -6.6e-05" rpy="0 0 0"/>
      <geometry>
        <mesh filename="file://$(find mini_pupper_2_description)/meshes/rb2.stl" scale="1 1 1"/>
      </geometry>
    </collision>
  </link>

  <link name="rb3">
    <inertial>
      <origin xyz="0.006208573190273861 -0.0034623583329196975 -0.015001217060300935" rpy="0 0 0"/>
      <mass value="0.0011440535724654094"/>
      <inertia ixx="0.484539e-6" iyy="0.567687e-06" izz="91.857e-9" ixy="2.182e-9" iyz="-5.285e-9" ixz="0.200597e-6"/>
    </inertial>
    <visual>
      <origin xyz="0.077049 0.043982 0.049173" rpy="0 0 0"/>
      <geometry>
        <mesh filename="file://$(find mini_pupper_2_description)/meshes/rb3.stl" scale="1 1 1"/>
      </geometry>
      <material name="opaque252525"/>
    </visual>
    <collision>
      <origin xyz="0.077049 0.043982 0.049173" rpy="0 0 0"/>
      <geometry>
        <mesh filename="file://$(find mini_pupper_2_description)/meshes/rb3.stl" scale="1 1 1"/>
      </geometry>
    </collision>
  </link>

  <link name="lb1">
    <inertial>
      <origin xyz="-0.020109716415830967 0.0023317718989125207 0.006499556305653081" rpy="0 0 0"/>
      <mass value="0.020769030189864354"/>
      <inertia ixx="2.494e-06" iyy="3.736e-06" izz="3.223e-06" ixy="7.659e-9" iyz="-0.072e-9" ixz="-33.608e-9"/>
    </inertial>
    <visual>
      <origin xyz="0.042701 -0.023745 -5.7e-05" rpy="0 0 0"/>
      <geometry>
        <mesh filename="file://$(find mini_pupper_2_description)/meshes/lb1.stl" scale="1 1 1"/>
      </geometry>
      <material name="opaque666666"/>
    </visual>
    <collision>
      <origin xyz="0.042701 -0.023745 -5.7e-05" rpy="0 0 0"/>
      <geometry>
        <mesh filename="file://$(find mini_pupper_2_description)/meshes/lb1.stl" scale="1 1 1"/>
      </geometry>
    </collision>
  </link>

  <link name="lb2">
    <inertial>
      <origin xyz="-0.0031709879518865836 0.0009860564153100285 -0.01798392227051571" rpy="0 0 0"/>
      <mass value="0.0019057729925095609"/>
      <inertia ixx="0.462172e-6" iyy="0.481174e-6" izz="26.874e-9" ixy="3.114e-9" iyz="17.663e-9" ixz="-79.218e-9"/>
    </inertial>
    <visual>
      <origin xyz="0.068367 -0.041445 -5.7e-05" rpy="0 0 0"/>
      <geometry>
        <mesh filename="file://$(find mini_pupper_2_description)/meshes/lb2.stl" scale="1 1 1"/>
      </geometry>
      <material name="opaque636363"/>
    </visual>
    <collision>
      <origin xyz="0.068367 -0.041445 -5.7e-05" rpy="0 0 0"/>
      <geometry>
        <mesh filename="file://$(find mini_pupper_2_description)/meshes/lb2.stl" scale="1 1 1"/>
      </geometry>
    </collision>
  </link>

  <link name="lb3">
    <inertial>
      <origin xyz="0.006208905683926957 0.0034523757482988054 -0.015005654191541921" rpy="0 0 0"/>
      <mass value="0.001144346207072784"/>
      <inertia ixx="0.484492e-6" iyy="0.567176e-06" izz="91.41e-9" ixy="-2.023e-9" iyz="4.977e-9" ixz="0.200063e-6"/>
    </inertial>
    <visual>
      <origin xyz="0.077049 -0.044445 0.049184" rpy="0 0 0"/>
      <geometry>
        <mesh filename="file://$(find mini_pupper_2_description)/meshes/lb3.stl" scale="1 1 1"/>
      </geometry>
      <material name="opaque252525"/>
    </visual>
    <collision>
      <origin xyz="0.077049 -0.044445 0.049184" rpy="0 0 0"/>
      <geometry>
        <mesh filename="file://$(find mini_pupper_2_description)/meshes/lb3.stl" scale="1 1 1"/>
      </geometry>
    </collision>
  </link>

  <link name="Body_front">
    <inertial>
      <origin xyz="-0.005538678480206852 -0.00020424196520824284 0.020222593513387798" rpy="0 0 0"/>
      <mass value="0.00785515871148119"/>
      <inertia ixx="5e-06" iyy="2e-06" izz="4e-06" ixy="0.0" iyz="0.0" ixz="0.0"/>
    </inertial>
    <visual>
      <origin xyz="-0.089299 -0.000245 0.015543" rpy="0 0 0"/>
      <geometry>
        <mesh filename="file://$(find mini_pupper_2_description)/meshes/Body_front.stl" scale="1 1 1"/>
      </geometry>
      <material name="opaque2552210"/>
    </visual>
    <collision>
      <origin xyz="-0.089299 -0.000245 0.015543" rpy="0 0 0"/>
      <geometry>
        <mesh filename="file://$(find mini_pupper_2_description)/meshes/Body_front.stl" scale="1 1 1"/>
      </geometry>
    </collision>
  </link>

  <link name="Board_PCB">
    <inertial>
      <origin xyz="0.08946128454598752 0.025716073555853 -3.6415040620890043e-05" rpy="0 0 0"/>
      <mass value="0.014261552601793053"/>
      <inertia ixx="4e-06" iyy="3.5e-05" izz="3.9e-05" ixy="0.0" iyz="0.0" ixz="0.0"/>
    </inertial>
    <visual>
      <origin xyz="0.087701 0.023255 -0.026457" rpy="0 0 0"/>
      <geometry>
        <mesh filename="file://$(find mini_pupper_2_description)/meshes/Board_PCB.stl" scale="1 1 1"/>
      </geometry>
      <material name="opaque646464"/>
    </visual>
    <collision>
      <origin xyz="0.087701 0.023255 -0.026457" rpy="0 0 0"/>
      <geometry>
        <mesh filename="file://$(find mini_pupper_2_description)/meshes/Board_PCB.stl" scale="1 1 1"/>
      </geometry>
    </collision>
  </link>

  <link name="Board_connectors_1">
    <inertial>
      <origin xyz="-0.07276303117117414 -0.002323344081837563 -0.0010631239213060653" rpy="0 0 0"/>
      <mass value="0.004688613655947816"/>
      <inertia ixx="0.203205e-6" iyy="1.5404404e-05" izz="1.5546403e-05" ixy="-0.625328e-06" iyz="42.901e-9" ixz="0.186346e-9"/>
    </inertial>
    <visual>
      <origin xyz="-0.061334 -0.000217 -0.026457" rpy="0 0 0"/>
      <geometry>
        <mesh filename="file://$(find mini_pupper_2_description)/meshes/Board_connectors_1.stl" scale="1 1 1"/>
      </geometry>
      <material name="opaque2491590"/>
    </visual>
    <collision>
      <origin xyz="-0.061334 -0.000217 -0.026457" rpy="0 0 0"/>
      <geometry>
        <mesh filename="file://$(find mini_pupper_2_description)/meshes/Board_connectors_1.stl" scale="1 1 1"/>
      </geometry>
    </collision>
  </link>

  <link name="Board_connectors_2">
    <inertial>
      <origin xyz="0.008233541174180986 -0.002138369786547657 -0.00030110978110910874" rpy="0 0 0"/>
      <mass value="0.0019746031301169403"/>
      <inertia ixx="0.458176e-6" iyy="3.284711e-06" izz="3.720353e-06" ixy="-79.81e-9" iyz="4.793e-9" ixz="0.123862e-9"/>
    </inertial>
    <visual>
      <origin xyz="0.045346 -0.000245 -0.026457" rpy="0 0 0"/>
      <geometry>
        <mesh filename="file://$(find mini_pupper_2_description)/meshes/Board_connectors_2.stl" scale="1 1 1"/>
      </geometry>
      <material name="opaque255255255"/>
    </visual>
    <collision>
      <origin xyz="0.045346 -0.000245 -0.026457" rpy="0 0 0"/>
      <geometry>
        <mesh filename="file://$(find mini_pupper_2_description)/meshes/Board_connectors_2.stl" scale="1 1 1"/>
      </geometry>
    </collision>
  </link>

  <link name="rffoot">
    <inertial>
      <origin xyz="-0.004983173489839052 -2.855799938611403e-07 0.006488367917121082" rpy="0 0 0"/>
      <mass value="0.0014053107976262874"/>
      <inertia ixx="41.992e-9" iyy="62.399e-9" izz="29.801e-9" ixy="0.0" iyz="0.0" ixz="1.625e-9"/>
    </inertial>
    <visual>
      <origin xyz="-0.068108 0.047705 0.103614" rpy="0 0 0"/>
      <geometry>
        <mesh filename="file://$(find mini_pupper_2_description)/meshes/rffoot.stl" scale="1 1 1"/>
      </geometry>
      <material name="opaque666666"/>
    </visual>
    <collision>
      <origin xyz="-0.068108 0.047705 0.103614" rpy="0 0 0"/>
      <geometry>
        <mesh filename="file://$(find mini_pupper_2_description)/meshes/rffoot.stl" scale="1 1 1"/>
      </geometry>
    </collision>
  </link>

  <link name="rbfoot">
    <inertial>
      <origin xyz="-0.004982788301465979 3.706995898918042e-06 0.006488719406103974" rpy="0 0 0"/>
      <mass value="0.0014053107976262874"/>
      <inertia ixx="41.992e-9" iyy="62.399e-9" izz="29.801e-9" ixy="0.001e-9" iyz="-0.018e-9" ixz="1.625e-9"/>
    </inertial>
    <visual>
      <origin xyz="0.052424 0.047762 0.103601" rpy="0 0 0"/>
      <geometry>
        <mesh filename="file://$(find mini_pupper_2_description)/meshes/rbfoot.stl" scale="1 1 1"/>
      </geometry>
      <material name="opaque666666"/>
    </visual>
    <collision>
      <origin xyz="0.052424 0.047762 0.103601" rpy="0 0 0"/>
      <geometry>
        <mesh filename="file://$(find mini_pupper_2_description)/meshes/rbfoot.stl" scale="1 1 1"/>
      </geometry>
    </collision>
  </link>

  <link name="lbfoot">
    <inertial>
      <origin xyz="-0.004982788451759437 -2.855826620323798e-07 0.0064883680140642025" rpy="0 0 0"/>
      <mass value="0.0014053107976262874"/>
      <inertia ixx="41.992e-9" iyy="62.399e-9" izz="29.801e-9" ixy="0.0" iyz="0.0" ixz="1.625e-9"/>
    </inertial>
    <visual>
      <origin xyz="0.052424 -0.048195 0.103614" rpy="0 0 0"/>
      <geometry>
        <mesh filename="file://$(find mini_pupper_2_description)/meshes/lbfoot.stl" scale="1 1 1"/>
      </geometry>
      <material name="opaque666666"/>
    </visual>
    <collision>
      <origin xyz="0.052424 -0.048195 0.103614" rpy="0 0 0"/>
      <geometry>
        <mesh filename="file://$(find mini_pupper_2_description)/meshes/lbfoot.stl" scale="1 1 1"/>
      </geometry>
    </collision>
  </link>

  <link name="lffoot">
    <inertial>
      <origin xyz="-0.004983499344395154 -2.861132842799097e-07 0.006488888240325896" rpy="0 0 0"/>
      <mass value="0.0014053107976262874"/>
      <inertia ixx="41.992e-9" iyy="62.399e-9" izz="29.801e-9" ixy="0.0" iyz="0.0" ixz="1.625e-9"/>
    </inertial>
    <visual>
      <origin xyz="-0.068108 -0.048195 0.103611" rpy="0 0 0"/>
      <geometry>
        <mesh filename="file://$(find mini_pupper_2_description)/meshes/lffoot.stl" scale="1 1 1"/>
      </geometry>
      <material name="opaque666666"/>
    </visual>
    <collision>
      <origin xyz="-0.068108 -0.048195 0.103611" rpy="0 0 0"/>
      <geometry>
        <mesh filename="file://$(find mini_pupper_2_description)/meshes/lffoot.stl" scale="1 1 1"/>
      </geometry>
    </collision>
  </link>

  <link name="lpf1">
    <inertial>
      <origin xyz="0.002258882765982295 0.008667473212030541 -0.002747896746317195" rpy="0 0 0"/>
      <mass value="0.002573897544461238"/>
      <inertia ixx="0.390582e-6" iyy="0.412423e-6" izz="0.246322e-6" ixy="24.632e-9" iyz="3.861e-9" ixz="54.103e-9"/>
    </inertial>
    <visual>
      <origin xyz="-0.071565 -0.038245 -0.013057" rpy="0 0 0"/>
      <geometry>
        <mesh filename="file://$(find mini_pupper_2_description)/meshes/lpf1.stl" scale="1 1 1"/>
      </geometry>
      <material name="opaque2552210"/>
    </visual>
    <collision>
      <origin xyz="-0.071565 -0.038245 -0.013057" rpy="0 0 0"/>
      <geometry>
        <mesh filename="file://$(find mini_pupper_2_description)/meshes/lpf1.stl" scale="1 1 1"/>
      </geometry>
    </collision>
  </link>

  <link name="lpb1">
    <inertial>
      <origin xyz="0.0022592683660053597 0.008667473212031727 -0.0027478967463174797" rpy="0 0 0"/>
      <mass value="0.002573897544461238"/>
      <inertia ixx="0.390582e-6" iyy="0.412423e-6" izz="0.246322e-6" ixy="24.632e-9" iyz="3.861e-9" ixz="54.103e-9"/>
    </inertial>
    <visual>
      <origin xyz="0.048967 -0.038245 -0.013057" rpy="0 0 0"/>
      <geometry>
        <mesh filename="file://$(find mini_pupper_2_description)/meshes/lpb1.stl" scale="1 1 1"/>
      </geometry>
      <material name="opaque2552210"/>
    </visual>
    <collision>
      <origin xyz="0.048967 -0.038245 -0.013057" rpy="0 0 0"/>
      <geometry>
        <mesh filename="file://$(find mini_pupper_2_description)/meshes/lpb1.stl" scale="1 1 1"/>
      </geometry>
    </collision>
  </link>

  <link name="rpf1">
    <inertial>
      <origin xyz="0.002219644336096324 -0.008605630927951344 -0.002709000699399786" rpy="0 0 0"/>
      <mass value="0.002396251664132183"/>
      <inertia ixx="0.364377e-6" iyy="0.38866e-6" izz="0.234177e-6" ixy="-23.674e-9" iyz="-3.338e-9" ixz="52.098e-9"/>
    </inertial>
    <visual>
      <origin xyz="-0.071565 0.037755 -0.013057" rpy="0 0 0"/>
      <geometry>
        <mesh filename="file://$(find mini_pupper_2_description)/meshes/rpf1.stl" scale="1 1 1"/>
      </geometry>
      <material name="opaque2552210"/>
    </visual>
    <collision>
      <origin xyz="-0.071565 0.037755 -0.013057" rpy="0 0 0"/>
      <geometry>
        <mesh filename="file://$(find mini_pupper_2_description)/meshes/rpf1.stl" scale="1 1 1"/>
      </geometry>
    </collision>
  </link>

  <link name="rpb1">
    <inertial>
      <origin xyz="0.0022200295152449145 -0.008607013686777375 -0.0027033986949916797" rpy="0 0 0"/>
      <mass value="0.002396251664132183"/>
      <inertia ixx="0.364377e-6" iyy="0.388657e-6" izz="0.23418e-6" ixy="-23.645e-9" iyz="-3.422e-9" ixz="52.111e-9"/>
    </inertial>
    <visual>
      <origin xyz="0.048967 0.037748 -0.013064" rpy="0 0 0"/>
      <geometry>
        <mesh filename="file://$(find mini_pupper_2_description)/meshes/rpb1.stl" scale="1 1 1"/>
      </geometry>
      <material name="opaque2552210"/>
    </visual>
    <collision>
      <origin xyz="0.048967 0.037748 -0.013064" rpy="0 0 0"/>
      <geometry>
        <mesh filename="file://$(find mini_pupper_2_description)/meshes/rpb1.stl" scale="1 1 1"/>
      </geometry>
    </collision>
  </link>

  <link name="lpf2">
    <inertial>
      <origin xyz="-0.001747332142694763 0.00790352811362327 0.005364507913861985" rpy="0 0 0"/>
      <mass value="0.0022314211131891203"/>
      <inertia ixx="0.862549e-06" iyy="0.991391e-06" izz="0.139046e-6" ixy="1.254e-9" iyz="-13.212e-9" ixz="-0.112903e-9"/>
    </inertial>
    <visual>
      <origin xyz="-0.048863 -0.044445 0.018654" rpy="0 0 0"/>
      <geometry>
        <mesh filename="file://$(find mini_pupper_2_description)/meshes/lpf2.stl" scale="1 1 1"/>
      </geometry>
      <material name="opaque2552210"/>
    </visual>
    <collision>
      <origin xyz="-0.048863 -0.044445 0.018654" rpy="0 0 0"/>
      <geometry>
        <mesh filename="file://$(find mini_pupper_2_description)/meshes/lpf2.stl" scale="1 1 1"/>
      </geometry>
    </collision>
  </link>

  <link name="lpb2">
    <inertial>
      <origin xyz="-0.001747730780760487 0.007903528639619323 0.005365117008527457" rpy="0 0 0"/>
      <mass value="0.0022314211131891203"/>
      <inertia ixx="0.862549e-06" iyy="0.991391e-06" izz="0.139046e-6" ixy="1.254e-9" iyz="-13.212e-9" ixz="-0.112903e-9"/>
    </inertial>
    <visual>
      <origin xyz="0.071666 -0.044445 0.018655" rpy="0 0 0"/>
      <geometry>
        <mesh filename="file://$(find mini_pupper_2_description)/meshes/lpb2.stl" scale="1 1 1"/>
      </geometry>
      <material name="opaque2552210"/>
    </visual>
    <collision>
      <origin xyz="0.071666 -0.044445 0.018655" rpy="0 0 0"/>
      <geometry>
        <mesh filename="file://$(find mini_pupper_2_description)/meshes/lpb2.stl" scale="1 1 1"/>
      </geometry>
    </collision>
  </link>

  <link name="rpf2">
    <inertial>
      <origin xyz="-0.0018083907227202795 -0.007907075713007514 0.005388328467850496" rpy="0 0 0"/>
      <mass value="0.002201611562253873"/>
      <inertia ixx="0.859857e-06" iyy="0.986828e-06" izz="0.137126e-6" ixy="-1.292e-9" iyz="13.109e-9" ixz="-0.111508e-9"/>
    </inertial>
    <visual>
      <origin xyz="-0.048865 0.043955 0.018655" rpy="0 0 0"/>
      <geometry>
        <mesh filename="file://$(find mini_pupper_2_description)/meshes/rpf2.stl" scale="1 1 1"/>
      </geometry>
      <material name="opaque2552210"/>
    </visual>
    <collision>
      <origin xyz="-0.048865 0.043955 0.018655" rpy="0 0 0"/>
      <geometry>
        <mesh filename="file://$(find mini_pupper_2_description)/meshes/rpf2.stl" scale="1 1 1"/>
      </geometry>
    </collision>
  </link>

  <link name="rpb2">
    <inertial>
      <origin xyz="-0.0018090055415128231 -0.007904339012704771 0.005392934920359041" rpy="0 0 0"/>
      <mass value="0.002201611562253873"/>
      <inertia ixx="0.859857e-06" iyy="0.986842e-06" izz="0.137112e-6" ixy="-1.352e-9" iyz="12.645e-9" ixz="-0.111508e-9"/>
    </inertial>
    <visual>
      <origin xyz="0.071666 0.043965 0.018644" rpy="0 0 0"/>
      <geometry>
        <mesh filename="file://$(find mini_pupper_2_description)/meshes/rpb2.stl" scale="1 1 1"/>
      </geometry>
      <material name="opaque2552210"/>
    </visual>
    <collision>
      <origin xyz="0.071666 0.043965 0.018644" rpy="0 0 0"/>
      <geometry>
        <mesh filename="file://$(find mini_pupper_2_description)/meshes/rpb2.stl" scale="1 1 1"/>
      </geometry>
    </collision>
  </link>

  <link name="Shell_Side">
    <inertial>
      <origin xyz="-2.7696824994153518e-05 0.029999714418054345 0.022370567779566777" rpy="0 0 0"/>
      <mass value="0.0051928835390001775"/>
      <inertia ixx="6e-06" iyy="3e-06" izz="7e-06" ixy="0.0" iyz="0.0" ixz="0.0"/>
    </inertial>
    <visual>
      <origin xyz="0.002701 0.029755 0.016293" rpy="0 0 0"/>
      <geometry>
        <mesh filename="file://$(find mini_pupper_2_description)/meshes/Shell_Side.stl" scale="1 1 1"/>
      </geometry>
      <material name="opaque2552210"/>
    </visual>
    <collision>
      <origin xyz="0.002701 0.029755 0.016293" rpy="0 0 0"/>
      <geometry>
        <mesh filename="file://$(find mini_pupper_2_description)/meshes/Shell_Side.stl" scale="1 1 1"/>
      </geometry>
    </collision>
  </link>
  
  <joint name="base_link_to_base_inertia" type="fixed">
    <parent link="base_link"/>
    <child link="base_inertia"/>
    <origin rpy="0 0 0" xyz="0 0 0"/>
  </joint>

  <joint name="base_lf1" type="revolute">
    <origin xyz="0.037299 0.023745 5.7e-05" rpy="0 0 0"/>
    <parent link="base_link"/>
    <child link="lf1"/>
    <axis xyz="1.0 0.0 0.0"/>
    <limit upper="3.141593" lower="-3.141593" effort="5" velocity="1.5"/>
  </joint>

  <joint name="lf1_lf2" type="revolute">
    <origin xyz="0.014866 0.0177 0.0" rpy="0 0 0"/>
    <parent link="lf1"/>
    <child link="lf2"/>
    <axis xyz="0.0 1.0 0.0"/>
    <limit upper="3.141593" lower="-3.141593" effort="5" velocity="1.5"/>
  </joint>

  <joint name="lf2_lf3" type="revolute">
    <origin xyz="-0.008689 0.003 -0.04924" rpy="0 0 0"/>
    <parent link="lf2"/>
    <child link="lf3"/>
    <axis xyz="0.0 1.0 0.0"/>
    <limit upper="3.141593" lower="-3.141593" effort="5" velocity="1.5"/>
  </joint>

  <joint name="base_rf1" type="revolute">
    <origin xyz="0.037299 -0.023255 5.7e-05" rpy="0 0 0"/>
    <parent link="base_link"/>
    <child link="rf1"/>
    <axis xyz="1.0 0.0 0.0"/>
    <limit upper="3.141593" lower="-3.141593" effort="5" velocity="1.5"/>
  </joint>

  <joint name="rf1_rf2" type="revolute">
    <origin xyz="0.014866 -0.0177 0.0" rpy="0 0 0"/>
    <parent link="rf1"/>
    <child link="rf2"/>
    <axis xyz="0.0 1.0 0.0"/>
    <limit upper="3.141593" lower="-3.141593" effort="5" velocity="1.5"/>
  </joint>

  <joint name="rf2_rf3" type="revolute">
    <origin xyz="-0.008683 -0.003 -0.049241" rpy="0 0 0"/>
    <parent link="rf2"/>
    <child link="rf3"/>
    <axis xyz="0.0 1.0 0.0"/>
    <limit upper="3.141593" lower="-3.141593" effort="5" velocity="1.5"/>
  </joint>

  <joint name="base_rb1" type="revolute">
    <origin xyz="-0.042701 -0.023255 5.7e-05" rpy="0 0 0"/>
    <parent link="base_link"/>
    <child link="rb1"/>
    <axis xyz="1.0 0.0 0.0"/>
    <limit upper="3.141593" lower="-3.141593" effort="5" velocity="1.5"/>
  </joint>

  <joint name="rb1_rb2" type="revolute">
    <origin xyz="-0.025666 -0.0177 9e-06" rpy="0 0 0"/>
    <parent link="rb1"/>
    <child link="rb2"/>
    <axis xyz="0.0 1.0 0.0"/>
    <limit upper="3.141593" lower="-3.141593" effort="5" velocity="1.5"/>
  </joint>

  <joint name="rb2_rb3" type="revolute">
    <origin xyz="-0.008682 -0.003027 -0.049239" rpy="0 0 0"/>
    <parent link="rb2"/>
    <child link="rb3"/>
    <axis xyz="0.0 1.0 0.0"/>
    <limit upper="3.141593" lower="-3.141593" effort="5" velocity="1.5"/>
  </joint>

  <joint name="base_lb1" type="revolute">
    <origin xyz="-0.042701 0.023745 5.7e-05" rpy="0 0 0"/>
    <parent link="base_link"/>
    <child link="lb1"/>
    <axis xyz="1.0 0.0 0.0"/>
    <limit upper="3.141593" lower="-3.141593" effort="5" velocity="1.5"/>
  </joint>

  <joint name="lb1_lb2" type="revolute">
    <origin xyz="-0.025666 0.0177 0.0" rpy="0 0 0"/>
    <parent link="lb1"/>
    <child link="lb2"/>
    <axis xyz="0.0 1.0 0.0"/>
    <limit upper="3.141593" lower="-3.141593" effort="5" velocity="1.5"/>
  </joint>

  <joint name="lb2_lb3" type="revolute">
    <origin xyz="-0.008682 0.003 -0.049241" rpy="0 0 0"/>
    <parent link="lb2"/>
    <child link="lb3"/>
    <axis xyz="0.0 1.0 0.0"/>
    <limit upper="3.141593" lower="-3.141593" effort="5" velocity="1.5"/>
  </joint>

  <joint name="base_front" type="fixed">
    <origin xyz="0.089299 0.000245 -0.015543" rpy="0 0 0"/>
    <parent link="base_link"/>
    <child link="Body_front"/>
  </joint>

  <joint name="base_board" type="fixed">
    <origin xyz="-0.087701 -0.023255 0.026457" rpy="0 0 0"/>
    <parent link="base_link"/>
    <child link="Board_PCB"/>
  </joint>

  <joint name="base_cn1" type="fixed">
    <origin xyz="0.149035 0.023472 0.0" rpy="0 0 0"/>
    <parent link="Board_PCB"/>
    <child link="Board_connectors_1"/>
  </joint>

  <joint name="base_cn2" type="fixed">
    <origin xyz="0.042355 0.0235 0.0" rpy="0 0 0"/>
    <parent link="Board_PCB"/>
    <child link="Board_connectors_2"/>
  </joint>

  <joint name="rf3_foot" type="fixed">
    <origin xyz="0.024626 -0.00375 -0.05443" rpy="0 0 0"/>
    <parent link="rf3"/>
    <child link="rffoot"/>
  </joint>

  <joint name="rb3_foot" type="fixed">
    <origin xyz="0.024625 -0.00378 -0.054428" rpy="0 0 0"/>
    <parent link="rb3"/>
    <child link="rbfoot"/>
  </joint>

  <joint name="lb3_foot" type="fixed">
    <origin xyz="0.024625 0.00375 -0.05443" rpy="0 0 0"/>
    <parent link="lb3"/>
    <child link="lbfoot"/>
  </joint>

  <joint name="lf3_foot" type="fixed">
    <origin xyz="0.024632 0.00375 -0.054428" rpy="0 0 0"/>
    <parent link="lf3"/>
    <child link="lffoot"/>
  </joint>

  <joint name="lf1_hip" type="fixed">
    <origin xyz="0.034266 0.0145 0.013" rpy="0 0 0"/>
    <parent link="lf1"/>
    <child link="lpf1"/>
  </joint>

  <joint name="lb1_hip" type="fixed">
    <origin xyz="-0.006266 0.0145 0.013" rpy="0 0 0"/>
    <parent link="lb1"/>
    <child link="lpb1"/>
  </joint>

  <joint name="rf1_hip" type="fixed">
    <origin xyz="0.034266 -0.0145 0.013" rpy="0 0 0"/>
    <parent link="rf1"/>
    <child link="rpf1"/>
  </joint>

  <joint name="rb2_hip" type="fixed">
    <origin xyz="-0.006266 -0.014493 0.013007" rpy="0 0 0"/>
    <parent link="rb1"/>
    <child link="rpb1"/>
  </joint>

  <joint name="lf2_shell" type="fixed">
    <origin xyz="-0.003302 0.003 -0.018711" rpy="0 0 0"/>
    <parent link="lf2"/>
    <child link="lpf2"/>
  </joint>

  <joint name="lb2_shell" type="fixed">
    <origin xyz="-0.003299 0.003 -0.018712" rpy="0 0 0"/>
    <parent link="lb2"/>
    <child link="lpb2"/>
  </joint>

  <joint name="rf2_shell" type="fixed">
    <origin xyz="-0.0033 -0.003 -0.018712" rpy="0 0 0"/>
    <parent link="rf2"/>
    <child link="rpf2"/>
  </joint>

  <joint name="rb2_shell" type="fixed">
    <origin xyz="-0.003299 -0.00301 -0.01871" rpy="0 0 0"/>
    <parent link="rb2"/>
    <child link="rpb2"/>
  </joint>

  <joint name="base_sides" type="fixed">
    <origin xyz="-0.002701 -0.029755 -0.016293" rpy="0 0 0"/>
    <parent link="base_link"/>
    <child link="Shell_Side"/>
  </joint>
  <ros2_control name="GazeboSystem" type="system">
    <hardware>
      <plugin>gazebo_ros2_control/GazeboSystem</plugin>
    </hardware>
    <joint name="base_lf1">
      <command_interface name="effort"/> 
      <state_interface name="position"/>
      <state_interface name="velocity"/>
    </joint>
    <joint name="lf1_lf2">
      <command_interface name="effort"/> 
      <state_interface name="position"/>
      <state_interface name="velocity"/>
    </joint>
    <joint name="lf2_lf3">
      <command_interface name="effort"/> 
      <state_interface name="position"/>
      <state_interface name="velocity"/>
    </joint>
    <joint name="base_rf1">
      <command_interface name="effort"/> 
      <state_interface name="position"/>
      <state_interface name="velocity"/>
    </joint>
    <joint name="rf1_rf2">
      <command_interface name="effort"/> 
      <state_interface name="position"/>
      <state_interface name="velocity"/>
    </joint>
    <joint name="rf2_rf3">
      <command_interface name="effort"/> 
      <state_interface name="position"/>
      <state_interface name="velocity"/>
    </joint>
    <joint name="base_lb1">
      <command_interface name="effort"/> 
      <state_interface name="position"/>
      <state_interface name="velocity"/>
    </joint>
    <joint name="lb1_lb2">
      <command_interface name="effort"/> 
      <state_interface name="position"/>
      <state_interface name="velocity"/>
    </joint>
    <joint name="lb2_lb3">
      <command_interface name="effort"/> 
      <state_interface name="position"/>
      <state_interface name="velocity"/>
    </joint>
    <joint name="base_rb1">
      <command_interface name="effort"/> 
      <state_interface name="position"/>
      <state_interface name="velocity"/>
    </joint>
    <joint name="rb1_rb2">
      <command_interface name="effort"/> 
      <state_interface name="position"/>
      <state_interface name="velocity"/>
    </joint>
    <joint name="rb2_rb3">
      <command_interface name="effort"/> 
      <state_interface name="position"/>
      <state_interface name="velocity"/>
    </joint>
  </ros2_control>
  <!-- coloring Gazebo model -->
  <gazebo reference="base_link">
    <material>Gazebo/FlatBlack</material>
  </gazebo>
  <gazebo reference="Shell_Side">
    <material>Gazebo/Yellow</material>
  </gazebo>
  
  <gazebo reference="lf1">
    <kp>1000000.0</kp>
    <kd>1.0</kd>
    <mu1>0.8</mu1>
    <mu2>0.8</mu2>
    <maxVel>0.0</maxVel>
    <minDepth>0.001</minDepth>
    <material>Gazebo/FlatBlack</material>
  </gazebo>
  <gazebo reference="lpf1">
    <material>Gazebo/Yellow</material>
  </gazebo>
  <gazebo reference="lf2">
    <kp>1000000.0</kp>
    <kd>1.0</kd>
    <mu1>0.8</mu1>
    <mu2>0.8</mu2>
    <maxVel>0.0</maxVel>
    <minDepth>0.001</minDepth>
    <material>Gazebo/FlatBlack</material>
  </gazebo>
  <gazebo reference="lpf2">
    <material>Gazebo/Yellow</material>
  </gazebo>
  <gazebo reference="lf3">
    <kp>1000000.0</kp>
    <kd>1.0</kd>
    <mu1>0.8</mu1>
    <mu2>0.8</mu2>
    <maxVel>0.0</maxVel>
    <minDepth>0.001</minDepth>
    <material>Gazebo/FlatBlack</material>
  </gazebo>
  <gazebo reference="lffoot">
    <kp>1000000.0</kp>
    <kd>1.0</kd>
    <mu1>0.8</mu1>
    <mu2>0.8</mu2>
    <maxVel>0.0</maxVel>
    <minDepth>0.001</minDepth>
    <material>Gazebo/FlatBlack</material>
  </gazebo>
  <gazebo reference="rf1">
    <kp>1000000.0</kp>
    <kd>1.0</kd>
    <mu1>0.8</mu1>
    <mu2>0.8</mu2>
    <maxVel>0.0</maxVel>
    <minDepth>0.001</minDepth>
    <material>Gazebo/FlatBlack</material>
  </gazebo>
  <gazebo reference="rpf1">
    <material>Gazebo/Yellow</material>
  </gazebo>
  <gazebo reference="rf2">
    <kp>1000000.0</kp>
    <kd>1.0</kd>
    <mu1>0.8</mu1>
    <mu2>0.8</mu2>
    <maxVel>0.0</maxVel>
    <minDepth>0.001</minDepth>
    <material>Gazebo/FlatBlack</material>
  </gazebo>
  <gazebo reference="rpf2">
    <material>Gazebo/Yellow</material>
  </gazebo>
  <gazebo reference="rf3">
    <kp>1000000.0</kp>
    <kd>1.0</kd>
    <mu1>0.8</mu1>
    <mu2>0.8</mu2>
    <maxVel>0.0</maxVel>
    <minDepth>0.001</minDepth>
    <material>Gazebo/FlatBlack</material>
  </gazebo>
  <gazebo reference="rffoot">
    <kp>1000000.0</kp>
    <kd>1.0</kd>
    <mu1>0.8</mu1>
    <mu2>0.8</mu2>
    <maxVel>0.0</maxVel>
    <minDepth>0.001</minDepth>
    <material>Gazebo/FlatBlack</material>
  </gazebo>
  <gazebo reference="lb1">
    <kp>1000000.0</kp>
    <kd>1.0</kd>
    <mu1>0.8</mu1>
    <mu2>0.8</mu2>
    <maxVel>0.0</maxVel>
    <minDepth>0.001</minDepth>
    <material>Gazebo/FlatBlack</material>
  </gazebo>
  <gazebo reference="lpb1">
    <material>Gazebo/Yellow</material>
  </gazebo>
  <gazebo reference="lb2">
    <kp>1000000.0</kp>
    <kd>1.0</kd>
    <mu1>0.8</mu1>
    <mu2>0.8</mu2>
    <maxVel>0.0</maxVel>
    <minDepth>0.001</minDepth>
    <material>Gazebo/FlatBlack</material>
  </gazebo>
  <gazebo reference="lpb2">
    <material>Gazebo/Yellow</material>
  </gazebo>
  <gazebo reference="lb3">
    <kp>1000000.0</kp>
    <kd>1.0</kd>
    <mu1>0.8</mu1>
    <mu2>0.8</mu2>
    <maxVel>0.0</maxVel>
    <minDepth>0.001</minDepth>
    <material>Gazebo/FlatBlack</material>
  </gazebo>
  <gazebo reference="lbfoot">
    <kp>1000000.0</kp>
    <kd>1.0</kd>
    <mu1>0.8</mu1>
    <mu2>0.8</mu2>
    <maxVel>0.0</maxVel>
    <minDepth>0.001</minDepth>
    <material>Gazebo/FlatBlack</material>
  </gazebo>
  <gazebo reference="rb1">
    <kp>1000000.0</kp>
    <kd>1.0</kd>
    <mu1>0.8</mu1>
    <mu2>0.8</mu2>
    <maxVel>0.0</maxVel>
    <minDepth>0.001</minDepth>
    <material>Gazebo/FlatBlack</material>
  </gazebo>
  <gazebo reference="rpb1">
    <material>Gazebo/Yellow</material>
  </gazebo>
  <gazebo reference="rb2">
    <kp>1000000.0</kp>
    <kd>1.0</kd>
    <mu1>0.8</mu1>
    <mu2>0.8</mu2>
    <maxVel>0.0</maxVel>
    <minDepth>0.001</minDepth>
    <material>Gazebo/FlatBlack</material>
  </gazebo>
  <gazebo reference="rpb2">
    <material>Gazebo/Yellow</material>
  </gazebo>
  <gazebo reference="rb3">
    <kp>1000000.0</kp>
    <kd>1.0</kd>
    <mu1>0.8</mu1>
    <mu2>0.8</mu2>
    <maxVel>0.0</maxVel>
    <minDepth>0.001</minDepth>
    <material>Gazebo/FlatBlack</material>
  </gazebo>
  <gazebo reference="rbfoot">
    <kp>1000000.0</kp>
    <kd>1.0</kd>
    <mu1>0.8</mu1>
    <mu2>0.8</mu2>
    <maxVel>0.0</maxVel>
    <minDepth>0.001</minDepth>
    <material>Gazebo/FlatBlack</material>
  </gazebo>

  <!-- <gazebo reference="lidar_link">
    <material>Gazebo/FlatBlack</material>
    <sensor type="ray" name="lidar">
      <always_on>true</always_on>
      <update_rate>30</update_rate>
      <pose>0 0 0 0 0 0</pose>
      <visualize>false</visualize>
      <ray>
        <scan>
          <horizontal>
            <samples>1040</samples>
            <resolution>1</resolution>
            <min_angle>0</min_angle>
            <max_angle>6.28</max_angle>
          </horizontal>
        </scan>
        <range>
          <min>0.2</min>
          <max>50.0</max>
          <resolution>0.01</resolution>
        </range>
        <noise>
          <type>gaussian</type>
          <mean>0.0</mean>
          <stddev>0.004</stddev>
        </noise>
      </ray>
      <plugin name="gazebo_ros_lidar_controller" filename="libgazebo_ros_ray_sensor.so">
        <ros>
          <remapping>~/out:=/scan</remapping>
        </ros>
        <output_type>sensor_msgs/LaserScan</output_type>
        <frame_name>lidar_link</frame_name> -->
        <!--min_intensity>100.0</min_intensity-->
      <!-- </plugin>
    </sensor>
  </gazebo> -->

  <gazebo>
    <plugin filename="libgazebo_ros_p3d.so" name="p3d_base_controller">
      <ros>
        <remapping>odom:=odom/ground_truth</remapping>
      </ros>
      <body_name>base_link</body_name>
      <frame_name>world</frame_name>
      <update_rate>10.0</update_rate>
      <xyz_offset>0 0 0</xyz_offset>
      <rpy_offset>0 0 0</rpy_offset>
      <gaussian_noise>0.01</gaussian_noise>
    </plugin>
  </gazebo>

  <gazebo>
    <plugin filename="libgazebo_ros2_control.so" name="gazebo_ros2_control">
      <parameters>$(find mini_pupper_2_description)/config/ros_control/mini_pupper_controller.yaml</parameters>
    </plugin>
  </gazebo>
  
  <link name="imu_link">
    <inertial>
      <mass value="0.0001"/>
      <origin rpy="0 0 0" xyz="0 0 0"/>
      <inertia ixx="1e-09" ixy="0.0" ixz="0.0" iyy="1e-09" iyz="0.0" izz="1e-09"/>
    </inertial>
  </link>

  <joint name="imu_joint" type="fixed">
    <parent link="base_link"/>
    <child link="imu_link"/>
  </joint>

  <gazebo reference="imu_link">
    <sensor name="imu_controller" type="imu">
      <always_on>true</always_on>
      <update_rate>50</update_rate>
      <plugin name="gazebo_ros_imu_sensor" filename="libgazebo_ros_imu_sensor.so">
          <ros>
              <namespace>/imu</namespace>
              <remapping>~/out:=data</remapping>
          </ros>
      </plugin>
    </sensor>
  </gazebo>

</robot>