<?xml version="1.0" ?>
<!-- =================================================================================== -->
<!-- |    This document was autogenerated by xacro from mini_pupper_2_description.urdf.xacro | -->
<!-- |    EDITING THIS FILE BY HAND IS NOT RECOMMENDED                                 | -->
<!-- =================================================================================== -->
<robot name="mini_pupper">
  <material name="silver_default">
    <color rgba="0.700 0.700 0.700 1.000"/>
  </material>
  <material name="opaque666666">
    <color rgba="0.25882352941176473 0.25882352941176473 0.25882352941176473 1.0"/>
  </material>
  <material name="opaque252525">
    <color rgba="0.09803921568627451 0.09803921568627451 0.09803921568627451 1.0"/>
  </material>
  <material name="opaque636363">
    <color rgba="0.25098039215686274 0.25098039215686274 0.25098039215686274 1.0"/>
  </material>
  <material name="opaque2552210">
    <color rgba="1.0 0.8666666666666667 0.0 1.0"/>
  </material>
  <material name="opaque646464">
    <color rgba="0.25098039215686274 0.25098039215686274 0.25098039215686274 1.0"/>
  </material>
  <material name="opaque25524395">
    <color rgba="1.0 0.9529411764705882 0.37254901960784315 1.0"/>
  </material>
  <material name="opaque2491590">
    <color rgba="0.9764705882352941 0.6235294117647059 0.0 1.0"/>
  </material>
  <material name="opaque255255255">
    <color rgba="1.0 1.0 1.0 1.0"/>
  </material>
  <!-- <xacro:include filename="$(find mini_pupper_2_description)/urdf/mini_pupper_2_description.trans" /> -->
  <link name="base_link">
    <visual>
      <origin rpy="0 0 0" xyz="0 0 0"/>
      <geometry>
        <mesh filename="package://mini_pupper_2_description/meshes/base_link.stl" scale="1 1 1"/>
      </geometry>
      <material name="opaque252525"/>
    </visual>
    <collision>
      <origin rpy="0 0 0" xyz="0 0 0"/>
      <geometry>
        <mesh filename="package://mini_pupper_2_description/meshes/base_link.stl" scale="1 1 1"/>
      </geometry>
    </collision>
  </link>
  <link name="base_inertia">
    <inertial>
      <origin rpy="0 0 0" xyz="-0.008866664732250966 0.0006462612742260995 -0.007154314406453802"/>
      <mass value="0.09818420433466489"/>
      <inertia ixx="5.2e-05" ixy="1e-06" ixz="-1e-05" iyy="0.000244" iyz="1e-06" izz="0.000252"/>
    </inertial>
  </link>
  <link name="lf1">
    <inertial>
      <origin rpy="0 0 0" xyz="0.020109281613098752 0.002331771723067172 0.0064994497731911665"/>
      <mass value="0.020769030109708524"/>
      <inertia ixx="2e-06" ixy="-0.0" ixz="-0.0" iyy="4e-06" iyz="-0.0" izz="3e-06"/>
    </inertial>
    <visual>
      <origin rpy="0 0 0" xyz="-0.037299 -0.023745 -5.7e-05"/>
      <geometry>
        <mesh filename="package://mini_pupper_2_description/meshes/lf1.stl" scale="1 1 1"/>
      </geometry>
      <material name="opaque666666"/>
    </visual>
    <collision>
      <origin rpy="0 0 0" xyz="-0.037299 -0.023745 -5.7e-05"/>
      <geometry>
        <mesh filename="package://mini_pupper_2_description/meshes/lf1.stl" scale="1 1 1"/>
      </geometry>
    </collision>
  </link>
  <link name="lf2">
    <inertial>
      <origin rpy="0 0 0" xyz="-2.5728896106275156e-06 0.0009860558893138652 -0.018261345499916863"/>
      <mass value="0.0019057729925096327"/>
      <inertia ixx="0.0" ixy="0.0" ixz="-0.0" iyy="0.0" iyz="0.0" izz="0.0"/>
    </inertial>
    <visual>
      <origin rpy="0 0 0" xyz="-0.052165 -0.041445 -5.7e-05"/>
      <geometry>
        <mesh filename="package://mini_pupper_2_description/meshes/lf2.stl" scale="1 1 1"/>
      </geometry>
      <material name="opaque636363"/>
    </visual>
    <collision>
      <origin rpy="0 0 0" xyz="-0.052165 -0.041445 -5.7e-05"/>
      <geometry>
        <mesh filename="package://mini_pupper_2_description/meshes/lf2.stl" scale="1 1 1"/>
      </geometry>
    </collision>
  </link>
  <link name="lf3">
    <inertial>
      <origin rpy="0 0 0" xyz="0.0007046107744873437 0.0034550275861905885 -0.016225601428628958"/>
      <mass value="0.0011438144457690698"/>
      <inertia ixx="1e-06" ixy="-0.0" ixz="0.0" iyy="1e-06" iyz="0.0" izz="0.0"/>
    </inertial>
    <visual>
      <origin rpy="0 0 0" xyz="-0.052159 -0.044445 0.049943"/>
      <geometry>
        <mesh filename="package://mini_pupper_2_description/meshes/lf3.stl" scale="1 1 1"/>
      </geometry>
      <material name="opaque252525"/>
    </visual>
    <collision>
      <origin rpy="0 0 0" xyz="-0.052159 -0.044445 0.049943"/>
      <geometry>
        <mesh filename="package://mini_pupper_2_description/meshes/lf3.stl" scale="1 1 1"/>
      </geometry>
    </collision>
  </link>
  <link name="rf1">
    <inertial>
      <origin rpy="0 0 0" xyz="0.020106742599110078 -0.00233237781568562 0.006497900858401761"/>
      <mass value="0.020769549324466178"/>
      <inertia ixx="2e-06" ixy="0.0" ixz="-0.0" iyy="4e-06" iyz="-0.0" izz="3e-06"/>
    </inertial>
    <visual>
      <origin rpy="0 0 0" xyz="-0.037299 0.023255 -5.7e-05"/>
      <geometry>
        <mesh filename="package://mini_pupper_2_description/meshes/rf1.stl" scale="1 1 1"/>
      </geometry>
      <material name="opaque666666"/>
    </visual>
    <collision>
      <origin rpy="0 0 0" xyz="-0.037299 0.023255 -5.7e-05"/>
      <geometry>
        <mesh filename="package://mini_pupper_2_description/meshes/rf1.stl" scale="1 1 1"/>
      </geometry>
    </collision>
  </link>
  <link name="rf2">
    <inertial>
      <origin rpy="0 0 0" xyz="-4.1025190424676117e-07 -0.0009866275794596438 -0.018261345629717353"/>
      <mass value="0.0019057729924780605"/>
      <inertia ixx="0.0" ixy="-0.0" ixz="-0.0" iyy="0.0" iyz="-0.0" izz="0.0"/>
    </inertial>
    <visual>
      <origin rpy="0 0 0" xyz="-0.052165 0.040955 -5.7e-05"/>
      <geometry>
        <mesh filename="package://mini_pupper_2_description/meshes/rf2.stl" scale="1 1 1"/>
      </geometry>
      <material name="opaque636363"/>
    </visual>
    <collision>
      <origin rpy="0 0 0" xyz="-0.052165 0.040955 -5.7e-05"/>
      <geometry>
        <mesh filename="package://mini_pupper_2_description/meshes/rf2.stl" scale="1 1 1"/>
      </geometry>
    </collision>
  </link>
  <link name="rf3">
    <inertial>
      <origin rpy="0 0 0" xyz="0.0007030898236521158 -0.003457422744677939 -0.016230262912113935"/>
      <mass value="0.001143490701517533"/>
      <inertia ixx="1e-06" ixy="0.0" ixz="0.0" iyy="1e-06" iyz="-0.0" izz="0.0"/>
    </inertial>
    <visual>
      <origin rpy="0 0 0" xyz="-0.052165 0.043955 0.049943"/>
      <geometry>
        <mesh filename="package://mini_pupper_2_description/meshes/rf3.stl" scale="1 1 1"/>
      </geometry>
      <material name="opaque252525"/>
    </visual>
    <collision>
      <origin rpy="0 0 0" xyz="-0.052165 0.043955 0.049943"/>
      <geometry>
        <mesh filename="package://mini_pupper_2_description/meshes/rf3.stl" scale="1 1 1"/>
      </geometry>
    </collision>
  </link>
  <link name="rb1">
    <inertial>
      <origin rpy="0 0 0" xyz="-0.020107177922528044 -0.0023288309787250286 0.006502376356642127"/>
      <mass value="0.020769549324363486"/>
      <inertia ixx="2e-06" ixy="-0.0" ixz="-0.0" iyy="4e-06" iyz="-0.0" izz="3e-06"/>
    </inertial>
    <visual>
      <origin rpy="0 0 0" xyz="0.042701 0.023255 -5.7e-05"/>
      <geometry>
        <mesh filename="package://mini_pupper_2_description/meshes/rb1.stl" scale="1 1 1"/>
      </geometry>
      <material name="opaque666666"/>
    </visual>
    <collision>
      <origin rpy="0 0 0" xyz="0.042701 0.023255 -5.7e-05"/>
      <geometry>
        <mesh filename="package://mini_pupper_2_description/meshes/rb1.stl" scale="1 1 1"/>
      </geometry>
    </collision>
  </link>
  <link name="rb2">
    <inertial>
      <origin rpy="0 0 0" xyz="-2.5070667000748337e-08 -0.000996585764066693 -0.018260149861185754"/>
      <mass value="0.0019057729926311429"/>
      <inertia ixx="0.0" ixy="-0.0" ixz="-0.0" iyy="0.0" iyz="-0.0" izz="0.0"/>
    </inertial>
    <visual>
      <origin rpy="0 0 0" xyz="0.068367 0.040955 -6.6e-05"/>
      <geometry>
        <mesh filename="package://mini_pupper_2_description/meshes/rb2.stl" scale="1 1 1"/>
      </geometry>
      <material name="opaque636363"/>
    </visual>
    <collision>
      <origin rpy="0 0 0" xyz="0.068367 0.040955 -6.6e-05"/>
      <geometry>
        <mesh filename="package://mini_pupper_2_description/meshes/rb2.stl" scale="1 1 1"/>
      </geometry>
    </collision>
  </link>
  <link name="rb3">
    <inertial>
      <origin rpy="0 0 0" xyz="0.0007031309185970697 -0.0034624258831375196 -0.016220094399306113"/>
      <mass value="0.0011440535724654094"/>
      <inertia ixx="1e-06" ixy="0.0" ixz="0.0" iyy="1e-06" iyz="-0.0" izz="0.0"/>
    </inertial>
    <visual>
      <origin rpy="0 0 0" xyz="0.068367 0.043983 0.049932"/>
      <geometry>
        <mesh filename="package://mini_pupper_2_description/meshes/rb3.stl" scale="1 1 1"/>
      </geometry>
      <material name="opaque252525"/>
    </visual>
    <collision>
      <origin rpy="0 0 0" xyz="0.068367 0.043983 0.049932"/>
      <geometry>
        <mesh filename="package://mini_pupper_2_description/meshes/rb3.stl" scale="1 1 1"/>
      </geometry>
    </collision>
  </link>
  <link name="lb1">
    <inertial>
      <origin rpy="0 0 0" xyz="-0.020109716415830967 0.0023317718989125207 0.006499556305653081"/>
      <mass value="0.020769030189864354"/>
      <inertia ixx="2e-06" ixy="0.0" ixz="-0.0" iyy="4e-06" iyz="0.0" izz="3e-06"/>
    </inertial>
    <visual>
      <origin rpy="0 0 0" xyz="0.042701 -0.023745 -5.7e-05"/>
      <geometry>
        <mesh filename="package://mini_pupper_2_description/meshes/lb1.stl" scale="1 1 1"/>
      </geometry>
      <material name="opaque666666"/>
    </visual>
    <collision>
      <origin rpy="0 0 0" xyz="0.042701 -0.023745 -5.7e-05"/>
      <geometry>
        <mesh filename="package://mini_pupper_2_description/meshes/lb1.stl" scale="1 1 1"/>
      </geometry>
    </collision>
  </link>
  <link name="lb2">
    <inertial>
      <origin rpy="0 0 0" xyz="-2.486178994620669e-08 0.0009860564153100007 -0.01826134562993383"/>
      <mass value="0.0019057729925095609"/>
      <inertia ixx="0.0" ixy="0.0" ixz="-0.0" iyy="0.0" iyz="0.0" izz="0.0"/>
    </inertial>
    <visual>
      <origin rpy="0 0 0" xyz="0.068367 -0.041445 -5.7e-05"/>
      <geometry>
        <mesh filename="package://mini_pupper_2_description/meshes/lb2.stl" scale="1 1 1"/>
      </geometry>
      <material name="opaque636363"/>
    </visual>
    <collision>
      <origin rpy="0 0 0" xyz="0.068367 -0.041445 -5.7e-05"/>
      <geometry>
        <mesh filename="package://mini_pupper_2_description/meshes/lb2.stl" scale="1 1 1"/>
      </geometry>
    </collision>
  </link>
  <link name="lb3">
    <inertial>
      <origin rpy="0 0 0" xyz="0.0007030123702261443 0.0034519487133846394 -0.016218113385159758"/>
      <mass value="0.001144346207072784"/>
      <inertia ixx="1e-06" ixy="-0.0" ixz="0.0" iyy="1e-06" iyz="0.0" izz="0.0"/>
    </inertial>
    <visual>
      <origin rpy="0 0 0" xyz="0.068367 -0.044445 0.049943"/>
      <geometry>
        <mesh filename="package://mini_pupper_2_description/meshes/lb3.stl" scale="1 1 1"/>
      </geometry>
      <material name="opaque252525"/>
    </visual>
    <collision>
      <origin rpy="0 0 0" xyz="0.068367 -0.044445 0.049943"/>
      <geometry>
        <mesh filename="package://mini_pupper_2_description/meshes/lb3.stl" scale="1 1 1"/>
      </geometry>
    </collision>
  </link>
  <link name="Body_front">
    <inertial>
      <origin rpy="0 0 0" xyz="-0.005538678480206852 -0.00020424196520824284 0.020222593513387798"/>
      <mass value="0.00785515871148119"/>
      <inertia ixx="5e-06" ixy="-0.0" ixz="-0.0" iyy="2e-06" iyz="-0.0" izz="4e-06"/>
    </inertial>
    <visual>
      <origin rpy="0 0 0" xyz="-0.089299 -0.000245 0.015543"/>
      <geometry>
        <mesh filename="package://mini_pupper_2_description/meshes/Body_front.stl" scale="1 1 1"/>
      </geometry>
      <material name="opaque2552210"/>
    </visual>
    <collision>
      <origin rpy="0 0 0" xyz="-0.089299 -0.000245 0.015543"/>
      <geometry>
        <mesh filename="package://mini_pupper_2_description/meshes/Body_front.stl" scale="1 1 1"/>
      </geometry>
    </collision>
  </link>
  <link name="Board_PCB">
    <inertial>
      <origin rpy="0 0 0" xyz="0.08946128454598752 0.025716073555853 -3.6415040620890043e-05"/>
      <mass value="0.014261552601793053"/>
      <inertia ixx="4e-06" ixy="0.0" ixz="0.0" iyy="3.5e-05" iyz="0.0" izz="3.9e-05"/>
    </inertial>
    <visual>
      <origin rpy="0 0 0" xyz="0.087701 0.023255 -0.026457"/>
      <geometry>
        <mesh filename="package://mini_pupper_2_description/meshes/Board_PCB.stl" scale="1 1 1"/>
      </geometry>
      <material name="opaque646464"/>
    </visual>
    <collision>
      <origin rpy="0 0 0" xyz="0.087701 0.023255 -0.026457"/>
      <geometry>
        <mesh filename="package://mini_pupper_2_description/meshes/Board_PCB.stl" scale="1 1 1"/>
      </geometry>
    </collision>
  </link>
  <link name="Board_connectors_1">
    <inertial>
      <origin rpy="0 0 0" xyz="-0.07276303117117414 -0.002323344081837563 -0.0010631239213060653"/>
      <mass value="0.004688613655947816"/>
      <inertia ixx="0.0" ixy="-1e-06" ixz="0.0" iyy="1.5e-05" iyz="0.0" izz="1.6e-05"/>
    </inertial>
    <visual>
      <origin rpy="0 0 0" xyz="-0.061334 -0.000217 -0.026457"/>
      <geometry>
        <mesh filename="package://mini_pupper_2_description/meshes/Board_connectors_1.stl" scale="1 1 1"/>
      </geometry>
      <material name="opaque2491590"/>
    </visual>
    <collision>
      <origin rpy="0 0 0" xyz="-0.061334 -0.000217 -0.026457"/>
      <geometry>
        <mesh filename="package://mini_pupper_2_description/meshes/Board_connectors_1.stl" scale="1 1 1"/>
      </geometry>
    </collision>
  </link>
  <link name="Board_connectors_2">
    <inertial>
      <origin rpy="0 0 0" xyz="0.008233541174180986 -0.002138369786547657 -0.00030110978110910874"/>
      <mass value="0.0019746031301169403"/>
      <inertia ixx="0.0" ixy="-0.0" ixz="0.0" iyy="3e-06" iyz="0.0" izz="4e-06"/>
    </inertial>
    <visual>
      <origin rpy="0 0 0" xyz="0.045346 -0.000245 -0.026457"/>
      <geometry>
        <mesh filename="package://mini_pupper_2_description/meshes/Board_connectors_2.stl" scale="1 1 1"/>
      </geometry>
      <material name="opaque255255255"/>
    </visual>
    <collision>
      <origin rpy="0 0 0" xyz="0.045346 -0.000245 -0.026457"/>
      <geometry>
        <mesh filename="package://mini_pupper_2_description/meshes/Board_connectors_2.stl" scale="1 1 1"/>
      </geometry>
    </collision>
  </link>
  <link name="rffoot">
    <inertial>
      <origin rpy="0 0 0" xyz="-0.0024634044240561814 -2.8557999392359035e-07 0.007801816226636768"/>
      <mass value="0.0014053107976262874"/>
      <inertia ixx="0.0" ixy="0.0" ixz="-0.0" iyy="0.0" iyz="-0.0" izz="0.0"/>
    </inertial>
    <visual>
      <origin rpy="0 0 0" xyz="-0.056689 0.047705 0.109514"/>
      <geometry>
        <mesh filename="package://mini_pupper_2_description/meshes/rffoot.stl" scale="1 1 1"/>
      </geometry>
      <material name="opaque666666"/>
    </visual>
    <collision>
      <origin rpy="0 0 0" xyz="-0.056689 0.047705 0.109514"/>
      <geometry>
        <mesh filename="package://mini_pupper_2_description/meshes/rffoot.stl" scale="1 1 1"/>
      </geometry>
    </collision>
  </link>
  <link name="rbfoot">
    <inertial>
      <origin rpy="0 0 0" xyz="-0.0024630192318816357 4.2051173794327434e-06 0.0078011683948505245"/>
      <mass value="0.0014053107976262874"/>
      <inertia ixx="0.0" ixy="-0.0" ixz="-0.0" iyy="0.0" iyz="-0.0" izz="0.0"/>
    </inertial>
    <visual>
      <origin rpy="0 0 0" xyz="0.063843 0.047765 0.1095"/>
      <geometry>
        <mesh filename="package://mini_pupper_2_description/meshes/rbfoot.stl" scale="1 1 1"/>
      </geometry>
      <material name="opaque666666"/>
    </visual>
    <collision>
      <origin rpy="0 0 0" xyz="0.063843 0.047765 0.1095"/>
      <geometry>
        <mesh filename="package://mini_pupper_2_description/meshes/rbfoot.stl" scale="1 1 1"/>
      </geometry>
    </collision>
  </link>
  <link name="lbfoot">
    <inertial>
      <origin rpy="0 0 0" xyz="-0.0024630193952935586 -2.855826621572799e-07 0.00780181622349041"/>
      <mass value="0.0014053107976262874"/>
      <inertia ixx="0.0" ixy="0.0" ixz="-0.0" iyy="0.0" iyz="-0.0" izz="0.0"/>
    </inertial>
    <visual>
      <origin rpy="0 0 0" xyz="0.063843 -0.048195 0.109514"/>
      <geometry>
        <mesh filename="package://mini_pupper_2_description/meshes/lbfoot.stl" scale="1 1 1"/>
      </geometry>
      <material name="opaque666666"/>
    </visual>
    <collision>
      <origin rpy="0 0 0" xyz="0.063843 -0.048195 0.109514"/>
      <geometry>
        <mesh filename="package://mini_pupper_2_description/meshes/lbfoot.stl" scale="1 1 1"/>
      </geometry>
    </collision>
  </link>
  <link name="lffoot">
    <inertial>
      <origin rpy="0 0 0" xyz="-0.002463300234335934 -2.8611328430766525e-07 0.00780127458383767"/>
      <mass value="0.0014053107976262874"/>
      <inertia ixx="0.0" ixy="0.0" ixz="-0.0" iyy="0.0" iyz="-0.0" izz="0.0"/>
    </inertial>
    <visual>
      <origin rpy="0 0 0" xyz="-0.056689 -0.048195 0.109513"/>
      <geometry>
        <mesh filename="package://mini_pupper_2_description/meshes/lffoot.stl" scale="1 1 1"/>
      </geometry>
      <material name="opaque666666"/>
    </visual>
    <collision>
      <origin rpy="0 0 0" xyz="-0.056689 -0.048195 0.109513"/>
      <geometry>
        <mesh filename="package://mini_pupper_2_description/meshes/lffoot.stl" scale="1 1 1"/>
      </geometry>
    </collision>
  </link>
  <link name="Shell_Hip_Left_1">
    <inertial>
      <origin rpy="0 0 0" xyz="0.002258882765982295 0.008667473212030541 -0.002747896746317195"/>
      <mass value="0.002573897544461238"/>
      <inertia ixx="0.0" ixy="0.0" ixz="0.0" iyy="0.0" iyz="0.0" izz="0.0"/>
    </inertial>
    <visual>
      <origin rpy="0 0 0" xyz="-0.071565 -0.038245 -0.013057"/>
      <geometry>
        <mesh filename="package://mini_pupper_2_description/meshes/Shell_Hip_Left_1.stl" scale="1 1 1"/>
      </geometry>
      <material name="opaque2552210"/>
    </visual>
    <collision>
      <origin rpy="0 0 0" xyz="-0.071565 -0.038245 -0.013057"/>
      <geometry>
        <mesh filename="package://mini_pupper_2_description/meshes/Shell_Hip_Left_1.stl" scale="1 1 1"/>
      </geometry>
    </collision>
  </link>
  <link name="Shell_Hip_Left_2">
    <inertial>
      <origin rpy="0 0 0" xyz="0.0022592683660053597 0.008667473212031727 -0.0027478967463174797"/>
      <mass value="0.002573897544461238"/>
      <inertia ixx="0.0" ixy="0.0" ixz="0.0" iyy="0.0" iyz="0.0" izz="0.0"/>
    </inertial>
    <visual>
      <origin rpy="0 0 0" xyz="0.048967 -0.038245 -0.013057"/>
      <geometry>
        <mesh filename="package://mini_pupper_2_description/meshes/Shell_Hip_Left_2.stl" scale="1 1 1"/>
      </geometry>
      <material name="opaque2552210"/>
    </visual>
    <collision>
      <origin rpy="0 0 0" xyz="0.048967 -0.038245 -0.013057"/>
      <geometry>
        <mesh filename="package://mini_pupper_2_description/meshes/Shell_Hip_Left_2.stl" scale="1 1 1"/>
      </geometry>
    </collision>
  </link>
  <link name="Shell_Hip_Right_1">
    <inertial>
      <origin rpy="0 0 0" xyz="0.002219644336096324 -0.008605630927951344 -0.002709000699399786"/>
      <mass value="0.002396251664132183"/>
      <inertia ixx="0.0" ixy="-0.0" ixz="0.0" iyy="0.0" iyz="-0.0" izz="0.0"/>
    </inertial>
    <visual>
      <origin rpy="0 0 0" xyz="-0.071565 0.037755 -0.013057"/>
      <geometry>
        <mesh filename="package://mini_pupper_2_description/meshes/Shell_Hip_Right_1.stl" scale="1 1 1"/>
      </geometry>
      <material name="opaque2552210"/>
    </visual>
    <collision>
      <origin rpy="0 0 0" xyz="-0.071565 0.037755 -0.013057"/>
      <geometry>
        <mesh filename="package://mini_pupper_2_description/meshes/Shell_Hip_Right_1.stl" scale="1 1 1"/>
      </geometry>
    </collision>
  </link>
  <link name="Shell_Hip_Right_2">
    <inertial>
      <origin rpy="0 0 0" xyz="0.0022200295152449145 -0.008607013686777375 -0.0027033986949916797"/>
      <mass value="0.002396251664132183"/>
      <inertia ixx="0.0" ixy="-0.0" ixz="0.0" iyy="0.0" iyz="-0.0" izz="0.0"/>
    </inertial>
    <visual>
      <origin rpy="0 0 0" xyz="0.048967 0.037748 -0.013064"/>
      <geometry>
        <mesh filename="package://mini_pupper_2_description/meshes/Shell_Hip_Right_2.stl" scale="1 1 1"/>
      </geometry>
      <material name="opaque2552210"/>
    </visual>
    <collision>
      <origin rpy="0 0 0" xyz="0.048967 0.037748 -0.013064"/>
      <geometry>
        <mesh filename="package://mini_pupper_2_description/meshes/Shell_Hip_Right_2.stl" scale="1 1 1"/>
      </geometry>
    </collision>
  </link>
  <link name="Shell_Leg_Upper_LeftSide_1">
    <inertial>
      <origin rpy="0 0 0" xyz="-0.0026521199361419917 0.00790352811362325 0.004979527414372081"/>
      <mass value="0.00223142111318912"/>
      <inertia ixx="1e-06" ixy="0.0" ixz="0.0" iyy="1e-06" iyz="-0.0" izz="0.0"/>
    </inertial>
    <visual>
      <origin rpy="0 0 0" xyz="-0.052162 -0.044445 0.018943"/>
      <geometry>
        <mesh filename="package://mini_pupper_2_description/meshes/Shell_Leg_Upper_LeftSide_1.stl" scale="1 1 1"/>
      </geometry>
      <material name="opaque2552210"/>
    </visual>
    <collision>
      <origin rpy="0 0 0" xyz="-0.052162 -0.044445 0.018943"/>
      <geometry>
        <mesh filename="package://mini_pupper_2_description/meshes/Shell_Leg_Upper_LeftSide_1.stl" scale="1 1 1"/>
      </geometry>
    </collision>
  </link>
  <link name="Shell_Leg_Upper_LeftSide_2">
    <inertial>
      <origin rpy="0 0 0" xyz="-0.002652484362897875 0.007903528639619295 0.004979527279084269"/>
      <mass value="0.00223142111318912"/>
      <inertia ixx="1e-06" ixy="0.0" ixz="0.0" iyy="1e-06" iyz="-0.0" izz="0.0"/>
    </inertial>
    <visual>
      <origin rpy="0 0 0" xyz="0.068367 -0.044445 0.018943"/>
      <geometry>
        <mesh filename="package://mini_pupper_2_description/meshes/Shell_Leg_Upper_LeftSide_2.stl" scale="1 1 1"/>
      </geometry>
      <material name="opaque2552210"/>
    </visual>
    <collision>
      <origin rpy="0 0 0" xyz="0.068367 -0.044445 0.018943"/>
      <geometry>
        <mesh filename="package://mini_pupper_2_description/meshes/Shell_Leg_Upper_LeftSide_2.stl" scale="1 1 1"/>
      </geometry>
    </collision>
  </link>
  <link name="Shell_Leg_Upper_RightSide_1">
    <inertial>
      <origin rpy="0 0 0" xyz="-0.0027172440375204526 -0.007907075713007534 0.004991745926148535"/>
      <mass value="0.0022016115622538724"/>
      <inertia ixx="1e-06" ixy="-0.0" ixz="0.0" iyy="1e-06" iyz="0.0" izz="0.0"/>
    </inertial>
    <visual>
      <origin rpy="0 0 0" xyz="-0.052165 0.043955 0.018943"/>
      <geometry>
        <mesh filename="package://mini_pupper_2_description/meshes/Shell_Leg_Upper_RightSide_1.stl" scale="1 1 1"/>
      </geometry>
      <material name="opaque2552210"/>
    </visual>
    <collision>
      <origin rpy="0 0 0" xyz="-0.052165 0.043955 0.018943"/>
      <geometry>
        <mesh filename="package://mini_pupper_2_description/meshes/Shell_Leg_Upper_RightSide_1.stl" scale="1 1 1"/>
      </geometry>
    </collision>
  </link>
  <link name="Shell_Leg_Upper_RightSide_2">
    <inertial>
      <origin rpy="0 0 0" xyz="-0.002716858856166446 -0.007903712439730225 0.004996352480544097"/>
      <mass value="0.0022016115622538724"/>
      <inertia ixx="1e-06" ixy="-0.0" ixz="0.0" iyy="1e-06" iyz="0.0" izz="0.0"/>
    </inertial>
    <visual>
      <origin rpy="0 0 0" xyz="0.068367 0.043966 0.018932"/>
      <geometry>
        <mesh filename="package://mini_pupper_2_description/meshes/Shell_Leg_Upper_RightSide_2.stl" scale="1 1 1"/>
      </geometry>
      <material name="opaque2552210"/>
    </visual>
    <collision>
      <origin rpy="0 0 0" xyz="0.068367 0.043966 0.018932"/>
      <geometry>
        <mesh filename="package://mini_pupper_2_description/meshes/Shell_Leg_Upper_RightSide_2.stl" scale="1 1 1"/>
      </geometry>
    </collision>
  </link>
  <link name="Shell_Side">
    <inertial>
      <origin rpy="0 0 0" xyz="-2.7696824994153518e-05 0.029999714418054345 0.022370567779566777"/>
      <mass value="0.0051928835390001775"/>
      <inertia ixx="6e-06" ixy="0.0" ixz="0.0" iyy="3e-06" iyz="0.0" izz="7e-06"/>
    </inertial>
    <visual>
      <origin rpy="0 0 0" xyz="0.002701 0.029755 0.016293"/>
      <geometry>
        <mesh filename="package://mini_pupper_2_description/meshes/Shell_Side.stl" scale="1 1 1"/>
      </geometry>
      <material name="opaque2552210"/>
    </visual>
    <collision>
      <origin rpy="0 0 0" xyz="0.002701 0.029755 0.016293"/>
      <geometry>
        <mesh filename="package://mini_pupper_2_description/meshes/Shell_Side.stl" scale="1 1 1"/>
      </geometry>
    </collision>
  </link>
  <joint name="base_link_to_base_inertia" type="fixed">
    <parent link="base_link"/>
    <child link="base_inertia"/>
    <origin rpy="0 0 0" xyz="0 0 0"/>
  </joint>
  <joint name="base_lf1" type="revolute">
    <origin rpy="0 0 0" xyz="0.037299 0.023745 5.7e-05"/>
    <parent link="base_link"/>
    <child link="lf1"/>
    <axis xyz="1.0 0.0 0.0"/>
    <limit effort="5" lower="-3.141593" upper="3.141593" velocity="1.5"/>
  </joint>
  <joint name="lf1_lf2" type="revolute">
    <origin rpy="0 0 0" xyz="0.014866 0.0177 0.0"/>
    <parent link="lf1"/>
    <child link="lf2"/>
    <axis xyz="0.0 1.0 -0.0"/>
    <limit effort="5" lower="-3.141593" upper="3.141593" velocity="1.5"/>
  </joint>
  <joint name="lf2_lf3" type="revolute">
    <origin rpy="0 0 0" xyz="-6e-06 0.003 -0.05"/>
    <parent link="lf2"/>
    <child link="lf3"/>
    <axis xyz="0.0 1.0 -0.0"/>
    <limit effort="5" lower="-3.141593" upper="3.141593" velocity="1.5"/>
  </joint>
  <joint name="base_rf1" type="revolute">
    <origin rpy="0 0 0" xyz="0.037299 -0.023255 5.7e-05"/>
    <parent link="base_link"/>
    <child link="rf1"/>
    <axis xyz="1.0 0.0 0.0"/>
    <limit effort="5" lower="-3.141593" upper="3.141593" velocity="1.5"/>
  </joint>
  <joint name="rf1_rf2" type="revolute">
    <origin rpy="0 0 0" xyz="0.014866 -0.0177 0.0"/>
    <parent link="rf1"/>
    <child link="rf2"/>
    <axis xyz="0.0 1.0 0.0"/>
    <limit effort="5" lower="-3.141593" upper="3.141593" velocity="1.5"/>
  </joint>
  <joint name="rf2_rf3" type="revolute">
    <origin rpy="0 0 0" xyz="0.0 -0.003 -0.05"/>
    <parent link="rf2"/>
    <child link="rf3"/>
    <axis xyz="0.0 1.0 0.0"/>
    <limit effort="5" lower="-3.141593" upper="3.141593" velocity="1.5"/>
  </joint>
  <joint name="base_rb1" type="revolute">
    <origin rpy="0 0 0" xyz="-0.042701 -0.023255 5.7e-05"/>
    <parent link="base_link"/>
    <child link="rb1"/>
    <axis xyz="1.0 0.0 0.0"/>
    <limit effort="5" lower="-3.141593" upper="3.141593" velocity="1.5"/>
  </joint>
  <joint name="rb1_rb2" type="revolute">
    <origin rpy="0 0 0" xyz="-0.025666 -0.0177 9e-06"/>
    <parent link="rb1"/>
    <child link="rb2"/>
    <axis xyz="0.0 1.0 0.0"/>
    <limit effort="5" lower="-3.141593" upper="3.141593" velocity="1.5"/>
  </joint>
  <joint name="rb2_rb3" type="revolute">
    <origin rpy="0 0 0" xyz="0.0 -0.003028 -0.049998"/>
    <parent link="rb2"/>
    <child link="rb3"/>
    <axis xyz="0.0 1.0 0.0"/>
    <limit effort="5" lower="-3.141593" upper="3.141593" velocity="1.5"/>
  </joint>
  <joint name="base_lb1" type="revolute">
    <origin rpy="0 0 0" xyz="-0.042701 0.023745 5.7e-05"/>
    <parent link="base_link"/>
    <child link="lb1"/>
    <axis xyz="1.0 0.0 0.0"/>
    <limit effort="5" lower="-3.141593" upper="3.141593" velocity="1.5"/>
  </joint>
  <joint name="lb1_lb2" type="revolute">
    <origin rpy="0 0 0" xyz="-0.025666 0.0177 0.0"/>
    <parent link="lb1"/>
    <child link="lb2"/>
    <axis xyz="0.0 1.0 -0.0"/>
    <limit effort="5" lower="-3.141593" upper="3.141593" velocity="1.5"/>
  </joint>
  <joint name="lb2_lb3" type="revolute">
    <origin rpy="0 0 0" xyz="0.0 0.003 -0.05"/>
    <parent link="lb2"/>
    <child link="lb3"/>
    <axis xyz="0.0 1.0 -0.0"/>
    <limit effort="5" lower="-3.141593" upper="3.141593" velocity="1.5"/>
  </joint>
  <joint name="base_front" type="fixed">
    <origin rpy="0 0 0" xyz="0.089299 0.000245 -0.015543"/>
    <parent link="base_link"/>
    <child link="Body_front"/>
  </joint>
  <joint name="base_board" type="fixed">
    <origin rpy="0 0 0" xyz="-0.087701 -0.023255 0.026457"/>
    <parent link="base_link"/>
    <child link="Board_PCB"/>
  </joint>
  <joint name="base_cn1" type="fixed">
    <origin rpy="0 0 0" xyz="0.149035 0.023472 0.0"/>
    <parent link="Board_PCB"/>
    <child link="Board_connectors_1"/>
  </joint>
  <joint name="base_cn2" type="fixed">
    <origin rpy="0 0 0" xyz="0.042355 0.0235 0.0"/>
    <parent link="Board_PCB"/>
    <child link="Board_connectors_2"/>
  </joint>
  <joint name="rf3_foot" type="fixed">
    <origin rpy="0 0 0" xyz="0.004524 -0.00375 -0.059571"/>
    <parent link="rf3"/>
    <child link="rffoot"/>
  </joint>
  <joint name="rb3_foot" type="fixed">
    <origin rpy="0 0 0" xyz="0.004524 -0.003782 -0.059568"/>
    <parent link="rb3"/>
    <child link="rbfoot"/>
  </joint>
  <joint name="lb3_foot" type="fixed">
    <origin rpy="0 0 0" xyz="0.004524 0.00375 -0.059571"/>
    <parent link="lb3"/>
    <child link="lbfoot"/>
  </joint>
  <joint name="lf3_foot" type="fixed">
    <origin rpy="0 0 0" xyz="0.00453 0.00375 -0.05957"/>
    <parent link="lf3"/>
    <child link="lffoot"/>
  </joint>
  <joint name="lf1_hip" type="fixed">
    <origin rpy="0 0 0" xyz="0.034266 0.0145 0.013"/>
    <parent link="lf1"/>
    <child link="Shell_Hip_Left_1"/>
  </joint>
  <joint name="lb1_hip" type="fixed">
    <origin rpy="0 0 0" xyz="-0.006266 0.0145 0.013"/>
    <parent link="lb1"/>
    <child link="Shell_Hip_Left_2"/>
  </joint>
  <joint name="rf1_hip" type="fixed">
    <origin rpy="0 0 0" xyz="0.034266 -0.0145 0.013"/>
    <parent link="rf1"/>
    <child link="Shell_Hip_Right_1"/>
  </joint>
  <joint name="rb2_hip" type="fixed">
    <origin rpy="0 0 0" xyz="-0.006266 -0.014493 0.013007"/>
    <parent link="rb1"/>
    <child link="Shell_Hip_Right_2"/>
  </joint>
  <joint name="lf2_shell" type="fixed">
    <origin rpy="0 0 0" xyz="-3e-06 0.003 -0.019"/>
    <parent link="lf2"/>
    <child link="Shell_Leg_Upper_LeftSide_1"/>
  </joint>
  <joint name="lb2_shell" type="fixed">
    <origin rpy="0 0 0" xyz="0.0 0.003 -0.019"/>
    <parent link="lb2"/>
    <child link="Shell_Leg_Upper_LeftSide_2"/>
  </joint>
  <joint name="rf2_shell" type="fixed">
    <origin rpy="0 0 0" xyz="0.0 -0.003 -0.019"/>
    <parent link="rf2"/>
    <child link="Shell_Leg_Upper_RightSide_1"/>
  </joint>
  <joint name="rb2_shell" type="fixed">
    <origin rpy="0 0 0" xyz="0.0 -0.003011 -0.018998"/>
    <parent link="rb2"/>
    <child link="Shell_Leg_Upper_RightSide_2"/>
  </joint>
  <joint name="base_sides" type="fixed">
    <origin rpy="0 0 0" xyz="-0.002701 -0.029755 -0.016293"/>
    <parent link="base_link"/>
    <child link="Shell_Side"/>
  </joint>
  <ros2_control name="GazeboSystem" type="system">
    <hardware>
      <plugin>gazebo_ros2_control/GazeboSystem</plugin>
    </hardware>
    <joint name="base_lf1">
      <command_interface name="effort"/>
      <state_interface name="position"/>
      <state_interface name="velocity"/>
    </joint>
    <joint name="lf1_lf2">
      <command_interface name="effort"/>
      <state_interface name="position"/>
      <state_interface name="velocity"/>
    </joint>
    <joint name="lf2_lf3">
      <command_interface name="effort"/>
      <state_interface name="position"/>
      <state_interface name="velocity"/>
    </joint>
    <joint name="base_rf1">
      <command_interface name="effort"/>
      <state_interface name="position"/>
      <state_interface name="velocity"/>
    </joint>
    <joint name="rf1_rf2">
      <command_interface name="effort"/>
      <state_interface name="position"/>
      <state_interface name="velocity"/>
    </joint>
    <joint name="rf2_rf3">
      <command_interface name="effort"/>
      <state_interface name="position"/>
      <state_interface name="velocity"/>
    </joint>
    <joint name="base_lb1">
      <command_interface name="effort"/>
      <state_interface name="position"/>
      <state_interface name="velocity"/>
    </joint>
    <joint name="lb1_lb2">
      <command_interface name="effort"/>
      <state_interface name="position"/>
      <state_interface name="velocity"/>
    </joint>
    <joint name="lb2_lb3">
      <command_interface name="effort"/>
      <state_interface name="position"/>
      <state_interface name="velocity"/>
    </joint>
    <joint name="base_rb1">
      <command_interface name="effort"/>
      <state_interface name="position"/>
      <state_interface name="velocity"/>
    </joint>
    <joint name="rb1_rb2">
      <command_interface name="effort"/>
      <state_interface name="position"/>
      <state_interface name="velocity"/>
    </joint>
    <joint name="rb2_rb3">
      <command_interface name="effort"/>
      <state_interface name="position"/>
      <state_interface name="velocity"/>
    </joint>
  </ros2_control>
  <!-- coloring Gazebo model -->
  <gazebo reference="base_link">
    <material>Gazebo/FlatBlack</material>
  </gazebo>
  <gazebo reference="Shell_Side">
    <material>Gazebo/Yellow</material>
  </gazebo>
  <gazebo reference="lf1">
    <kp>1000000.0</kp>
    <kd>1.0</kd>
    <mu1>0.8</mu1>
    <mu2>0.8</mu2>
    <maxVel>0.0</maxVel>
    <minDepth>0.001</minDepth>
    <material>Gazebo/FlatBlack</material>
  </gazebo>
  <gazebo reference="Shell_Hip_Left_1">
    <material>Gazebo/Yellow</material>
  </gazebo>
  <gazebo reference="lf2">
    <kp>1000000.0</kp>
    <kd>1.0</kd>
    <mu1>0.8</mu1>
    <mu2>0.8</mu2>
    <maxVel>0.0</maxVel>
    <minDepth>0.001</minDepth>
    <material>Gazebo/FlatBlack</material>
  </gazebo>
  <gazebo reference="Shell_Leg_Upper_LeftSide_1">
    <material>Gazebo/Yellow</material>
  </gazebo>
  <gazebo reference="lf3">
    <kp>1000000.0</kp>
    <kd>1.0</kd>
    <mu1>0.8</mu1>
    <mu2>0.8</mu2>
    <maxVel>0.0</maxVel>
    <minDepth>0.001</minDepth>
    <material>Gazebo/FlatBlack</material>
  </gazebo>
  <gazebo reference="lffoot">
    <kp>1000000.0</kp>
    <kd>1.0</kd>
    <mu1>0.8</mu1>
    <mu2>0.8</mu2>
    <maxVel>0.0</maxVel>
    <minDepth>0.001</minDepth>
    <material>Gazebo/FlatBlack</material>
  </gazebo>
  <gazebo reference="rf1">
    <kp>1000000.0</kp>
    <kd>1.0</kd>
    <mu1>0.8</mu1>
    <mu2>0.8</mu2>
    <maxVel>0.0</maxVel>
    <minDepth>0.001</minDepth>
    <material>Gazebo/FlatBlack</material>
  </gazebo>
  <gazebo reference="Shell_Hip_Right_1">
    <material>Gazebo/Yellow</material>
  </gazebo>
  <gazebo reference="rf2">
    <kp>1000000.0</kp>
    <kd>1.0</kd>
    <mu1>0.8</mu1>
    <mu2>0.8</mu2>
    <maxVel>0.0</maxVel>
    <minDepth>0.001</minDepth>
    <material>Gazebo/FlatBlack</material>
  </gazebo>
  <gazebo reference="Shell_Leg_Upper_RightSide_1">
    <material>Gazebo/Yellow</material>
  </gazebo>
  <gazebo reference="rf3">
    <kp>1000000.0</kp>
    <kd>1.0</kd>
    <mu1>0.8</mu1>
    <mu2>0.8</mu2>
    <maxVel>0.0</maxVel>
    <minDepth>0.001</minDepth>
    <material>Gazebo/FlatBlack</material>
  </gazebo>
  <gazebo reference="rffoot">
    <kp>1000000.0</kp>
    <kd>1.0</kd>
    <mu1>0.8</mu1>
    <mu2>0.8</mu2>
    <maxVel>0.0</maxVel>
    <minDepth>0.001</minDepth>
    <material>Gazebo/FlatBlack</material>
  </gazebo>
  <gazebo reference="lb1">
    <kp>1000000.0</kp>
    <kd>1.0</kd>
    <mu1>0.8</mu1>
    <mu2>0.8</mu2>
    <maxVel>0.0</maxVel>
    <minDepth>0.001</minDepth>
    <material>Gazebo/FlatBlack</material>
  </gazebo>
  <gazebo reference="Shell_Hip_Left_2">
    <material>Gazebo/Yellow</material>
  </gazebo>
  <gazebo reference="lb2">
    <kp>1000000.0</kp>
    <kd>1.0</kd>
    <mu1>0.8</mu1>
    <mu2>0.8</mu2>
    <maxVel>0.0</maxVel>
    <minDepth>0.001</minDepth>
    <material>Gazebo/FlatBlack</material>
  </gazebo>
  <gazebo reference="Shell_Leg_Upper_LeftSide_2">
    <material>Gazebo/Yellow</material>
  </gazebo>
  <gazebo reference="lb3">
    <kp>1000000.0</kp>
    <kd>1.0</kd>
    <mu1>0.8</mu1>
    <mu2>0.8</mu2>
    <maxVel>0.0</maxVel>
    <minDepth>0.001</minDepth>
    <material>Gazebo/FlatBlack</material>
  </gazebo>
  <gazebo reference="lbfoot">
    <kp>1000000.0</kp>
    <kd>1.0</kd>
    <mu1>0.8</mu1>
    <mu2>0.8</mu2>
    <maxVel>0.0</maxVel>
    <minDepth>0.001</minDepth>
    <material>Gazebo/FlatBlack</material>
  </gazebo>
  <gazebo reference="rb1">
    <kp>1000000.0</kp>
    <kd>1.0</kd>
    <mu1>0.8</mu1>
    <mu2>0.8</mu2>
    <maxVel>0.0</maxVel>
    <minDepth>0.001</minDepth>
    <material>Gazebo/FlatBlack</material>
  </gazebo>
  <gazebo reference="Shell_Hip_Right_2">
    <material>Gazebo/Yellow</material>
  </gazebo>
  <gazebo reference="rb2">
    <kp>1000000.0</kp>
    <kd>1.0</kd>
    <mu1>0.8</mu1>
    <mu2>0.8</mu2>
    <maxVel>0.0</maxVel>
    <minDepth>0.001</minDepth>
    <material>Gazebo/FlatBlack</material>
  </gazebo>
  <gazebo reference="Shell_Leg_Upper_RightSide_2">
    <material>Gazebo/Yellow</material>
  </gazebo>
  <gazebo reference="rb3">
    <kp>1000000.0</kp>
    <kd>1.0</kd>
    <mu1>0.8</mu1>
    <mu2>0.8</mu2>
    <maxVel>0.0</maxVel>
    <minDepth>0.001</minDepth>
    <material>Gazebo/FlatBlack</material>
  </gazebo>
  <gazebo reference="rbfoot">
    <kp>1000000.0</kp>
    <kd>1.0</kd>
    <mu1>0.8</mu1>
    <mu2>0.8</mu2>
    <maxVel>0.0</maxVel>
    <minDepth>0.001</minDepth>
    <material>Gazebo/FlatBlack</material>
  </gazebo>
  <!-- <gazebo reference="lidar_link">
    <material>Gazebo/FlatBlack</material>
    <sensor type="ray" name="lidar">
      <always_on>true</always_on>
      <update_rate>30</update_rate>
      <pose>0 0 0 0 0 0</pose>
      <visualize>false</visualize>
      <ray>
        <scan>
          <horizontal>
            <samples>1040</samples>
            <resolution>1</resolution>
            <min_angle>0</min_angle>
            <max_angle>6.28</max_angle>
          </horizontal>
        </scan>
        <range>
          <min>0.2</min>
          <max>50.0</max>
          <resolution>0.01</resolution>
        </range>
        <noise>
          <type>gaussian</type>
          <mean>0.0</mean>
          <stddev>0.004</stddev>
        </noise>
      </ray>
      <plugin name="gazebo_ros_lidar_controller" filename="libgazebo_ros_ray_sensor.so">
        <ros>
          <argument>~/out:=/scan</argument>
        </ros>
        <output_type>sensor_msgs/LaserScan</output_type>
        <frame_name>lidar_link</frame_name> -->
  <!--min_intensity>100.0</min_intensity-->
  <!-- </plugin>
    </sensor>
  </gazebo> -->
  <gazebo>
    <plugin filename="libgazebo_ros_p3d.so" name="p3d_base_controller">
      <ros>
        <argument>odom:=odom/ground_truth</argument>
      </ros>
      <body_name>base_link</body_name>
      <frame_name>world</frame_name>
      <update_rate>10.0</update_rate>
      <xyz_offset>0 0 0</xyz_offset>
      <rpy_offset>0 0 0</rpy_offset>
      <gaussian_noise>0.01</gaussian_noise>
    </plugin>
  </gazebo>
  <gazebo>
    <plugin filename="libgazebo_ros2_control.so" name="gazebo_ros2_control">
      <parameters>/home/peter/ros2_ws/install/mini_pupper_2_description/share/mini_pupper_2_description/config/ros_control/mini_pupper_controller.yaml</parameters>
    </plugin>
  </gazebo>
  <link name="imu_link">
    <inertial>
      <mass value="0.0001"/>
      <origin rpy="0 0 0" xyz="0 0 0"/>
      <inertia ixx="1e-09" ixy="0.0" ixz="0.0" iyy="1e-09" iyz="0.0" izz="1e-09"/>
    </inertial>
  </link>
  <joint name="imu_joint" type="fixed">
    <parent link="base_link"/>
    <child link="imu_link"/>
  </joint>
  <gazebo reference="imu_link">
    <sensor name="imu_controller" type="imu">
      <always_on>true</always_on>
      <update_rate>50</update_rate>
      <plugin filename="libgazebo_ros_imu_sensor.so" name="gazebo_ros_imu_sensor">
        <ros>
          <namespace>/imu</namespace>
          <argument>~/out:=data</argument>
        </ros>
      </plugin>
    </sensor>
  </gazebo>
</robot>
