<?xml version="1.0" ?>
<!-- =================================================================================== -->
<!-- |    This document was autogenerated by xacro from mini_pupper_description.urdf.xacro | -->
<!-- |    EDITING THIS FILE BY HAND IS NOT RECOMMENDED                                 | -->
<!-- =================================================================================== -->
<!-- This URDF was automatically created by SolidWorks to URDF Exporter! Originally created by Stephen Brawner (brawner@gmail.com) 
     Commit Version: 1.6.0-1-g15f4949  Build Version: 1.6.7594.29634
     For more information, please see http://wiki.ros.org/sw_urdf_exporter -->
<robot name="mini_pupper_description">
  <material name="aluminum">
    <color rgba="0.5 0.5 0.5 1"/>
  </material>
  <material name="plastic">
    <color rgba="0.1 0.1 0.1 1"/>
  </material>
  <link name="base_link">
    <inertial>
      <origin rpy="0 0 0" xyz="0.00660426498064391 8.26976427410632E-06 0.0200623332889016"/>
      <mass value="0.7"/>
      <inertia ixx="3.3463402501291E-05" ixy="-2.80059099694232E-07" ixz="1.59673474113324E-08" iyy="9.73631866262367E-05" iyz="2.90091309171363E-09" izz="0.00010929561287651"/>
    </inertial>
    <visual>
      <origin rpy="0 0 0" xyz="0 0 0"/>
      <geometry>
        <mesh filename="package://mini_pupper_description/meshes/base_link.STL"/>
      </geometry>
      <material name="">
        <color rgba="0.2 0.2 0.2 1"/>
      </material>
    </visual>
    <collision>
      <origin rpy="0 0 0" xyz="0 0 0"/>
      <geometry>
        <mesh filename="package://mini_pupper_description/meshes/base_link.STL"/>
      </geometry>
    </collision>
  </link>
  <link name="yellow_plate">
    <inertial>
      <origin rpy="0 0 0" xyz="-0.0265979628467293 0.00100265856976752 -0.0205696864633185"/>
      <mass value="0.3"/>
      <inertia ixx="2.63040079082852E-05" ixy="-5.56245753822899E-07" ixz="-1.84870621911762E-06" iyy="5.64225933806734E-05" iyz="6.34788357961111E-09" izz="7.28861115131965E-05"/>
    </inertial>
    <visual>
      <origin rpy="0 0 0" xyz="0 0 0"/>
      <geometry>
        <mesh filename="package://mini_pupper_description/meshes/yellow_plate.STL"/>
      </geometry>
      <material name="">
        <color rgba="1 1 0 1"/>
      </material>
    </visual>
    <collision>
      <origin rpy="0 0 0" xyz="0 0 0"/>
      <geometry>
        <mesh filename="package://mini_pupper_description/meshes/yellow_plate.STL"/>
      </geometry>
    </collision>
  </link>
  <joint name="base_yellowplate" type="fixed">
    <origin rpy="0 0 0" xyz="0.0556975724826061 -0.000166914683579864 0.0700000000000001"/>
    <parent link="base_link"/>
    <child link="yellow_plate"/>
    <axis xyz="0 0 0"/>
  </joint>
  <link name="lidar">
    <inertial>
      <origin rpy="0 0 0" xyz="1.56706411611127E-05 -5.16565672073303E-13 -0.0191835739440227"/>
      <mass value="0.27"/>
      <inertia ixx="8.74731426973985E-06" ixy="-6.66781590704156E-08" ixz="1.89196685410159E-11" iyy="8.70097486591694E-06" iyz="-1.13397577799603E-17" izz="9.98821295317784E-06"/>
    </inertial>
    <visual>
      <origin rpy="0 0 0" xyz="0 0 0"/>
      <geometry>
        <mesh filename="package://mini_pupper_description/meshes/lidar.STL"/>
      </geometry>
      <material name="">
        <color rgba="0.2 0.2 0.2 1"/>
      </material>
    </visual>
    <collision>
      <origin rpy="0 0 0" xyz="0 0 0"/>
      <geometry>
        <mesh filename="package://mini_pupper_description/meshes/lidar.STL"/>
      </geometry>
    </collision>
  </link>
  <joint name="base_lidar" type="fixed">
    <origin rpy="0 0 0" xyz="-0.070475 0.0001 0.08"/>
    <parent link="base_link"/>
    <child link="lidar"/>
    <axis xyz="0 0 0"/>
  </joint>
  <link name="lf1">
    <inertial>
      <origin rpy="0 0 0" xyz="0.00519546289834071 0.00279246570724686 0.0063718183283844"/>
      <mass value="0.25"/>
      <inertia ixx="2.16792829512222E-06" ixy="-6.02508577918412E-09" ixz="5.90505149164062E-08" iyy="3.44088340998371E-06" iyz="-1.92270764243995E-08" izz="3.1963969100223E-06"/>
    </inertial>
    <visual>
      <origin rpy="0 0 0" xyz="0 0 0"/>
      <geometry>
        <mesh filename="package://mini_pupper_description/meshes/lf1.STL"/>
      </geometry>
      <material name="">
        <color rgba="0.2 0.2 0.2 1"/>
      </material>
    </visual>
    <collision>
      <origin rpy="0 0 0" xyz="0 0 0"/>
      <geometry>
        <mesh filename="package://mini_pupper_description/meshes/lf1.STL"/>
      </geometry>
    </collision>
  </link>
  <joint name="base_lf1" type="revolute">
    <origin rpy="0 0 0" xyz="0.06014 0.0235 0.0171"/>
    <parent link="base_link"/>
    <child link="lf1"/>
    <axis xyz="1 0 0"/>
    <limit effort="5" lower="-3.14" upper="3.14" velocity="1.5"/>
  </joint>
  <link name="lpf1">
    <inertial>
      <origin rpy="0 0 0" xyz="0.00874956145631699 -0.0057963784801828 -0.00450693686767675"/>
      <mass value="0.005"/>
      <inertia ixx="8.1813456986579E-07" ixy="8.78628279607434E-08" ixz="-3.80902489021625E-08" iyy="1.01534357250605E-06" iyz="7.21698179094722E-08" izz="5.74768328209026E-07"/>
    </inertial>
    <visual>
      <origin rpy="0 0 0" xyz="0 0 0"/>
      <geometry>
        <mesh filename="package://mini_pupper_description/meshes/lpf1.STL"/>
      </geometry>
      <material name="">
        <color rgba="1 1 0 1"/>
      </material>
    </visual>
    <collision>
      <origin rpy="0 0 0" xyz="0 0 0"/>
      <geometry>
        <mesh filename="package://mini_pupper_description/meshes/lpf1.STL"/>
      </geometry>
    </collision>
  </link>
  <joint name="lf1_plate" type="fixed">
    <origin rpy="0 0 0" xyz="0.0107600000007337 0.0306999999992666 0.0130000000001585"/>
    <parent link="lf1"/>
    <child link="lpf1"/>
    <axis xyz="0 0 0"/>
  </joint>
  <link name="lf2">
    <inertial>
      <origin rpy="0 0 0" xyz="1.3988810110277E-14 -0.00101365780344401 -0.0182607957247316"/>
      <mass value="0.125"/>
      <inertia ixx="2.56149742521739E-07" ixy="8.35373111913384E-24" ixz="-9.77082381851893E-23" iyy="2.61721029733561E-07" iyz="1.5669129777113E-10" izz="6.97328365560507E-09"/>
    </inertial>
    <visual>
      <origin rpy="0 0 0" xyz="0 0 0"/>
      <geometry>
        <mesh filename="package://mini_pupper_description/meshes/lf2.STL"/>
      </geometry>
      <material name="">
        <color rgba="0.2 0.2 0.2 1"/>
      </material>
    </visual>
    <collision>
      <origin rpy="0 0 0" xyz="0 0 0"/>
      <geometry>
        <mesh filename="package://mini_pupper_description/meshes/lf2.STL"/>
      </geometry>
    </collision>
  </link>
  <joint name="lf1_lf2" type="revolute">
    <origin rpy="0 0 0" xyz="-4E-05 0.0197 0"/>
    <parent link="lf1"/>
    <child link="lf2"/>
    <axis xyz="0 1 0"/>
    <limit effort="5" lower="-3.14" upper="3.14" velocity="1.5"/>
  </joint>
  <link name="lpf2">
    <inertial>
      <origin rpy="0 0 0" xyz="-0.00217866290818425 -0.001566384405815 0.034099120119674"/>
      <mass value="0.005"/>
      <inertia ixx="9.34196968596698E-07" ixy="5.95712897889122E-09" ixz="2.71831950266143E-08" iyy="1.03925284587874E-06" iyz="-2.35723407122805E-08" izz="1.25155524458103E-07"/>
    </inertial>
    <visual>
      <origin rpy="0 0 0" xyz="0 0 0"/>
      <geometry>
        <mesh filename="package://mini_pupper_description/meshes/lpf2.STL"/>
      </geometry>
      <material name="">
        <color rgba="1 1 0 1"/>
      </material>
    </visual>
    <collision>
      <origin rpy="0 0 0" xyz="0 0 0"/>
      <geometry>
        <mesh filename="package://mini_pupper_description/meshes/lpf2.STL"/>
      </geometry>
    </collision>
  </link>
  <joint name="lf2_plate" type="fixed">
    <origin rpy="0 0 0" xyz="0 0.00999999999998141 -0.0500000000003035"/>
    <parent link="lf2"/>
    <child link="lpf2"/>
    <axis xyz="0 0 0"/>
  </joint>
  <link name="lf3">
    <inertial>
      <origin rpy="0 0 0" xyz="0.000237268946264135 -0.000198312911218489 -0.016535656084904"/>
      <mass value="0.0625"/>
      <inertia ixx="3.17108530490043E-07" ixy="-8.19624096923979E-15" ixz="6.63472331942981E-09" iyy="3.19154628309319E-07" iyz="-1.49720639035527E-14" izz="2.63315261030515E-09"/>
    </inertial>
    <visual>
      <origin rpy="0 0 0" xyz="0 0 0"/>
      <geometry>
        <mesh filename="package://mini_pupper_description/meshes/lf3.STL"/>
      </geometry>
      <material name="">
        <color rgba="0.2 0.2 0.2 1"/>
      </material>
    </visual>
    <collision>
      <origin rpy="0 0 0" xyz="0 0 0"/>
      <geometry>
        <mesh filename="package://mini_pupper_description/meshes/lf3.STL"/>
      </geometry>
    </collision>
  </link>
  <joint name="lf2_lf3" type="revolute">
    <origin rpy="0 0 0" xyz="0 0.00475 -0.05"/>
    <parent link="lf2"/>
    <child link="lf3"/>
    <axis xyz="0 1 0"/>
    <limit effort="5" lower="-3.14" upper="3.14" velocity="1.5"/>
  </joint>
  <link name="lffoot">
    <inertial>
      <origin rpy="0 0 0" xyz="0.000424477269554246 -1.81550998540336E-09 0.000743181675761886"/>
      <mass value="0.0625"/>
      <inertia ixx="3.88852646564769E-08" ixy="3.60583012427767E-14" ixz="-2.99983098577409E-09" iyy="5.81684749230997E-08" iyz="1.31966996419541E-14" izz="2.7893076025217E-08"/>
    </inertial>
    <visual>
      <origin rpy="0 0 0" xyz="0 0 0"/>
      <geometry>
        <mesh filename="package://mini_pupper_description/meshes/lffoot.STL"/>
      </geometry>
      <material name="">
        <color rgba="0.2 0.2 0.2 1"/>
      </material>
    </visual>
    <collision>
      <origin rpy="0 0 0" xyz="0 0 0"/>
      <geometry>
        <mesh filename="package://mini_pupper_description/meshes/lffoot.STL"/>
      </geometry>
    </collision>
  </link>
  <joint name="lf3_foot" type="fixed">
    <origin rpy="0 0 0" xyz="0 -4.9999999999939E-05 -0.056"/>
    <parent link="lf3"/>
    <child link="lffoot"/>
    <axis xyz="0 0 0"/>
  </joint>
  <link name="rf1">
    <inertial>
      <origin rpy="0 0 0" xyz="0.00519546371324378 -0.00279246587993302 0.00637181920913787"/>
      <mass value="0.25"/>
      <inertia ixx="2.16792855298178E-06" ixy="6.02507996345136E-09" ixz="5.90497387290611E-08" iyy="3.44088387908968E-06" iyz="1.9227066292514E-08" izz="3.19639712715432E-06"/>
    </inertial>
    <visual>
      <origin rpy="0 0 0" xyz="0 0 0"/>
      <geometry>
        <mesh filename="package://mini_pupper_description/meshes/rf1.STL"/>
      </geometry>
      <material name="">
        <color rgba="0.2 0.2 0.2 1"/>
      </material>
    </visual>
    <collision>
      <origin rpy="0 0 0" xyz="0 0 0"/>
      <geometry>
        <mesh filename="package://mini_pupper_description/meshes/rf1.STL"/>
      </geometry>
    </collision>
  </link>
  <joint name="base_rf1" type="revolute">
    <origin rpy="0 0 0" xyz="0.06014 -0.0235 0.0171"/>
    <parent link="base_link"/>
    <child link="rf1"/>
    <axis xyz="1 0 0"/>
    <limit effort="5" lower="-3.14" upper="3.14" velocity="1.5"/>
  </joint>
  <link name="rpf1">
    <inertial>
      <origin rpy="0 0 0" xyz="0.00874955403415308 0.00579637837903884 -0.0045069339932012"/>
      <mass value="0.005"/>
      <inertia ixx="8.18135114571354E-07" ixy="-8.78629613826191E-08" ixz="-3.80902795457312E-08" iyy="1.01534342262631E-06" iyz="-7.21698953092889E-08" izz="5.74767755618967E-07"/>
    </inertial>
    <visual>
      <origin rpy="0 0 0" xyz="0 0 0"/>
      <geometry>
        <mesh filename="package://mini_pupper_description/meshes/rpf1.STL"/>
      </geometry>
      <material name="">
        <color rgba="1 1 0 1"/>
      </material>
    </visual>
    <collision>
      <origin rpy="0 0 0" xyz="0 0 0"/>
      <geometry>
        <mesh filename="package://mini_pupper_description/meshes/rpf1.STL"/>
      </geometry>
    </collision>
  </link>
  <joint name="rf1_plate" type="fixed">
    <origin rpy="0 0 0" xyz="0.0107599999999999 -0.0306999999999999 0.013"/>
    <parent link="rf1"/>
    <child link="rpf1"/>
    <axis xyz="0 0 0"/>
  </joint>
  <link name="rf2">
    <inertial>
      <origin rpy="0 0 0" xyz="-9.71445146547012E-17 0.00101365780342547 -0.0182607957244276"/>
      <mass value="0.125"/>
      <inertia ixx="2.56149742521738E-07" ixy="8.12572657898901E-24" ixz="1.8668027519541E-22" iyy="2.6172102973356E-07" iyz="-1.56691297771191E-10" izz="6.97328365560504E-09"/>
    </inertial>
    <visual>
      <origin rpy="0 0 0" xyz="0 0 0"/>
      <geometry>
        <mesh filename="package://mini_pupper_description/meshes/rf2.STL"/>
      </geometry>
      <material name="">
        <color rgba="0.2 0.2 0.2 1"/>
      </material>
    </visual>
    <collision>
      <origin rpy="0 0 0" xyz="0 0 0"/>
      <geometry>
        <mesh filename="package://mini_pupper_description/meshes/rf2.STL"/>
      </geometry>
    </collision>
  </link>
  <joint name="rf1_rf2" type="revolute">
    <origin rpy="0 0 0" xyz="-4E-05 -0.0197 0"/>
    <parent link="rf1"/>
    <child link="rf2"/>
    <axis xyz="0 1 0"/>
    <limit effort="5" lower="-3.14" upper="3.14" velocity="1.5"/>
  </joint>
  <link name="rpf2">
    <inertial>
      <origin rpy="0 0 0" xyz="-0.00222610657532629 0.00156905803495648 0.0340862685574021"/>
      <mass value="0.005"/>
      <inertia ixx="9.31223932833859E-07" ixy="-6.03482748767291E-09" ixz="2.85227004671628E-08" iyy="1.03508297458339E-06" iyz="2.34659787841745E-08" izz="1.23911464668974E-07"/>
    </inertial>
    <visual>
      <origin rpy="0 0 0" xyz="0 0 0"/>
      <geometry>
        <mesh filename="package://mini_pupper_description/meshes/rpf2.STL"/>
      </geometry>
      <material name="">
        <color rgba="1 1 0 1"/>
      </material>
    </visual>
    <collision>
      <origin rpy="0 0 0" xyz="0 0 0"/>
      <geometry>
        <mesh filename="package://mini_pupper_description/meshes/rpf2.STL"/>
      </geometry>
    </collision>
  </link>
  <joint name="rf2_plate" type="fixed">
    <origin rpy="0 0 0" xyz="0 -0.00999999999999994 -0.0499999999999996"/>
    <parent link="rf2"/>
    <child link="rpf2"/>
    <axis xyz="0 0 0"/>
  </joint>
  <link name="rf3">
    <inertial>
      <origin rpy="0 0 0" xyz="0.000237280669710932 0.000198312911218648 -0.0165356564440727"/>
      <mass value="0.0625"/>
      <inertia ixx="3.17108530808881E-07" ixy="-7.26391171726489E-15" ixz="6.63472855289727E-09" iyy="3.19154628309318E-07" iyz="1.5448111353928E-14" izz="2.63315229146555E-09"/>
    </inertial>
    <visual>
      <origin rpy="0 0 0" xyz="0 0 0"/>
      <geometry>
        <mesh filename="package://mini_pupper_description/meshes/rf3.STL"/>
      </geometry>
      <material name="">
        <color rgba="0.2 0.2 0.2 1"/>
      </material>
    </visual>
    <collision>
      <origin rpy="0 0 0" xyz="0 0 0"/>
      <geometry>
        <mesh filename="package://mini_pupper_description/meshes/rf3.STL"/>
      </geometry>
    </collision>
  </link>
  <joint name="rf2_rf3" type="revolute">
    <origin rpy="0 0 0" xyz="0 -0.00475 -0.05"/>
    <parent link="rf2"/>
    <child link="rf3"/>
    <axis xyz="0 1 0"/>
    <limit effort="5" lower="-3.14" upper="3.14" velocity="1.5"/>
  </joint>
  <link name="rffoot">
    <inertial>
      <origin rpy="0 0 0" xyz="0.000424477269554566 4.99981844905087E-05 0.000743181675762233"/>
      <mass value="0.0625"/>
      <inertia ixx="3.88852646564774E-08" ixy="3.60583012797131E-14" ixz="-2.99983098577438E-09" iyy="5.81684749231005E-08" iyz="1.31966996988911E-14" izz="2.78930760252171E-08"/>
    </inertial>
    <visual>
      <origin rpy="0 0 0" xyz="0 0 0"/>
      <geometry>
        <mesh filename="package://mini_pupper_description/meshes/rffoot.STL"/>
      </geometry>
      <material name="">
        <color rgba="0.2 0.2 0.2 1"/>
      </material>
    </visual>
    <collision>
      <origin rpy="0 0 0" xyz="0 0 0"/>
      <geometry>
        <mesh filename="package://mini_pupper_description/meshes/rffoot.STL"/>
      </geometry>
    </collision>
  </link>
  <joint name="rf3_foot" type="fixed">
    <origin rpy="0 0 0" xyz="0 0 -0.056"/>
    <parent link="rf3"/>
    <child link="rffoot"/>
    <axis xyz="0 0 0"/>
  </joint>
  <link name="lb1">
    <inertial>
      <origin rpy="0 0 0" xyz="0.00541706873953783 0.00276212057731937 0.00645819913657113"/>
      <mass value="0.25"/>
      <inertia ixx="2.2041347583079E-06" ixy="-1.21330026225997E-08" ixz="-9.24364679790947E-09" iyy="3.50716356932593E-06" iyz="-4.41858294139363E-09" izz="3.24535065112903E-06"/>
    </inertial>
    <visual>
      <origin rpy="0 0 0" xyz="0 0 0"/>
      <geometry>
        <mesh filename="package://mini_pupper_description/meshes/lb1.STL"/>
      </geometry>
      <material name="">
        <color rgba="0.2 0.2 0.2 1"/>
      </material>
    </visual>
    <collision>
      <origin rpy="0 0 0" xyz="0 0 0"/>
      <geometry>
        <mesh filename="package://mini_pupper_description/meshes/lb1.STL"/>
      </geometry>
    </collision>
  </link>
  <joint name="base_lb1" type="revolute">
    <origin rpy="0 0 0" xyz="-0.05886 0.0235 0.0171"/>
    <parent link="base_link"/>
    <child link="lb1"/>
    <axis xyz="1 0 0"/>
    <limit effort="5" lower="-3.14" upper="3.14" velocity="1.5"/>
  </joint>
  <link name="lpb1">
    <inertial>
      <origin rpy="0 0 0" xyz="0.00874956145631699 -0.00579637848018278 -0.00450693686767676"/>
      <mass value="0.005"/>
      <inertia ixx="8.18134569865789E-07" ixy="8.78628279607436E-08" ixz="-3.80902489021627E-08" iyy="1.01534357250605E-06" iyz="7.21698179094726E-08" izz="5.74768328209026E-07"/>
    </inertial>
    <visual>
      <origin rpy="0 0 0" xyz="0 0 0"/>
      <geometry>
        <mesh filename="package://mini_pupper_description/meshes/lpb1.STL"/>
      </geometry>
      <material name="">
        <color rgba="1 1 0 1"/>
      </material>
    </visual>
    <collision>
      <origin rpy="0 0 0" xyz="0 0 0"/>
      <geometry>
        <mesh filename="package://mini_pupper_description/meshes/lpb1.STL"/>
      </geometry>
    </collision>
  </link>
  <joint name="lb1_plate" type="fixed">
    <origin rpy="0 0 0" xyz="0.0107599999999999 0.0307 0.013"/>
    <parent link="lb1"/>
    <child link="lpb1"/>
    <axis xyz="0 0 0"/>
  </joint>
  <link name="lb2">
    <inertial>
      <origin rpy="0 0 0" xyz="-1.17961196366423E-16 -0.00101365780342477 -0.0182607957244282"/>
      <mass value="0.125"/>
      <inertia ixx="2.56149742521739E-07" ixy="4.90778381056253E-24" ixz="-6.13191156321568E-23" iyy="2.61721029733561E-07" iyz="1.56691297771418E-10" izz="6.97328365560507E-09"/>
    </inertial>
    <visual>
      <origin rpy="0 0 0" xyz="0 0 0"/>
      <geometry>
        <mesh filename="package://mini_pupper_description/meshes/lb2.STL"/>
      </geometry>
      <material name="">
        <color rgba="0.2 0.2 0.2 1"/>
      </material>
    </visual>
    <collision>
      <origin rpy="0 0 0" xyz="0 0 0"/>
      <geometry>
        <mesh filename="package://mini_pupper_description/meshes/lb2.STL"/>
      </geometry>
    </collision>
  </link>
  <joint name="lb1_lb2" type="revolute">
    <origin rpy="0 0 0" xyz="-4E-05 0.0197 0"/>
    <parent link="lb1"/>
    <child link="lb2"/>
    <axis xyz="0 1 0"/>
    <limit effort="5" lower="-3.14" upper="3.14" velocity="1.5"/>
  </joint>
  <link name="lpb2">
    <inertial>
      <origin rpy="0 0 0" xyz="-0.00217866290818428 -0.00156638440581503 0.034099120119674"/>
      <mass value="0.005"/>
      <inertia ixx="9.34196968596701E-07" ixy="5.95712897889121E-09" ixz="2.71831950266149E-08" iyy="1.03925284587875E-06" iyz="-2.35723407122794E-08" izz="1.25155524458103E-07"/>
    </inertial>
    <visual>
      <origin rpy="0 0 0" xyz="0 0 0"/>
      <geometry>
        <mesh filename="package://mini_pupper_description/meshes/lpb2.STL"/>
      </geometry>
      <material name="">
        <color rgba="1 1 0 1"/>
      </material>
    </visual>
    <collision>
      <origin rpy="0 0 0" xyz="0 0 0"/>
      <geometry>
        <mesh filename="package://mini_pupper_description/meshes/lpb2.STL"/>
      </geometry>
    </collision>
  </link>
  <joint name="lb2_plate" type="fixed">
    <origin rpy="0 0 0" xyz="0 0.0100000000000007 -0.0500000000000001"/>
    <parent link="lb2"/>
    <child link="lpb2"/>
    <axis xyz="0 0 0"/>
  </joint>
  <link name="lb3">
    <inertial>
      <origin rpy="0 0 0" xyz="0.000237271929228088 -0.000198322763325702 -0.016535653838918"/>
      <mass value="0.0625"/>
      <inertia ixx="3.17108528910548E-07" ixy="-1.44307528577898E-14" ixz="6.6347256081998E-09" iyy="3.19154628310024E-07" iyz="-9.120429245734E-15" izz="2.63315419409871E-09"/>
    </inertial>
    <visual>
      <origin rpy="0 0 0" xyz="0 0 0"/>
      <geometry>
        <mesh filename="package://mini_pupper_description/meshes/lb3.STL"/>
      </geometry>
      <material name="">
        <color rgba="0.2 0.2 0.2 1"/>
      </material>
    </visual>
    <collision>
      <origin rpy="0 0 0" xyz="0 0 0"/>
      <geometry>
        <mesh filename="package://mini_pupper_description/meshes/lb3.STL"/>
      </geometry>
    </collision>
  </link>
  <joint name="lb2_lb3" type="revolute">
    <origin rpy="0 0 0" xyz="0 0.00475 -0.05"/>
    <parent link="lb2"/>
    <child link="lb3"/>
    <axis xyz="0 1 0"/>
    <limit effort="5" lower="-3.14" upper="3.14" velocity="1.5"/>
  </joint>
  <link name="lbfoot">
    <inertial>
      <origin rpy="0 0 0" xyz="0.000424477269554052 -5.00018155106391E-05 0.000743181675762469"/>
      <mass value="0.0625"/>
      <inertia ixx="3.8885264656477E-08" ixy="3.60583012801976E-14" ixz="-2.99983098577426E-09" iyy="5.81684749230999E-08" iyz="1.31966997327651E-14" izz="2.7893076025217E-08"/>
    </inertial>
    <visual>
      <origin rpy="0 0 0" xyz="0 0 0"/>
      <geometry>
        <mesh filename="package://mini_pupper_description/meshes/lbfoot.STL"/>
      </geometry>
      <material name="">
        <color rgba="0.2 0.2 0.2 1"/>
      </material>
    </visual>
    <collision>
      <origin rpy="0 0 0" xyz="0 0 0"/>
      <geometry>
        <mesh filename="package://mini_pupper_description/meshes/lbfoot.STL"/>
      </geometry>
    </collision>
  </link>
  <joint name="lb3_foot" type="fixed">
    <origin rpy="0 0 0" xyz="0 0 -0.056"/>
    <parent link="lb3"/>
    <child link="lbfoot"/>
    <axis xyz="0 0 0"/>
  </joint>
  <link name="rb1">
    <inertial>
      <origin rpy="0 0 0" xyz="0.00541706873953746 -0.00276212057731962 0.00645819913656822"/>
      <mass value="0.25"/>
      <inertia ixx="2.2041347583079E-06" ixy="1.21330026226012E-08" ixz="-9.24417396767407E-09" iyy="3.50716356932592E-06" iyz="4.41858294139476E-09" izz="3.24535065112903E-06"/>
    </inertial>
    <visual>
      <origin rpy="0 0 0" xyz="0 0 0"/>
      <geometry>
        <mesh filename="package://mini_pupper_description/meshes/rb1.STL"/>
      </geometry>
      <material name="">
        <color rgba="0.2 0.2 0.2 1"/>
      </material>
    </visual>
    <collision>
      <origin rpy="0 0 0" xyz="0 0 0"/>
      <geometry>
        <mesh filename="package://mini_pupper_description/meshes/rb1.STL"/>
      </geometry>
    </collision>
  </link>
  <joint name="base_rb1" type="revolute">
    <origin rpy="0 0 0" xyz="-0.05886 -0.0235 0.0171"/>
    <parent link="base_link"/>
    <child link="rb1"/>
    <axis xyz="1 0 0"/>
    <limit effort="5" lower="-3.14" upper="3.14" velocity="1.5"/>
  </joint>
  <link name="rpb1">
    <inertial>
      <origin rpy="0 0 0" xyz="0.00874955403415308 0.00579637837903882 -0.00450693399320118"/>
      <mass value="0.005"/>
      <inertia ixx="8.18135114571351E-07" ixy="-8.78629613826186E-08" ixz="-3.80902795457312E-08" iyy="1.0153434226263E-06" iyz="-7.21698953092885E-08" izz="5.74767755618965E-07"/>
    </inertial>
    <visual>
      <origin rpy="0 0 0" xyz="0 0 0"/>
      <geometry>
        <mesh filename="package://mini_pupper_description/meshes/rpb1.STL"/>
      </geometry>
      <material name="">
        <color rgba="1 1 0 1"/>
      </material>
    </visual>
    <collision>
      <origin rpy="0 0 0" xyz="0 0 0"/>
      <geometry>
        <mesh filename="package://mini_pupper_description/meshes/rpb1.STL"/>
      </geometry>
    </collision>
  </link>
  <joint name="rb1_plate" type="fixed">
    <origin rpy="0 0 0" xyz="0.0107578315199995 -0.0307000000000005 0.0129999999999966"/>
    <parent link="rb1"/>
    <child link="rpb1"/>
    <axis xyz="0 0 0"/>
  </joint>
  <link name="rb2">
    <inertial>
      <origin rpy="0 0 0" xyz="-2.35922392732846E-16 0.00101365780342582 -0.0182607957244286"/>
      <mass value="0.125"/>
      <inertia ixx="2.56149742521738E-07" ixy="4.58825592822502E-24" ixz="-1.29829794647633E-21" iyy="2.61721029733561E-07" iyz="-1.56691297770442E-10" izz="6.97328365560507E-09"/>
    </inertial>
    <visual>
      <origin rpy="0 0 0" xyz="0 0 0"/>
      <geometry>
        <mesh filename="package://mini_pupper_description/meshes/rb2.STL"/>
      </geometry>
      <material name="">
        <color rgba="0.2 0.2 0.2 1"/>
      </material>
    </visual>
    <collision>
      <origin rpy="0 0 0" xyz="0 0 0"/>
      <geometry>
        <mesh filename="package://mini_pupper_description/meshes/rb2.STL"/>
      </geometry>
    </collision>
  </link>
  <joint name="rb1_rb2" type="revolute">
    <origin rpy="0 0 0" xyz="-4E-05 -0.0197 0"/>
    <parent link="rb1"/>
    <child link="rb2"/>
    <axis xyz="0 1 0"/>
    <limit effort="5" lower="-3.14" upper="3.14" velocity="1.5"/>
  </joint>
  <link name="rpb2">
    <inertial>
      <origin rpy="0 0 0" xyz="-0.002226106575326 0.00156905803495637 0.034086268557402"/>
      <mass value="0.005"/>
      <inertia ixx="9.31223932833863E-07" ixy="-6.03482748767292E-09" ixz="2.8522700467156E-08" iyy="1.03508297458339E-06" iyz="2.34659787841777E-08" izz="1.23911464668974E-07"/>
    </inertial>
    <visual>
      <origin rpy="0 0 0" xyz="0 0 0"/>
      <geometry>
        <mesh filename="package://mini_pupper_description/meshes/rpb2.STL"/>
      </geometry>
      <material name="">
        <color rgba="1 1 0 1"/>
      </material>
    </visual>
    <collision>
      <origin rpy="0 0 0" xyz="0 0 0"/>
      <geometry>
        <mesh filename="package://mini_pupper_description/meshes/rpb2.STL"/>
      </geometry>
    </collision>
  </link>
  <joint name="rb2_plate" type="fixed">
    <origin rpy="0 0 0" xyz="0 -0.0099999999999994 -0.0500000000000005"/>
    <parent link="rb2"/>
    <child link="rpb2"/>
    <axis xyz="0 0 0"/>
  </joint>
  <link name="rb3">
    <inertial>
      <origin rpy="0 0 0" xyz="0.000237267386725477 0.000198312811274914 -0.0165356596906083"/>
      <mass value="0.0625"/>
      <inertia ixx="3.17108534392357E-07" ixy="-5.35428361452917E-15" ixz="6.63472696394029E-09" iyy="3.19154628307937E-07" iyz="-1.62028942327462E-14" izz="2.63314870485568E-09"/>
    </inertial>
    <visual>
      <origin rpy="0 0 0" xyz="0 0 0"/>
      <geometry>
        <mesh filename="package://mini_pupper_description/meshes/rb3.STL"/>
      </geometry>
      <material name="">
        <color rgba="0.2 0.2 0.2 1"/>
      </material>
    </visual>
    <collision>
      <origin rpy="0 0 0" xyz="0 0 0"/>
      <geometry>
        <mesh filename="package://mini_pupper_description/meshes/rb3.STL"/>
      </geometry>
    </collision>
  </link>
  <joint name="rb2_rb3" type="revolute">
    <origin rpy="0 0 0" xyz="0 -0.00475 -0.05"/>
    <parent link="rb2"/>
    <child link="rb3"/>
    <axis xyz="0 1 0"/>
    <limit effort="5" lower="-3.14" upper="3.14" velocity="1.5"/>
  </joint>
  <link name="rbfoot">
    <inertial>
      <origin rpy="0 0 0" xyz="0.000424477269553421 4.99981844908973E-05 0.000743181675762136"/>
      <mass value="0.0625"/>
      <inertia ixx="3.88852646564768E-08" ixy="3.60583012702203E-14" ixz="-2.99983098577417E-09" iyy="5.81684749230997E-08" iyz="1.31966997511807E-14" izz="2.78930760252171E-08"/>
    </inertial>
    <visual>
      <origin rpy="0 0 0" xyz="0 0 0"/>
      <geometry>
        <mesh filename="package://mini_pupper_description/meshes/rbfoot.STL"/>
      </geometry>
      <material name="">
        <color rgba="0.2 0.2 0.2 1"/>
      </material>
    </visual>
    <collision>
      <origin rpy="0 0 0" xyz="0 0 0"/>
      <geometry>
        <mesh filename="package://mini_pupper_description/meshes/rbfoot.STL"/>
      </geometry>
    </collision>
  </link>
  <joint name="rb3_foot" type="fixed">
    <origin rpy="0 0 0" xyz="0 0 -0.056"/>
    <parent link="rb3"/>
    <child link="rbfoot"/>
    <axis xyz="0 0 0"/>
  </joint>
  <transmission name="base_lf1_trans">
    <type>transmission_interface/SimpleTransmission</type>
    <joint name="base_lf1">
      <hardwareInterface>hardware_interface/EffortJointInterface</hardwareInterface>
    </joint>
    <actuator name="base_lf1_motor">
      <hardwareInterface>hardware_interface/EffortJointInterface</hardwareInterface>
      <mechanicalReduction>1</mechanicalReduction>
    </actuator>
  </transmission>
  <transmission name="lf1_lf2_trans">
    <type>transmission_interface/SimpleTransmission</type>
    <joint name="lf1_lf2">
      <hardwareInterface>hardware_interface/EffortJointInterface</hardwareInterface>
    </joint>
    <actuator name="lf1_lf2_motor">
      <hardwareInterface>hardware_interface/EffortJointInterface</hardwareInterface>
      <mechanicalReduction>1</mechanicalReduction>
    </actuator>
  </transmission>
  <transmission name="lf2_lf3_trans">
    <type>transmission_interface/SimpleTransmission</type>
    <joint name="lf2_lf3">
      <hardwareInterface>hardware_interface/EffortJointInterface</hardwareInterface>
    </joint>
    <actuator name="lf2_lf3_motor">
      <hardwareInterface>hardware_interface/EffortJointInterface</hardwareInterface>
      <mechanicalReduction>1</mechanicalReduction>
    </actuator>
  </transmission>
  <transmission name="base_rf1_trans">
    <type>transmission_interface/SimpleTransmission</type>
    <joint name="base_rf1">
      <hardwareInterface>hardware_interface/EffortJointInterface</hardwareInterface>
    </joint>
    <actuator name="base_rf1_motor">
      <hardwareInterface>hardware_interface/EffortJointInterface</hardwareInterface>
      <mechanicalReduction>1</mechanicalReduction>
    </actuator>
  </transmission>
  <transmission name="rf1_rf2_trans">
    <type>transmission_interface/SimpleTransmission</type>
    <joint name="rf1_rf2">
      <hardwareInterface>hardware_interface/EffortJointInterface</hardwareInterface>
    </joint>
    <actuator name="rf1_rf2_motor">
      <hardwareInterface>hardware_interface/EffortJointInterface</hardwareInterface>
      <mechanicalReduction>1</mechanicalReduction>
    </actuator>
  </transmission>
  <transmission name="rf2_rf3_trans">
    <type>transmission_interface/SimpleTransmission</type>
    <joint name="rf2_rf3">
      <hardwareInterface>hardware_interface/EffortJointInterface</hardwareInterface>
    </joint>
    <actuator name="rf2_rf3_motor">
      <hardwareInterface>hardware_interface/EffortJointInterface</hardwareInterface>
      <mechanicalReduction>1</mechanicalReduction>
    </actuator>
  </transmission>
  <transmission name="base_lb1_trans">
    <type>transmission_interface/SimpleTransmission</type>
    <joint name="base_lb1">
      <hardwareInterface>hardware_interface/EffortJointInterface</hardwareInterface>
    </joint>
    <actuator name="base_lb1_motor">
      <hardwareInterface>hardware_interface/EffortJointInterface</hardwareInterface>
      <mechanicalReduction>1</mechanicalReduction>
    </actuator>
  </transmission>
  <transmission name="lb1_lb2_trans">
    <type>transmission_interface/SimpleTransmission</type>
    <joint name="lb1_lb2">
      <hardwareInterface>hardware_interface/EffortJointInterface</hardwareInterface>
    </joint>
    <actuator name="lb1_lb2_motor">
      <hardwareInterface>hardware_interface/EffortJointInterface</hardwareInterface>
      <mechanicalReduction>1</mechanicalReduction>
    </actuator>
  </transmission>
  <transmission name="lb2_lb3_trans">
    <type>transmission_interface/SimpleTransmission</type>
    <joint name="lb2_lb3">
      <hardwareInterface>hardware_interface/EffortJointInterface</hardwareInterface>
    </joint>
    <actuator name="lb2_lb3_motor">
      <hardwareInterface>hardware_interface/EffortJointInterface</hardwareInterface>
      <mechanicalReduction>1</mechanicalReduction>
    </actuator>
  </transmission>
  <transmission name="base_rb1_trans">
    <type>transmission_interface/SimpleTransmission</type>
    <joint name="base_rb1">
      <hardwareInterface>hardware_interface/EffortJointInterface</hardwareInterface>
    </joint>
    <actuator name="base_rb1_motor">
      <hardwareInterface>hardware_interface/EffortJointInterface</hardwareInterface>
      <mechanicalReduction>1</mechanicalReduction>
    </actuator>
  </transmission>
  <transmission name="rb1_rb2_trans">
    <type>transmission_interface/SimpleTransmission</type>
    <joint name="rb1_rb2">
      <hardwareInterface>hardware_interface/EffortJointInterface</hardwareInterface>
    </joint>
    <actuator name="rb1_rb2_motor">
      <hardwareInterface>hardware_interface/EffortJointInterface</hardwareInterface>
      <mechanicalReduction>1</mechanicalReduction>
    </actuator>
  </transmission>
  <transmission name="rb2_rb3_trans">
    <type>transmission_interface/SimpleTransmission</type>
    <joint name="rb2_rb3">
      <hardwareInterface>hardware_interface/EffortJointInterface</hardwareInterface>
    </joint>
    <actuator name="rb2_rb3_motor">
      <hardwareInterface>hardware_interface/EffortJointInterface</hardwareInterface>
      <mechanicalReduction>1</mechanicalReduction>
    </actuator>
  </transmission>
  <!-- coloring Gazebo model -->
  <gazebo reference="base_link">
    <material>Gazebo/FlatBlack</material>
  </gazebo>
  <gazebo reference="yellow_plate">
    <material>Gazebo/Yellow</material>
  </gazebo>
  <gazebo reference="lidar">
    <material>Gazebo/FlatBlack</material>
  </gazebo>
  <gazebo reference="lf1">
    <kp>1000000.0</kp>
    <kd>1.0</kd>
    <mu1>0.8</mu1>
    <mu2>0.8</mu2>
    <maxVel>0.0</maxVel>
    <minDepth>0.001</minDepth>
    <material>Gazebo/FlatBlack</material>
  </gazebo>
  <gazebo reference="lpf1">
    <material>Gazebo/Yellow</material>
  </gazebo>
  <gazebo reference="lf2">
    <kp>1000000.0</kp>
    <kd>1.0</kd>
    <mu1>0.8</mu1>
    <mu2>0.8</mu2>
    <maxVel>0.0</maxVel>
    <minDepth>0.001</minDepth>
    <material>Gazebo/FlatBlack</material>
  </gazebo>
  <gazebo reference="lpf2">
    <material>Gazebo/Yellow</material>
  </gazebo>
  <gazebo reference="lf3">
    <kp>1000000.0</kp>
    <kd>1.0</kd>
    <mu1>0.8</mu1>
    <mu2>0.8</mu2>
    <maxVel>0.0</maxVel>
    <minDepth>0.001</minDepth>
    <material>Gazebo/FlatBlack</material>
  </gazebo>
  <gazebo reference="lffoot">
    <kp>1000000.0</kp>
    <kd>1.0</kd>
    <mu1>0.8</mu1>
    <mu2>0.8</mu2>
    <maxVel>0.0</maxVel>
    <minDepth>0.001</minDepth>
    <material>Gazebo/FlatBlack</material>
  </gazebo>
  <gazebo reference="rf1">
    <kp>1000000.0</kp>
    <kd>1.0</kd>
    <mu1>0.8</mu1>
    <mu2>0.8</mu2>
    <maxVel>0.0</maxVel>
    <minDepth>0.001</minDepth>
    <material>Gazebo/FlatBlack</material>
  </gazebo>
  <gazebo reference="rpf1">
    <material>Gazebo/Yellow</material>
  </gazebo>
  <gazebo reference="rf2">
    <kp>1000000.0</kp>
    <kd>1.0</kd>
    <mu1>0.8</mu1>
    <mu2>0.8</mu2>
    <maxVel>0.0</maxVel>
    <minDepth>0.001</minDepth>
    <material>Gazebo/FlatBlack</material>
  </gazebo>
  <gazebo reference="rpf2">
    <material>Gazebo/Yellow</material>
  </gazebo>
  <gazebo reference="rf3">
    <kp>1000000.0</kp>
    <kd>1.0</kd>
    <mu1>0.8</mu1>
    <mu2>0.8</mu2>
    <maxVel>0.0</maxVel>
    <minDepth>0.001</minDepth>
    <material>Gazebo/FlatBlack</material>
  </gazebo>
  <gazebo reference="rffoot">
    <kp>1000000.0</kp>
    <kd>1.0</kd>
    <mu1>0.8</mu1>
    <mu2>0.8</mu2>
    <maxVel>0.0</maxVel>
    <minDepth>0.001</minDepth>
    <material>Gazebo/FlatBlack</material>
  </gazebo>
  <gazebo reference="lb1">
    <kp>1000000.0</kp>
    <kd>1.0</kd>
    <mu1>0.8</mu1>
    <mu2>0.8</mu2>
    <maxVel>0.0</maxVel>
    <minDepth>0.001</minDepth>
    <material>Gazebo/FlatBlack</material>
  </gazebo>
  <gazebo reference="lpb1">
    <material>Gazebo/Yellow</material>
  </gazebo>
  <gazebo reference="lb2">
    <kp>1000000.0</kp>
    <kd>1.0</kd>
    <mu1>0.8</mu1>
    <mu2>0.8</mu2>
    <maxVel>0.0</maxVel>
    <minDepth>0.001</minDepth>
    <material>Gazebo/FlatBlack</material>
  </gazebo>
  <gazebo reference="lpb2">
    <material>Gazebo/Yellow</material>
  </gazebo>
  <gazebo reference="lb3">
    <kp>1000000.0</kp>
    <kd>1.0</kd>
    <mu1>0.8</mu1>
    <mu2>0.8</mu2>
    <maxVel>0.0</maxVel>
    <minDepth>0.001</minDepth>
    <material>Gazebo/FlatBlack</material>
  </gazebo>
  <gazebo reference="lbfoot">
    <kp>1000000.0</kp>
    <kd>1.0</kd>
    <mu1>0.8</mu1>
    <mu2>0.8</mu2>
    <maxVel>0.0</maxVel>
    <minDepth>0.001</minDepth>
    <material>Gazebo/FlatBlack</material>
  </gazebo>
  <gazebo reference="rb1">
    <kp>1000000.0</kp>
    <kd>1.0</kd>
    <mu1>0.8</mu1>
    <mu2>0.8</mu2>
    <maxVel>0.0</maxVel>
    <minDepth>0.001</minDepth>
    <material>Gazebo/FlatBlack</material>
  </gazebo>
  <gazebo reference="rpb1">
    <material>Gazebo/Yellow</material>
  </gazebo>
  <gazebo reference="rb2">
    <kp>1000000.0</kp>
    <kd>1.0</kd>
    <mu1>0.8</mu1>
    <mu2>0.8</mu2>
    <maxVel>0.0</maxVel>
    <minDepth>0.001</minDepth>
    <material>Gazebo/FlatBlack</material>
  </gazebo>
  <gazebo reference="rpb2">
    <material>Gazebo/Yellow</material>
  </gazebo>
  <gazebo reference="rb3">
    <kp>1000000.0</kp>
    <kd>1.0</kd>
    <mu1>0.8</mu1>
    <mu2>0.8</mu2>
    <maxVel>0.0</maxVel>
    <minDepth>0.001</minDepth>
    <material>Gazebo/FlatBlack</material>
  </gazebo>
  <gazebo reference="rbfoot">
    <kp>1000000.0</kp>
    <kd>1.0</kd>
    <mu1>0.8</mu1>
    <mu2>0.8</mu2>
    <maxVel>0.0</maxVel>
    <minDepth>0.001</minDepth>
    <material>Gazebo/FlatBlack</material>
  </gazebo>
  <gazebo reference="lidar">
    <sensor name="ld06" type="ray">
      <always_on>true</always_on>
      <update_rate>30</update_rate>
      <pose>0 0 0 0 0 0</pose>
      <visualize>false</visualize>
      <ray>
        <scan>
          <horizontal>
            <samples>1040</samples>
            <resolution>1</resolution>
            <min_angle>-3.14</min_angle>
            <max_angle>3.14</max_angle>
          </horizontal>
        </scan>
        <range>
          <min>0.02</min>
          <max>12.0</max>
          <resolution>0.01</resolution>
        </range>
        <noise>
          <type>gaussian</type>
          <mean>0.0</mean>
          <stddev>0.004</stddev>
        </noise>
      </ray>
      <plugin filename="libgazebo_ros_laser.so" name="gazebo_ros_hokuyo_controller">
        <topicName>scan</topicName>
        <frameName>lidar</frameName>
      </plugin>
    </sensor>
  </gazebo>
  <gazebo>
    <plugin filename="libgazebo_ros_p3d.so" name="p3d_base_controller">
      <alwaysOn>true</alwaysOn>
      <updateRate>10.0</updateRate>
      <bodyName>base_link</bodyName>
      <topicName>odom/ground_truth</topicName>
      <gaussianNoise>0.01</gaussianNoise>
      <frameName>world</frameName>
      <xyzOffsets>0 0 0</xyzOffsets>
      <rpyOffsets>0 0 0</rpyOffsets>
    </plugin>
  </gazebo>
  <gazebo>
    <plugin filename="libgazebo_ros_control.so" name="gazebo_ros_control">
      <legacyModeNS>true</legacyModeNS>
    </plugin>
  </gazebo>
  <gazebo>
    <plugin filename="libhector_gazebo_ros_imu.so" name="imu_controller">
      <updateRate>50.0</updateRate>
      <bodyName>imu_link</bodyName>
      <topicName>imu/data</topicName>
      <accelDrift>0.005 0.005 0.005</accelDrift>
      <accelGaussianNoise>0.005 0.005 0.005</accelGaussianNoise>
      <rateDrift>0.005 0.005 0.005 </rateDrift>
      <rateGaussianNoise>0.005 0.005 0.005 </rateGaussianNoise>
      <headingDrift>0.005</headingDrift>
      <headingGaussianNoise>0.005</headingGaussianNoise>
    </plugin>
  </gazebo>
  <link name="imu_link">
    <inertial>
      <mass value="0.001"/>
      <origin rpy="0 0 0" xyz="0 0 0"/>
      <inertia ixx="1e-09" ixy="0.0" ixz="0.0" iyy="1e-09" iyz="0.0" izz="1e-09"/>
    </inertial>
  </link>
  <joint name="imu_joint" type="fixed">
    <parent link="base_link"/>
    <child link="imu_link"/>
  </joint>
  <!-- camera body, with origin at bottom screw mount -->
  <joint name="camera_joint" type="fixed">
    <origin rpy="0 0 0" xyz="0.08 0.0 0.07"/>
    <parent link="base_link"/>
    <child link="camera_bottom_screw_frame"/>
  </joint>
  <link name="camera_bottom_screw_frame"/>
  <joint name="camera_link_joint" type="fixed">
    <origin rpy="0 0 0" xyz="0.010600000000000002 0.0175 0.0125"/>
    <parent link="camera_bottom_screw_frame"/>
    <child link="camera_link"/>
  </joint>
  <link name="camera_link">
    <visual>
      <!-- the mesh origin is at front plate in between the two infrared camera axes -->
      <origin rpy="1.5707963267948966 0 1.5707963267948966" xyz="0.0043 -0.0175 0"/>
      <geometry>
        <mesh filename="package://mini_pupper_description/meshes/d435.dae"/>
      </geometry>
    </visual>
    <collision>
      <origin rpy="0 0 0" xyz="0 -0.0175 0"/>
      <geometry>
        <box size="0.02505 0.09 0.025"/>
      </geometry>
    </collision>
    <inertial>
      <!-- The following are not reliable values, and should not be used for modeling -->
      <mass value="0.072"/>
      <origin xyz="0 0 0"/>
      <inertia ixx="0.003881243" ixy="0.0" ixz="0.0" iyy="0.000498940" iyz="0.0" izz="0.003879257"/>
    </inertial>
  </link>
  <!-- camera depth joints and links -->
  <joint name="camera_depth_joint" type="fixed">
    <origin rpy="0 0 0" xyz="0 0 0"/>
    <parent link="camera_link"/>
    <child link="camera_depth_frame"/>
  </joint>
  <link name="camera_depth_frame"/>
  <joint name="camera_depth_optical_joint" type="fixed">
    <origin rpy="-1.5707963267948966 0 -1.5707963267948966" xyz="0 0 0"/>
    <parent link="camera_depth_frame"/>
    <child link="camera_depth_optical_frame"/>
  </joint>
  <link name="camera_depth_optical_frame"/>
  <!-- camera left IR joints and links -->
  <joint name="camera_infra1_joint" type="fixed">
    <origin rpy="0 0 0" xyz="0 0.0 0"/>
    <parent link="camera_link"/>
    <child link="camera_infra1_frame"/>
  </joint>
  <link name="camera_infra1_frame"/>
  <joint name="camera_infra1_optical_joint" type="fixed">
    <origin rpy="-1.5707963267948966 0 -1.5707963267948966" xyz="0 0 0"/>
    <parent link="camera_infra1_frame"/>
    <child link="camera_infra1_optical_frame"/>
  </joint>
  <link name="camera_infra1_optical_frame"/>
  <!-- camera right IR joints and links -->
  <joint name="camera_infra2_joint" type="fixed">
    <origin rpy="0 0 0" xyz="0 -0.05 0"/>
    <parent link="camera_link"/>
    <child link="camera_infra2_frame"/>
  </joint>
  <link name="camera_infra2_frame"/>
  <joint name="camera_infra2_optical_joint" type="fixed">
    <origin rpy="-1.5707963267948966 0 -1.5707963267948966" xyz="0 0 0"/>
    <parent link="camera_infra2_frame"/>
    <child link="camera_infra2_optical_frame"/>
  </joint>
  <link name="camera_infra2_optical_frame"/>
  <!-- camera color joints and links -->
  <joint name="camera_color_joint" type="fixed">
    <origin rpy="0 0 0" xyz="0 0.015 0"/>
    <parent link="camera_link"/>
    <child link="camera_color_frame"/>
  </joint>
  <link name="camera_color_frame"/>
  <joint name="camera_color_optical_joint" type="fixed">
    <origin rpy="-1.5707963267948966 0 -1.5707963267948966" xyz="0 0 0"/>
    <parent link="camera_color_frame"/>
    <child link="camera_color_optical_frame"/>
  </joint>
  <link name="camera_color_optical_frame"/>
  <gazebo reference="camera_depth_frame">
    <sensor name="camera" type="depth">
      <update_rate>20</update_rate>
      <camera>
        <horizontal_fov>1.09606677025</horizontal_fov>
        <image>
          <format>R8G8B8</format>
          <width>640</width>
          <height>480</height>
        </image>
        <clip>
          <near>0.5</near>
          <far>9</far>
        </clip>
      </camera>
      <plugin filename="libgazebo_ros_openni_kinect.so" name="camera_camera_controller">
        <imageTopicName>/camera/color/image_raw</imageTopicName>
        <cameraInfoTopicName>/camera/color/camera_info</cameraInfoTopicName>
        <depthImageTopicName>/camera/aligned_depth_to_color/image_raw</depthImageTopicName>
        <depthImageCameraInfoTopicName>/camera/depth/camera_info</depthImageCameraInfoTopicName>
        <pointCloudTopicName>/camera/depth/color/points</pointCloudTopicName>
        <frameName>camera_depth_optical_frame</frameName>
      </plugin>
    </sensor>
  </gazebo>
</robot>
