<?xml version="1.0"?>
<robot name="mini-pupper" xmlns:xacro="http://ros.org/wiki/xacro">
  <xacro:include filename="$(find mini_pupper_description)/urdf/_d435.urdf.xacro" />
  <link name="base_link">
    <visual>
      <origin
        xyz="0 0 0"
        rpy="0 0 0" />
      <geometry>
        <mesh
          filename="file://$(find mini_pupper_description)/meshes/base_link.STL" />
      </geometry>
      <material
        name="">
        <color
          rgba="0.2 0.2 0.2 1" />
      </material>
    </visual>
    <collision>
      <origin
        xyz="0 0 0"
        rpy="0 0 0" />
      <geometry>
        <mesh
          filename="file://$(find mini_pupper_description)/meshes/base_link.STL" />
      </geometry>
    </collision>
  </link>
  <link name="base_inertia">    
    <inertial>
      <origin
        xyz="0.00660426498064391 8.26976427410632E-06 0.0200623332889016"
        rpy="0 0 0" />
      <mass
        value="0.07" />
      <inertia
        ixx="3.3463402501291E-05"
        ixy="-2.80059099694232E-07"
        ixz="1.59673474113324E-08"
        iyy="9.73631866262367E-05"
        iyz="2.90091309171363E-09"
        izz="0.00010929561287651" />
    </inertial>
  </link> 
  <joint name="base_link_to_base_inertia" type="fixed">    
      <parent link="base_link"/>    
      <child link="base_inertia"/>    
      <origin rpy="0 0 0" xyz="0 0 0"/>  
  </joint>  
  <link
    name="yellow_plate">
    <inertial>
      <origin
        xyz="-0.0265979628467293 0.00100265856976752 -0.0205696864633185"
        rpy="0 0 0" />
      <mass
        value="0.03" />
      <inertia
        ixx="2.63040079082852E-05"
        ixy="-5.56245753822899E-07"
        ixz="-1.84870621911762E-06"
        iyy="5.64225933806734E-05"
        iyz="6.34788357961111E-09"
        izz="7.28861115131965E-05" />
    </inertial>
    <visual>
      <origin
        xyz="0 0 0"
        rpy="0 0 0" />
      <geometry>
        <mesh
          filename="file://$(find mini_pupper_description)/meshes/yellow_plate.STL" />
      </geometry>
      <material
        name="">
        <color
          rgba="1 1 0 1" />
      </material>
    </visual>
    <collision>
      <origin
        xyz="0 0 0"
        rpy="0 0 0" />
      <geometry>
        <mesh
          filename="file://$(find mini_pupper_description)/meshes/yellow_plate.STL" />
      </geometry>
    </collision>
  </link>
  <joint
    name="base_yellowplate"
    type="fixed">
    <origin
      xyz="0.0556975724826061 -0.000166914683579864 0.0700000000000001"
      rpy="0 0 0" />
    <parent
      link="base_link" />
    <child
      link="yellow_plate" />
    <axis
      xyz="0 0 0" />
  </joint>
  <link
    name="lidar_link">
    <inertial>
      <origin
        xyz="1.56706411611127E-05 -5.16565672073303E-13 -0.0191835739440227"
        rpy="0 0 -1.57" />
      <mass
        value="0.0001" />
      <inertia
        ixx="8.74731426973985E-06"
        ixy="-6.66781590704156E-08"
        ixz="1.89196685410159E-11"
        iyy="8.70097486591694E-06"
        iyz="-1.13397577799603E-17"
        izz="9.98821295317784E-06" />
    </inertial>
    <visual>
      <origin
        xyz="0 0 0"
        rpy="0 0 -1.57" />
      <geometry>
        <mesh
          filename="file://$(find mini_pupper_description)/meshes/lidar.STL" />
      </geometry>
      <material
        name="">
        <color
          rgba="0.2 0.2 0.2 1" />
      </material>
    </visual>
    <collision>
      <origin
        xyz="0 0 0"
        rpy="0 0 -1.57" />
      <geometry>
        <mesh
          filename="file://$(find mini_pupper_description)/meshes/lidar.STL" />
      </geometry>
    </collision>
  </link>
  <joint
    name="base_lidar"
    type="fixed">
    <origin
      xyz="-0.070475 0.0001 0.08"
      rpy="0 0 1.57" />
    <parent
      link="base_link" />
    <child
      link="lidar_link" />
    <axis
      xyz="0 0 0" />
  </joint>
  <link
    name="lf1">
    <inertial>
      <origin
        xyz="0.00519546289834071 0.00279246570724686 0.0063718183283844"
        rpy="0 0 0" />
      <mass
        value="0.025" />
      <inertia
        ixx="2.16792829512222E-06"
        ixy="-6.02508577918412E-09"
        ixz="5.90505149164062E-08"
        iyy="3.44088340998371E-06"
        iyz="-1.92270764243995E-08"
        izz="3.1963969100223E-06" />
    </inertial>
    <visual>
      <origin
        xyz="0 0 0"
        rpy="0 0 0" />
      <geometry>
        <mesh
          filename="file://$(find mini_pupper_description)/meshes/lf1.STL" />
      </geometry>
      <material
        name="">
        <color
          rgba="0.2 0.2 0.2 1" />
      </material>
    </visual>
    <collision>
      <origin
        xyz="0 0 0"
        rpy="0 0 0" />
      <geometry>
        <mesh
          filename="file://$(find mini_pupper_description)/meshes/lf1.STL" />
      </geometry>
    </collision>
  </link>
  <joint
    name="base_lf1"
    type="revolute">
    <origin
      xyz="0.06014 0.0235 0.0171"
      rpy="0 0 0" />
    <parent
      link="base_link" />
    <child
      link="lf1" />
    <axis
      xyz="1 0 0" />
    <limit
      lower="-3.14"
      upper="3.14"
      effort="5"
      velocity="1.5" />
  </joint>
  <link
    name="lpf1">
    <inertial>
      <origin
        xyz="0.00874956145631699 -0.0057963784801828 -0.00450693686767675"
        rpy="0 0 0" />
      <mass
        value="0.0005" />
      <inertia
        ixx="8.1813456986579E-07"
        ixy="8.78628279607434E-08"
        ixz="-3.80902489021625E-08"
        iyy="1.01534357250605E-06"
        iyz="7.21698179094722E-08"
        izz="5.74768328209026E-07" />
    </inertial>
    <visual>
      <origin
        xyz="0 0 0"
        rpy="0 0 0" />
      <geometry>
        <mesh
          filename="file://$(find mini_pupper_description)/meshes/lpf1.STL" />
      </geometry>
      <material
        name="">
        <color
          rgba="1 1 0 1" />
      </material>
    </visual>
    <collision>
      <origin
        xyz="0 0 0"
        rpy="0 0 0" />
      <geometry>
        <mesh
          filename="file://$(find mini_pupper_description)/meshes/lpf1.STL" />
      </geometry>
    </collision>
  </link>
  <joint
    name="lf1_plate"
    type="fixed">
    <origin
      xyz="0.0107600000007337 0.0306999999992666 0.0130000000001585"
      rpy="0 0 0" />
    <parent
      link="lf1" />
    <child
      link="lpf1" />
    <axis
      xyz="0 0 0" />
  </joint>
  <link
    name="lf2">
    <inertial>
      <origin
        xyz="1.3988810110277E-14 -0.00101365780344401 -0.0182607957247316"
        rpy="0 0 0" />
      <mass
        value="0.0125" />
      <inertia
        ixx="2.56149742521739E-07"
        ixy="8.35373111913384E-24"
        ixz="-9.77082381851893E-23"
        iyy="2.61721029733561E-07"
        iyz="1.5669129777113E-10"
        izz="6.97328365560507E-09" />
    </inertial>
    <visual>
      <origin
        xyz="0 0 0"
        rpy="0 0 0" />
      <geometry>
        <mesh
          filename="file://$(find mini_pupper_description)/meshes/lf2.STL" />
      </geometry>
      <material
        name="">
        <color
          rgba="0.2 0.2 0.2 1" />
      </material>
    </visual>
    <collision>
      <origin
        xyz="0 0 0"
        rpy="0 0 0" />
      <geometry>
        <mesh
          filename="file://$(find mini_pupper_description)/meshes/lf2.STL" />
      </geometry>
    </collision>
  </link>
  <joint
    name="lf1_lf2"
    type="revolute">
    <origin
      xyz="-4E-05 0.0197 0"
      rpy="0 0 0" />
    <parent
      link="lf1" />
    <child
      link="lf2" />
    <axis
      xyz="0 1 0" />
    <limit
      lower="-3.14"
      upper="3.14"
      effort="5"
      velocity="1.5" />
  </joint>
  <link
    name="lpf2">
    <inertial>
      <origin
        xyz="-0.00217866290818425 -0.001566384405815 0.034099120119674"
        rpy="0 0 0" />
      <mass
        value="0.0005" />
      <inertia
        ixx="9.34196968596698E-07"
        ixy="5.95712897889122E-09"
        ixz="2.71831950266143E-08"
        iyy="1.03925284587874E-06"
        iyz="-2.35723407122805E-08"
        izz="1.25155524458103E-07" />
    </inertial>
    <visual>
      <origin
        xyz="0 0 0"
        rpy="0 0 0" />
      <geometry>
        <mesh
          filename="file://$(find mini_pupper_description)/meshes/lpf2.STL" />
      </geometry>
      <material
        name="">
        <color
          rgba="1 1 0 1" />
      </material>
    </visual>
    <collision>
      <origin
        xyz="0 0 0"
        rpy="0 0 0" />
      <geometry>
        <mesh
          filename="file://$(find mini_pupper_description)/meshes/lpf2.STL" />
      </geometry>
    </collision>
  </link>
  <joint
    name="lf2_plate"
    type="fixed">
    <origin
      xyz="0 0.00999999999998141 -0.0500000000003035"
      rpy="0 0 0" />
    <parent
      link="lf2" />
    <child
      link="lpf2" />
    <axis
      xyz="0 0 0" />
  </joint>
  <link
    name="lf3">
    <inertial>
      <origin
        xyz="0.000237268946264135 -0.000198312911218489 -0.016535656084904"
        rpy="0 0 0" />
      <mass
        value="0.00625" />
      <inertia
        ixx="3.17108530490043E-07"
        ixy="-8.19624096923979E-15"
        ixz="6.63472331942981E-09"
        iyy="3.19154628309319E-07"
        iyz="-1.49720639035527E-14"
        izz="2.63315261030515E-09" />
    </inertial>
    <visual>
      <origin
        xyz="0 0 0"
        rpy="0 0 0" />
      <geometry>
        <mesh
          filename="file://$(find mini_pupper_description)/meshes/lf3.STL" />
      </geometry>
      <material
        name="">
        <color
          rgba="0.2 0.2 0.2 1" />
      </material>
    </visual>
    <collision>
      <origin
        xyz="0 0 0"
        rpy="0 0 0" />
      <geometry>
        <mesh
          filename="file://$(find mini_pupper_description)/meshes/lf3.STL" />
      </geometry>
    </collision>
  </link>
  <joint
    name="lf2_lf3"
    type="revolute">
    <origin
      xyz="0 0.00475 -0.05"
      rpy="0 0 0" />
    <parent
      link="lf2" />
    <child
      link="lf3" />
    <axis
      xyz="0 1 0" />
    <limit
      lower="-3.14"
      upper="3.14"
      effort="5"
      velocity="1.5" />
  </joint>
  <link
    name="lffoot">
    <inertial>
      <origin
        xyz="0.000424477269554246 -1.81550998540336E-09 0.000743181675761886"
        rpy="0 0 0" />
      <mass
        value="0.00625" />
      <inertia
        ixx="3.88852646564769E-08"
        ixy="3.60583012427767E-14"
        ixz="-2.99983098577409E-09"
        iyy="5.81684749230997E-08"
        iyz="1.31966996419541E-14"
        izz="2.7893076025217E-08" />
    </inertial>
    <visual>
      <origin
        xyz="0 0 0"
        rpy="0 0 0" />
      <geometry>
        <mesh
          filename="file://$(find mini_pupper_description)/meshes/lffoot.STL" />
      </geometry>
      <material
        name="">
        <color
          rgba="0.2 0.2 0.2 1" />
      </material>
    </visual>
    <collision>
      <origin
        xyz="0 0 0"
        rpy="0 0 0" />
      <geometry>
        <mesh
          filename="file://$(find mini_pupper_description)/meshes/lffoot.STL" />
      </geometry>
    </collision>
  </link>
  <joint
    name="lf3_foot"
    type="fixed">
    <origin
      xyz="0 -4.9999999999939E-05 -0.056"
      rpy="0 0 0" />
    <parent
      link="lf3" />
    <child
      link="lffoot" />
    <axis
      xyz="0 0 0" />
  </joint>
  <link
    name="rf1">
    <inertial>
      <origin
        xyz="0.00519546371324378 -0.00279246587993302 0.00637181920913787"
        rpy="0 0 0" />
      <mass
        value="0.025" />
      <inertia
        ixx="2.16792855298178E-06"
        ixy="6.02507996345136E-09"
        ixz="5.90497387290611E-08"
        iyy="3.44088387908968E-06"
        iyz="1.9227066292514E-08"
        izz="3.19639712715432E-06" />
    </inertial>
    <visual>
      <origin
        xyz="0 0 0"
        rpy="0 0 0" />
      <geometry>
        <mesh
          filename="file://$(find mini_pupper_description)/meshes/rf1.STL" />
      </geometry>
      <material
        name="">
        <color
          rgba="0.2 0.2 0.2 1" />
      </material>
    </visual>
    <collision>
      <origin
        xyz="0 0 0"
        rpy="0 0 0" />
      <geometry>
        <mesh
          filename="file://$(find mini_pupper_description)/meshes/rf1.STL" />
      </geometry>
    </collision>
  </link>
  <joint
    name="base_rf1"
    type="revolute">
    <origin
      xyz="0.06014 -0.0235 0.0171"
      rpy="0 0 0" />
    <parent
      link="base_link" />
    <child
      link="rf1" />
    <axis
      xyz="1 0 0" />
    <limit
      lower="-3.14"
      upper="3.14"
      effort="5"
      velocity="1.5" />
  </joint>
  <link
    name="rpf1">
    <inertial>
      <origin
        xyz="0.00874955403415308 0.00579637837903884 -0.0045069339932012"
        rpy="0 0 0" />
      <mass
        value="0.0005" />
      <inertia
        ixx="8.18135114571354E-07"
        ixy="-8.78629613826191E-08"
        ixz="-3.80902795457312E-08"
        iyy="1.01534342262631E-06"
        iyz="-7.21698953092889E-08"
        izz="5.74767755618967E-07" />
    </inertial>
    <visual>
      <origin
        xyz="0 0 0"
        rpy="0 0 0" />
      <geometry>
        <mesh
          filename="file://$(find mini_pupper_description)/meshes/rpf1.STL" />
      </geometry>
      <material
        name="">
        <color
          rgba="1 1 0 1" />
      </material>
    </visual>
    <collision>
      <origin
        xyz="0 0 0"
        rpy="0 0 0" />
      <geometry>
        <mesh
          filename="file://$(find mini_pupper_description)/meshes/rpf1.STL" />
      </geometry>
    </collision>
  </link>
  <joint
    name="rf1_plate"
    type="fixed">
    <origin
      xyz="0.0107599999999999 -0.0306999999999999 0.013"
      rpy="0 0 0" />
    <parent
      link="rf1" />
    <child
      link="rpf1" />
    <axis
      xyz="0 0 0" />
  </joint>
  <link
    name="rf2">
    <inertial>
      <origin
        xyz="-9.71445146547012E-17 0.00101365780342547 -0.0182607957244276"
        rpy="0 0 0" />
      <mass
        value="0.0125" />
      <inertia
        ixx="2.56149742521738E-07"
        ixy="8.12572657898901E-24"
        ixz="1.8668027519541E-22"
        iyy="2.6172102973356E-07"
        iyz="-1.56691297771191E-10"
        izz="6.97328365560504E-09" />
    </inertial>
    <visual>
      <origin
        xyz="0 0 0"
        rpy="0 0 0" />
      <geometry>
        <mesh
          filename="file://$(find mini_pupper_description)/meshes/rf2.STL" />
      </geometry>
      <material
        name="">
        <color
          rgba="0.2 0.2 0.2 1" />
      </material>
    </visual>
    <collision>
      <origin
        xyz="0 0 0"
        rpy="0 0 0" />
      <geometry>
        <mesh
          filename="file://$(find mini_pupper_description)/meshes/rf2.STL" />
      </geometry>
    </collision>
  </link>
  <joint
    name="rf1_rf2"
    type="revolute">
    <origin
      xyz="-4E-05 -0.0197 0"
      rpy="0 0 0" />
    <parent
      link="rf1" />
    <child
      link="rf2" />
    <axis
      xyz="0 1 0" />
    <limit
      lower="-3.14"
      upper="3.14"
      effort="5"
      velocity="1.5" />
  </joint>
  <link
    name="rpf2">
    <inertial>
      <origin
        xyz="-0.00222610657532629 0.00156905803495648 0.0340862685574021"
        rpy="0 0 0" />
      <mass
        value="0.0005" />
      <inertia
        ixx="9.31223932833859E-07"
        ixy="-6.03482748767291E-09"
        ixz="2.85227004671628E-08"
        iyy="1.03508297458339E-06"
        iyz="2.34659787841745E-08"
        izz="1.23911464668974E-07" />
    </inertial>
    <visual>
      <origin
        xyz="0 0 0"
        rpy="0 0 0" />
      <geometry>
        <mesh
          filename="file://$(find mini_pupper_description)/meshes/rpf2.STL" />
      </geometry>
      <material
        name="">
        <color
          rgba="1 1 0 1" />
      </material>
    </visual>
    <collision>
      <origin
        xyz="0 0 0"
        rpy="0 0 0" />
      <geometry>
        <mesh
          filename="file://$(find mini_pupper_description)/meshes/rpf2.STL" />
      </geometry>
    </collision>
  </link>
  <joint
    name="rf2_plate"
    type="fixed">
    <origin
      xyz="0 -0.00999999999999994 -0.0499999999999996"
      rpy="0 0 0" />
    <parent
      link="rf2" />
    <child
      link="rpf2" />
    <axis
      xyz="0 0 0" />
  </joint>
  <link
    name="rf3">
    <inertial>
      <origin
        xyz="0.000237280669710932 0.000198312911218648 -0.0165356564440727"
        rpy="0 0 0" />
      <mass
        value="0.00625" />
      <inertia
        ixx="3.17108530808881E-07"
        ixy="-7.26391171726489E-15"
        ixz="6.63472855289727E-09"
        iyy="3.19154628309318E-07"
        iyz="1.5448111353928E-14"
        izz="2.63315229146555E-09" />
    </inertial>
    <visual>
      <origin
        xyz="0 0 0"
        rpy="0 0 0" />
      <geometry>
        <mesh
          filename="file://$(find mini_pupper_description)/meshes/rf3.STL" />
      </geometry>
      <material
        name="">
        <color
          rgba="0.2 0.2 0.2 1" />
      </material>
    </visual>
    <collision>
      <origin
        xyz="0 0 0"
        rpy="0 0 0" />
      <geometry>
        <mesh
          filename="file://$(find mini_pupper_description)/meshes/rf3.STL" />
      </geometry>
    </collision>
  </link>
  <joint
    name="rf2_rf3"
    type="revolute">
    <origin
      xyz="0 -0.00475 -0.05"
      rpy="0 0 0" />
    <parent
      link="rf2" />
    <child
      link="rf3" />
    <axis
      xyz="0 1 0" />
    <limit
      lower="-3.14"
      upper="3.14"
      effort="5"
      velocity="1.5" />
  </joint>
  <link
    name="rffoot">
    <inertial>
      <origin
        xyz="0.000424477269554566 4.99981844905087E-05 0.000743181675762233"
        rpy="0 0 0" />
      <mass
        value="0.00625" />
      <inertia
        ixx="3.88852646564774E-08"
        ixy="3.60583012797131E-14"
        ixz="-2.99983098577438E-09"
        iyy="5.81684749231005E-08"
        iyz="1.31966996988911E-14"
        izz="2.78930760252171E-08" />
    </inertial>
    <visual>
      <origin
        xyz="0 0 0"
        rpy="0 0 0" />
      <geometry>
        <mesh
          filename="file://$(find mini_pupper_description)/meshes/rffoot.STL" />
      </geometry>
      <material
        name="">
        <color
          rgba="0.2 0.2 0.2 1" />
      </material>
    </visual>
    <collision>
      <origin
        xyz="0 0 0"
        rpy="0 0 0" />
      <geometry>
        <mesh
          filename="file://$(find mini_pupper_description)/meshes/rffoot.STL" />
      </geometry>
    </collision>
  </link>
  <joint
    name="rf3_foot"
    type="fixed">
    <origin
      xyz="0 0 -0.056"
      rpy="0 0 0" />
    <parent
      link="rf3" />
    <child
      link="rffoot" />
    <axis
      xyz="0 0 0" />
  </joint>
  <link
    name="lb1">
    <inertial>
      <origin
        xyz="0.00541706873953783 0.00276212057731937 0.00645819913657113"
        rpy="0 0 0" />
      <mass
        value="0.025" />
      <inertia
        ixx="2.2041347583079E-06"
        ixy="-1.21330026225997E-08"
        ixz="-9.24364679790947E-09"
        iyy="3.50716356932593E-06"
        iyz="-4.41858294139363E-09"
        izz="3.24535065112903E-06" />
    </inertial>
    <visual>
      <origin
        xyz="0 0 0"
        rpy="0 0 0" />
      <geometry>
        <mesh
          filename="file://$(find mini_pupper_description)/meshes/lb1.STL" />
      </geometry>
      <material
        name="">
        <color
          rgba="0.2 0.2 0.2 1" />
      </material>
    </visual>
    <collision>
      <origin
        xyz="0 0 0"
        rpy="0 0 0" />
      <geometry>
        <mesh
          filename="file://$(find mini_pupper_description)/meshes/lb1.STL" />
      </geometry>
    </collision>
  </link>
  <joint
    name="base_lb1"
    type="revolute">
    <origin
      xyz="-0.05886 0.0235 0.0171"
      rpy="0 0 0" />
    <parent
      link="base_link" />
    <child
      link="lb1" />
    <axis
      xyz="1 0 0" />
    <limit
      lower="-3.14"
      upper="3.14"
      effort="5"
      velocity="1.5" />
  </joint>
  <link
    name="lpb1">
    <inertial>
      <origin
        xyz="0.00874956145631699 -0.00579637848018278 -0.00450693686767676"
        rpy="0 0 0" />
      <mass
        value="0.0005" />
      <inertia
        ixx="8.18134569865789E-07"
        ixy="8.78628279607436E-08"
        ixz="-3.80902489021627E-08"
        iyy="1.01534357250605E-06"
        iyz="7.21698179094726E-08"
        izz="5.74768328209026E-07" />
    </inertial>
    <visual>
      <origin
        xyz="0 0 0"
        rpy="0 0 0" />
      <geometry>
        <mesh
          filename="file://$(find mini_pupper_description)/meshes/lpb1.STL" />
      </geometry>
      <material
        name="">
        <color
          rgba="1 1 0 1" />
      </material>
    </visual>
    <collision>
      <origin
        xyz="0 0 0"
        rpy="0 0 0" />
      <geometry>
        <mesh
          filename="file://$(find mini_pupper_description)/meshes/lpb1.STL" />
      </geometry>
    </collision>
  </link>
  <joint
    name="lb1_plate"
    type="fixed">
    <origin
      xyz="0.0107599999999999 0.0307 0.013"
      rpy="0 0 0" />
    <parent
      link="lb1" />
    <child
      link="lpb1" />
    <axis
      xyz="0 0 0" />
  </joint>
  <link
    name="lb2">
    <inertial>
      <origin
        xyz="-1.17961196366423E-16 -0.00101365780342477 -0.0182607957244282"
        rpy="0 0 0" />
      <mass
        value="0.0125" />
      <inertia
        ixx="2.56149742521739E-07"
        ixy="4.90778381056253E-24"
        ixz="-6.13191156321568E-23"
        iyy="2.61721029733561E-07"
        iyz="1.56691297771418E-10"
        izz="6.97328365560507E-09" />
    </inertial>
    <visual>
      <origin
        xyz="0 0 0"
        rpy="0 0 0" />
      <geometry>
        <mesh
          filename="file://$(find mini_pupper_description)/meshes/lb2.STL" />
      </geometry>
      <material
        name="">
        <color
          rgba="0.2 0.2 0.2 1" />
      </material>
    </visual>
    <collision>
      <origin
        xyz="0 0 0"
        rpy="0 0 0" />
      <geometry>
        <mesh
          filename="file://$(find mini_pupper_description)/meshes/lb2.STL" />
      </geometry>
    </collision>
  </link>
  <joint
    name="lb1_lb2"
    type="revolute">
    <origin
      xyz="-4E-05 0.0197 0"
      rpy="0 0 0" />
    <parent
      link="lb1" />
    <child
      link="lb2" />
    <axis
      xyz="0 1 0" />
    <limit
      lower="-3.14"
      upper="3.14"
      effort="5"
      velocity="1.5" />
  </joint>
  <link
    name="lpb2">
    <inertial>
      <origin
        xyz="-0.00217866290818428 -0.00156638440581503 0.034099120119674"
        rpy="0 0 0" />
      <mass
        value="0.0005" />
      <inertia
        ixx="9.34196968596701E-07"
        ixy="5.95712897889121E-09"
        ixz="2.71831950266149E-08"
        iyy="1.03925284587875E-06"
        iyz="-2.35723407122794E-08"
        izz="1.25155524458103E-07" />
    </inertial>
    <visual>
      <origin
        xyz="0 0 0"
        rpy="0 0 0" />
      <geometry>
        <mesh
          filename="file://$(find mini_pupper_description)/meshes/lpb2.STL" />
      </geometry>
      <material
        name="">
        <color
          rgba="1 1 0 1" />
      </material>
    </visual>
    <collision>
      <origin
        xyz="0 0 0"
        rpy="0 0 0" />
      <geometry>
        <mesh
          filename="file://$(find mini_pupper_description)/meshes/lpb2.STL" />
      </geometry>
    </collision>
  </link>
  <joint
    name="lb2_plate"
    type="fixed">
    <origin
      xyz="0 0.0100000000000007 -0.0500000000000001"
      rpy="0 0 0" />
    <parent
      link="lb2" />
    <child
      link="lpb2" />
    <axis
      xyz="0 0 0" />
  </joint>
  <link
    name="lb3">
    <inertial>
      <origin
        xyz="0.000237271929228088 -0.000198322763325702 -0.016535653838918"
        rpy="0 0 0" />
      <mass
        value="0.00625" />
      <inertia
        ixx="3.17108528910548E-07"
        ixy="-1.44307528577898E-14"
        ixz="6.6347256081998E-09"
        iyy="3.19154628310024E-07"
        iyz="-9.120429245734E-15"
        izz="2.63315419409871E-09" />
    </inertial>
    <visual>
      <origin
        xyz="0 0 0"
        rpy="0 0 0" />
      <geometry>
        <mesh
          filename="file://$(find mini_pupper_description)/meshes/lb3.STL" />
      </geometry>
      <material
        name="">
        <color
          rgba="0.2 0.2 0.2 1" />
      </material>
    </visual>
    <collision>
      <origin
        xyz="0 0 0"
        rpy="0 0 0" />
      <geometry>
        <mesh
          filename="file://$(find mini_pupper_description)/meshes/lb3.STL" />
      </geometry>
    </collision>
  </link>
  <joint
    name="lb2_lb3"
    type="revolute">
    <origin
      xyz="0 0.00475 -0.05"
      rpy="0 0 0" />
    <parent
      link="lb2" />
    <child
      link="lb3" />
    <axis
      xyz="0 1 0" />
    <limit
      lower="-3.14"
      upper="3.14"
      effort="5"
      velocity="1.5" />
  </joint>
  <link
    name="lbfoot">
    <inertial>
      <origin
        xyz="0.000424477269554052 -5.00018155106391E-05 0.000743181675762469"
        rpy="0 0 0" />
      <mass
        value="0.00625" />
      <inertia
        ixx="3.8885264656477E-08"
        ixy="3.60583012801976E-14"
        ixz="-2.99983098577426E-09"
        iyy="5.81684749230999E-08"
        iyz="1.31966997327651E-14"
        izz="2.7893076025217E-08" />
    </inertial>
    <visual>
      <origin
        xyz="0 0 0"
        rpy="0 0 0" />
      <geometry>
        <mesh
          filename="file://$(find mini_pupper_description)/meshes/lbfoot.STL" />
      </geometry>
      <material
        name="">
        <color
          rgba="0.2 0.2 0.2 1" />
      </material>
    </visual>
    <collision>
      <origin
        xyz="0 0 0"
        rpy="0 0 0" />
      <geometry>
        <mesh
          filename="file://$(find mini_pupper_description)/meshes/lbfoot.STL" />
      </geometry>
    </collision>
  </link>
  <joint
    name="lb3_foot"
    type="fixed">
    <origin
      xyz="0 0 -0.056"
      rpy="0 0 0" />
    <parent
      link="lb3" />
    <child
      link="lbfoot" />
    <axis
      xyz="0 0 0" />
  </joint>
  <link
    name="rb1">
    <inertial>
      <origin
        xyz="0.00541706873953746 -0.00276212057731962 0.00645819913656822"
        rpy="0 0 0" />
      <mass
        value="0.025" />
      <inertia
        ixx="2.2041347583079E-06"
        ixy="1.21330026226012E-08"
        ixz="-9.24417396767407E-09"
        iyy="3.50716356932592E-06"
        iyz="4.41858294139476E-09"
        izz="3.24535065112903E-06" />
    </inertial>
    <visual>
      <origin
        xyz="0 0 0"
        rpy="0 0 0" />
      <geometry>
        <mesh
          filename="file://$(find mini_pupper_description)/meshes/rb1.STL" />
      </geometry>
      <material
        name="">
        <color
          rgba="0.2 0.2 0.2 1" />
      </material>
    </visual>
    <collision>
      <origin
        xyz="0 0 0"
        rpy="0 0 0" />
      <geometry>
        <mesh
          filename="file://$(find mini_pupper_description)/meshes/rb1.STL" />
      </geometry>
    </collision>
  </link>
  <joint
    name="base_rb1"
    type="revolute">
    <origin
      xyz="-0.05886 -0.0235 0.0171"
      rpy="0 0 0" />
    <parent
      link="base_link" />
    <child
      link="rb1" />
    <axis
      xyz="1 0 0" />
    <limit
      lower="-3.14"
      upper="3.14"
      effort="5"
      velocity="1.5" />
  </joint>
  <link
    name="rpb1">
    <inertial>
      <origin
        xyz="0.00874955403415308 0.00579637837903882 -0.00450693399320118"
        rpy="0 0 0" />
      <mass
        value="0.0005" />
      <inertia
        ixx="8.18135114571351E-07"
        ixy="-8.78629613826186E-08"
        ixz="-3.80902795457312E-08"
        iyy="1.0153434226263E-06"
        iyz="-7.21698953092885E-08"
        izz="5.74767755618965E-07" />
    </inertial>
    <visual>
      <origin
        xyz="0 0 0"
        rpy="0 0 0" />
      <geometry>
        <mesh
          filename="file://$(find mini_pupper_description)/meshes/rpb1.STL" />
      </geometry>
      <material
        name="">
        <color
          rgba="1 1 0 1" />
      </material>
    </visual>
    <collision>
      <origin
        xyz="0 0 0"
        rpy="0 0 0" />
      <geometry>
        <mesh
          filename="file://$(find mini_pupper_description)/meshes/rpb1.STL" />
      </geometry>
    </collision>
  </link>
  <joint
    name="rb1_plate"
    type="fixed">
    <origin
      xyz="0.0107578315199995 -0.0307000000000005 0.0129999999999966"
      rpy="0 0 0" />
    <parent
      link="rb1" />
    <child
      link="rpb1" />
    <axis
      xyz="0 0 0" />
  </joint>
  <link
    name="rb2">
    <inertial>
      <origin
        xyz="-2.35922392732846E-16 0.00101365780342582 -0.0182607957244286"
        rpy="0 0 0" />
      <mass
        value="0.0125" />
      <inertia
        ixx="2.56149742521738E-07"
        ixy="4.58825592822502E-24"
        ixz="-1.29829794647633E-21"
        iyy="2.61721029733561E-07"
        iyz="-1.56691297770442E-10"
        izz="6.97328365560507E-09" />
    </inertial>
    <visual>
      <origin
        xyz="0 0 0"
        rpy="0 0 0" />
      <geometry>
        <mesh
          filename="file://$(find mini_pupper_description)/meshes/rb2.STL" />
      </geometry>
      <material
        name="">
        <color
          rgba="0.2 0.2 0.2 1" />
      </material>
    </visual>
    <collision>
      <origin
        xyz="0 0 0"
        rpy="0 0 0" />
      <geometry>
        <mesh
          filename="file://$(find mini_pupper_description)/meshes/rb2.STL" />
      </geometry>
    </collision>
  </link>
  <joint
    name="rb1_rb2"
    type="revolute">
    <origin
      xyz="-4E-05 -0.0197 0"
      rpy="0 0 0" />
    <parent
      link="rb1" />
    <child
      link="rb2" />
    <axis
      xyz="0 1 0" />
    <limit
      lower="-3.14"
      upper="3.14"
      effort="5"
      velocity="1.5" />
  </joint>
  <link
    name="rpb2">
    <inertial>
      <origin
        xyz="-0.002226106575326 0.00156905803495637 0.034086268557402"
        rpy="0 0 0" />
      <mass
        value="0.0005" />
      <inertia
        ixx="9.31223932833863E-07"
        ixy="-6.03482748767292E-09"
        ixz="2.8522700467156E-08"
        iyy="1.03508297458339E-06"
        iyz="2.34659787841777E-08"
        izz="1.23911464668974E-07" />
    </inertial>
    <visual>
      <origin
        xyz="0 0 0"
        rpy="0 0 0" />
      <geometry>
        <mesh
          filename="file://$(find mini_pupper_description)/meshes/rpb2.STL" />
      </geometry>
      <material
        name="">
        <color
          rgba="1 1 0 1" />
      </material>
    </visual>
    <collision>
      <origin
        xyz="0 0 0"
        rpy="0 0 0" />
      <geometry>
        <mesh
          filename="file://$(find mini_pupper_description)/meshes/rpb2.STL" />
      </geometry>
    </collision>
  </link>
  <joint
    name="rb2_plate"
    type="fixed">
    <origin
      xyz="0 -0.0099999999999994 -0.0500000000000005"
      rpy="0 0 0" />
    <parent
      link="rb2" />
    <child
      link="rpb2" />
    <axis
      xyz="0 0 0" />
  </joint>
  <link
    name="rb3">
    <inertial>
      <origin
        xyz="0.000237267386725477 0.000198312811274914 -0.0165356596906083"
        rpy="0 0 0" />
      <mass
        value="0.00625" />
      <inertia
        ixx="3.17108534392357E-07"
        ixy="-5.35428361452917E-15"
        ixz="6.63472696394029E-09"
        iyy="3.19154628307937E-07"
        iyz="-1.62028942327462E-14"
        izz="2.63314870485568E-09" />
    </inertial>
    <visual>
      <origin
        xyz="0 0 0"
        rpy="0 0 0" />
      <geometry>
        <mesh
          filename="file://$(find mini_pupper_description)/meshes/rb3.STL" />
      </geometry>
      <material
        name="">
        <color
          rgba="0.2 0.2 0.2 1" />
      </material>
    </visual>
    <collision>
      <origin
        xyz="0 0 0"
        rpy="0 0 0" />
      <geometry>
        <mesh
          filename="file://$(find mini_pupper_description)/meshes/rb3.STL" />
      </geometry>
    </collision>
  </link>
  <joint
    name="rb2_rb3"
    type="revolute">
    <origin
      xyz="0 -0.00475 -0.05"
      rpy="0 0 0" />
    <parent
      link="rb2" />
    <child
      link="rb3" />
    <axis
      xyz="0 1 0" />
    <limit
      lower="-3.14"
      upper="3.14"
      effort="5"
      velocity="1.5" />
  </joint>
  <link
    name="rbfoot">
    <inertial>
      <origin
        xyz="0.000424477269553421 4.99981844908973E-05 0.000743181675762136"
        rpy="0 0 0" />
      <mass
        value="0.00625" />
      <inertia
        ixx="3.88852646564768E-08"
        ixy="3.60583012702203E-14"
        ixz="-2.99983098577417E-09"
        iyy="5.81684749230997E-08"
        iyz="1.31966997511807E-14"
        izz="2.78930760252171E-08" />
    </inertial>
    <visual>
      <origin
        xyz="0 0 0"
        rpy="0 0 0" />
      <geometry>
        <mesh
          filename="file://$(find mini_pupper_description)/meshes/rbfoot.STL" />
      </geometry>
      <material
        name="">
        <color
          rgba="0.2 0.2 0.2 1" />
      </material>
    </visual>
    <collision>
      <origin
        xyz="0 0 0"
        rpy="0 0 0" />
      <geometry>
        <mesh
          filename="file://$(find mini_pupper_description)/meshes/rbfoot.STL" />
      </geometry>
    </collision>
  </link>
  <joint
    name="rb3_foot"
    type="fixed">
    <origin
      xyz="0 0 -0.056"
      rpy="0 0 0" />
    <parent
      link="rb3" />
    <child
      link="rbfoot" />
    <axis
      xyz="0 0 0" />
  </joint>
  <ros2_control name="GazeboSystem" type="system">
    <hardware>
      <plugin>gazebo_ros2_control/GazeboSystem</plugin>
    </hardware>
    <joint name="base_lf1">
      <command_interface name="effort"/> 
      <state_interface name="position"/>
      <state_interface name="velocity"/>
    </joint>
    <joint name="lf1_lf2">
      <command_interface name="effort"/> 
      <state_interface name="position"/>
      <state_interface name="velocity"/>
    </joint>
    <joint name="lf2_lf3">
      <command_interface name="effort"/> 
      <state_interface name="position"/>
      <state_interface name="velocity"/>
    </joint>
    <joint name="base_rf1">
      <command_interface name="effort"/> 
      <state_interface name="position"/>
      <state_interface name="velocity"/>
    </joint>
    <joint name="rf1_rf2">
      <command_interface name="effort"/> 
      <state_interface name="position"/>
      <state_interface name="velocity"/>
    </joint>
    <joint name="rf2_rf3">
      <command_interface name="effort"/> 
      <state_interface name="position"/>
      <state_interface name="velocity"/>
    </joint>
    <joint name="base_lb1">
      <command_interface name="effort"/> 
      <state_interface name="position"/>
      <state_interface name="velocity"/>
    </joint>
    <joint name="lb1_lb2">
      <command_interface name="effort"/> 
      <state_interface name="position"/>
      <state_interface name="velocity"/>
    </joint>
    <joint name="lb2_lb3">
      <command_interface name="effort"/> 
      <state_interface name="position"/>
      <state_interface name="velocity"/>
    </joint>
    <joint name="base_rb1">
      <command_interface name="effort"/> 
      <state_interface name="position"/>
      <state_interface name="velocity"/>
    </joint>
    <joint name="rb1_rb2">
      <command_interface name="effort"/> 
      <state_interface name="position"/>
      <state_interface name="velocity"/>
    </joint>
    <joint name="rb2_rb3">
      <command_interface name="effort"/> 
      <state_interface name="position"/>
      <state_interface name="velocity"/>
    </joint>
  </ros2_control>
  <!-- coloring Gazebo model -->
  <gazebo reference="base_link">
    <material>Gazebo/FlatBlack</material>
  </gazebo>
  <gazebo reference="yellow_plate">
    <material>Gazebo/Yellow</material>
  </gazebo>
  
  <gazebo reference="lf1">
    <kp>1000000.0</kp>
    <kd>1.0</kd>
    <mu1>0.8</mu1>
    <mu2>0.8</mu2>
    <maxVel>0.0</maxVel>
    <minDepth>0.001</minDepth>
    <material>Gazebo/FlatBlack</material>
  </gazebo>
  <gazebo reference="lpf1">
    <material>Gazebo/Yellow</material>
  </gazebo>
  <gazebo reference="lf2">
    <kp>1000000.0</kp>
    <kd>1.0</kd>
    <mu1>0.8</mu1>
    <mu2>0.8</mu2>
    <maxVel>0.0</maxVel>
    <minDepth>0.001</minDepth>
    <material>Gazebo/FlatBlack</material>
  </gazebo>
  <gazebo reference="lpf2">
    <material>Gazebo/Yellow</material>
  </gazebo>
  <gazebo reference="lf3">
    <kp>1000000.0</kp>
    <kd>1.0</kd>
    <mu1>0.8</mu1>
    <mu2>0.8</mu2>
    <maxVel>0.0</maxVel>
    <minDepth>0.001</minDepth>
    <material>Gazebo/FlatBlack</material>
  </gazebo>
  <gazebo reference="lffoot">
    <kp>1000000.0</kp>
    <kd>1.0</kd>
    <mu1>0.8</mu1>
    <mu2>0.8</mu2>
    <maxVel>0.0</maxVel>
    <minDepth>0.001</minDepth>
    <material>Gazebo/FlatBlack</material>
  </gazebo>
  <gazebo reference="rf1">
    <kp>1000000.0</kp>
    <kd>1.0</kd>
    <mu1>0.8</mu1>
    <mu2>0.8</mu2>
    <maxVel>0.0</maxVel>
    <minDepth>0.001</minDepth>
    <material>Gazebo/FlatBlack</material>
  </gazebo>
  <gazebo reference="rpf1">
    <material>Gazebo/Yellow</material>
  </gazebo>
  <gazebo reference="rf2">
    <kp>1000000.0</kp>
    <kd>1.0</kd>
    <mu1>0.8</mu1>
    <mu2>0.8</mu2>
    <maxVel>0.0</maxVel>
    <minDepth>0.001</minDepth>
    <material>Gazebo/FlatBlack</material>
  </gazebo>
  <gazebo reference="rpf2">
    <material>Gazebo/Yellow</material>
  </gazebo>
  <gazebo reference="rf3">
    <kp>1000000.0</kp>
    <kd>1.0</kd>
    <mu1>0.8</mu1>
    <mu2>0.8</mu2>
    <maxVel>0.0</maxVel>
    <minDepth>0.001</minDepth>
    <material>Gazebo/FlatBlack</material>
  </gazebo>
  <gazebo reference="rffoot">
    <kp>1000000.0</kp>
    <kd>1.0</kd>
    <mu1>0.8</mu1>
    <mu2>0.8</mu2>
    <maxVel>0.0</maxVel>
    <minDepth>0.001</minDepth>
    <material>Gazebo/FlatBlack</material>
  </gazebo>
  <gazebo reference="lb1">
    <kp>1000000.0</kp>
    <kd>1.0</kd>
    <mu1>0.8</mu1>
    <mu2>0.8</mu2>
    <maxVel>0.0</maxVel>
    <minDepth>0.001</minDepth>
    <material>Gazebo/FlatBlack</material>
  </gazebo>
  <gazebo reference="lpb1">
    <material>Gazebo/Yellow</material>
  </gazebo>
  <gazebo reference="lb2">
    <kp>1000000.0</kp>
    <kd>1.0</kd>
    <mu1>0.8</mu1>
    <mu2>0.8</mu2>
    <maxVel>0.0</maxVel>
    <minDepth>0.001</minDepth>
    <material>Gazebo/FlatBlack</material>
  </gazebo>
  <gazebo reference="lpb2">
    <material>Gazebo/Yellow</material>
  </gazebo>
  <gazebo reference="lb3">
    <kp>1000000.0</kp>
    <kd>1.0</kd>
    <mu1>0.8</mu1>
    <mu2>0.8</mu2>
    <maxVel>0.0</maxVel>
    <minDepth>0.001</minDepth>
    <material>Gazebo/FlatBlack</material>
  </gazebo>
  <gazebo reference="lbfoot">
    <kp>1000000.0</kp>
    <kd>1.0</kd>
    <mu1>0.8</mu1>
    <mu2>0.8</mu2>
    <maxVel>0.0</maxVel>
    <minDepth>0.001</minDepth>
    <material>Gazebo/FlatBlack</material>
  </gazebo>
  <gazebo reference="rb1">
    <kp>1000000.0</kp>
    <kd>1.0</kd>
    <mu1>0.8</mu1>
    <mu2>0.8</mu2>
    <maxVel>0.0</maxVel>
    <minDepth>0.001</minDepth>
    <material>Gazebo/FlatBlack</material>
  </gazebo>
  <gazebo reference="rpb1">
    <material>Gazebo/Yellow</material>
  </gazebo>
  <gazebo reference="rb2">
    <kp>1000000.0</kp>
    <kd>1.0</kd>
    <mu1>0.8</mu1>
    <mu2>0.8</mu2>
    <maxVel>0.0</maxVel>
    <minDepth>0.001</minDepth>
    <material>Gazebo/FlatBlack</material>
  </gazebo>
  <gazebo reference="rpb2">
    <material>Gazebo/Yellow</material>
  </gazebo>
  <gazebo reference="rb3">
    <kp>1000000.0</kp>
    <kd>1.0</kd>
    <mu1>0.8</mu1>
    <mu2>0.8</mu2>
    <maxVel>0.0</maxVel>
    <minDepth>0.001</minDepth>
    <material>Gazebo/FlatBlack</material>
  </gazebo>
  <gazebo reference="rbfoot">
    <kp>1000000.0</kp>
    <kd>1.0</kd>
    <mu1>0.8</mu1>
    <mu2>0.8</mu2>
    <maxVel>0.0</maxVel>
    <minDepth>0.001</minDepth>
    <material>Gazebo/FlatBlack</material>
  </gazebo>
  
  <gazebo reference="lidar_link">
    <material>Gazebo/FlatBlack</material>
    <sensor type="ray" name="lidar">
      <always_on>true</always_on>
      <update_rate>30</update_rate>
      <pose>0 0 0 0 0 0</pose>
      <visualize>false</visualize>
      <ray>
        <scan>
          <horizontal>
            <samples>1040</samples>
            <resolution>1</resolution>
            <min_angle>0</min_angle>
            <max_angle>6.28</max_angle>
          </horizontal>
        </scan>
        <range>
          <min>0.2</min>
          <max>50.0</max>
          <resolution>0.01</resolution>
        </range>
        <noise>
          <type>gaussian</type>
          <mean>0.0</mean>
          <stddev>0.004</stddev>
        </noise>
      </ray>
      <plugin name="gazebo_ros_lidar_controller" filename="libgazebo_ros_ray_sensor.so">
        <ros>
          <argument>~/out:=/scan</argument>
        </ros>
        <output_type>sensor_msgs/LaserScan</output_type>
        <frame_name>lidar_link</frame_name>
        <!--min_intensity>100.0</min_intensity-->
      </plugin>
    </sensor>
  </gazebo>
  
  <gazebo>
    <plugin filename="libgazebo_ros_p3d.so" name="p3d_base_controller">
      <ros>
          <argument>odom:=odom/ground_truth</argument>
      </ros>
      <body_name>base_link</body_name>
      <frame_name>world</frame_name>
      <update_rate>10.0</update_rate>
      <xyz_offset>0 0 0</xyz_offset>
      <rpy_offset>0 0 0</rpy_offset>
      <gaussian_noise>0.01</gaussian_noise>
    </plugin>
  </gazebo>
  
  <gazebo>
    <plugin filename="libgazebo_ros2_control.so" name="gazebo_ros2_control">
      <parameters>$(find mini_pupper_description)/config/ros_control/mini_pupper_controller.yaml</parameters>
    </plugin>
  </gazebo>
  
  <link name="imu_link">
    <inertial>
      <mass value="0.0001"/>
      <origin rpy="0 0 0" xyz="0 0 0"/>
      <inertia ixx="1e-09" ixy="0.0" ixz="0.0" iyy="1e-09" iyz="0.0" izz="1e-09"/>
    </inertial>
  </link>

  <joint name="imu_joint" type="fixed">
    <parent link="base_link"/>
    <child link="imu_link"/>
  </joint>

  <gazebo reference="imu_link">
    <sensor name="imu_controller" type="imu">
      <always_on>true</always_on>
      <update_rate>50</update_rate>
      <plugin name="gazebo_ros_imu_sensor" filename="libgazebo_ros_imu_sensor.so">
          <ros>
              <namespace>/imu</namespace>
              <argument>~/out:=data</argument>
          </ros>
      </plugin>
    </sensor>
  </gazebo>
  
  <!--xacro:sensor_d435 parent="base_link">
  <origin xyz="0.08 0.0 0.07" rpy="0 0 0" />
  </xacro:sensor_d435-->
</robot>
